Workbook

Sheet JADWAL
E1: SENIN1 | F1: SENIN2 | G1: SENIN3 | H1: SENIN4 | I1: SENIN5 | K1: SENIN6 | L1: SENIN | M1: SENIN6 | N1: SENIN7 | O1: SENIN8 | P1: SENIN9 | Q1: SENIN8 | R1: SENIN | S1: SENIN10 | T1: SENIN11 | W1: SELASA0 | X1: SELASA1 | Y1: SELASA2 | Z1: SELASA3 | AA1: SELASA4 | AB1: SELASA | AC1: SELASA5 | AD1: SELASA6 | AE1: SELASA | AF1: SELASA7 | AG1: SELASA8 | AH1: SELASA9 | AI1: SELASA10 | AJ1: SELASA | AK1: SELASA11 | AL1: SELASA12 | AN1: RABU0 | AO1: RABU1 | AP1: RABU2 | AQ1: RABU3 | AR1: RABU4 | AS1: RABU | AT1: RABU5 | AU1: RABU6 | AV1: RABU | AW1: RABU7 | AX1: RABU8 | AY1: RABU9 | AZ1: RABU10 | BA1: RABU | BB1: RABU11 | BC1: RABU12 | BF1: KAMIS0 | BG1: KAMIS1 | BH1: KAMIS2 | BI1: KAMIS3 | BJ1: KAMIS4 | BK1: KAMIS | BL1: KAMIS5 | BM1: KAMIS6 | BN1: KAMIS | BO1: KAMIS7 | BP1: KAMIS8 | BQ1: KAMIS9 | BR1: KAMIS10 | BS1: KAMIS | BT1: KAMIS11 | BU1: KAMIS12 | BW1: JUM'AT0 | BX1: JUM'AT1 | BY1: JUM'AT2 | BZ1: JUM'AT3 | CA1: JUM'AT4 | CB1: JUM'AT5 | CC1: JUM'AT6 | CD1: JUM'AT | CE1: JUM'AT7 | CF1: JUM'AT8 | CG1: JUM'AT9 | CH1: JUM'AT10 | CI1: JUM'AT | CJ1: JUM'AT11 | CK1: JUM'AT12 | CL1: JUM'AT
A2: A | B2: B | C2: C | D2: D | E2: E | F2: F | G2: G | H2: H | I2: I | J2: J | K2: K | L2: L | M2: M | N2: N | O2: O | P2: P | Q2: Q | R2: R | S2: S | T2: T | V2: U | W2: V | X2: W | Y2: X | Z2: Y | AA2: Z | AB2: AA | AC2: AB | AD2: AC | AE2: AD | AF2: AE | AG2: AF | AH2: AG | AI2: AH | AJ2: AI | AK2: AJ | AL2: AK | AM2: AL | AN2: AM | AO2: AO | AP2: AP | AQ2: AQ | AR2: AR | AS2: AS | AT2: AT | AU2: AU | AV2: AV | AW2: AW | AX2: AX | AY2: AY | AZ2: AZ | BA2: BA | BB2: BB | BC2: BC | BD2: BD | BF2: BE | BG2: BF | BH2: BG | BI2: BH | BJ2: BI | BK2: BJ | BL2: BK | BM2: BL | BN2: BM | BO2: BN | BP2: BO | BQ2: BP | BR2: BQ | BS2: BR | BT2: BS | BU2: BT | BV2: BU | BW2: BV | BX2: BW | BY2: BX | BZ2: BY | CA2: BZ | CB2: CA | CC2: CB | CD2: CC | CE2: CD | CF2: CE | CG2: CF | CH2: CG | CI2: CH | CJ2: CI | CK2: CJ | CL2: CK
E3: SENIN | F3: SENIN | G3: SENIN | H3: SENIN | I3: SENIN | J3: SENIN | K3: SENIN | L3: SENIN | M3: SENIN | N3: SENIN | O3: SENIN | P3: SENIN | Q3: SENIN | R3: SENIN | S3: SENIN | V3: SELASA | W3: SELASA | X3: SELASA | Y3: SELASA | Z3: SELASA | AA3: SELASA | AB3: SELASA | AC3: SELASA | AD3: SELASA | AE3: SELASA | AF3: SELASA | AG3: SELASA | AH3: SELASA | AI3: SELASA | AJ3: SELASA | AK3: SELASA | AM3: RABU | AN3: RABU | AO3: RABU | AP3: RABU | AQ3: RABU | AR3: RABU | AS3: RABU | AT3: RABU | AU3: RABU | AV3: RABU | AW3: RABU | AX3: RABU | AY3: RABU | AZ3: RABU | BA3: RABU | BB3: RABU | BC3: RABU | BF3: KAMIS | BG3: KAMIS | BH3: KAMIS | BI3: KAMIS | BJ3: KAMIS | BK3: KAMIS | BL3: KAMIS | BM3: KAMIS | BN3: KAMIS | BO3: KAMIS | BP3: KAMIS | BQ3: KAMIS | BR3: KAMIS | BS3: KAMIS | BT3: KAMIS | BU3: KAMIS | BW3: JUM'AT | BX3: JUM'AT | BY3: JUM'AT | BZ3: JUM'AT | CA3: JUM'AT | CB3: JUM'AT | CC3: JUM'AT | CD3: JUM'AT | CE3: JUM'AT | CF3: JUM'AT | CG3: JUM'AT | CH3: JUM'AT | CI3: JUM'AT | CJ3: JUM'AT | CK3: JUM'AT
A4: No. | B4: KELAS | C4: JAM KE | E4: 1 | F4: 2 | G4: 3 | H4: 4 | I4: 5 | K4: 6 | L4: 7 | M4: 8 | N4: 9 | O4: 10 | P4: 11 | Q4: 12 | R4: 11 | S4: 12 | U4: PEMBIASAAN | V4: 1 | W4: 2 | X4: 3 | Y4: 4 | Z4: 5 | AB4: 6 | AC4: 7 | AD4: 8 | AE4: 9 | AF4: 10 | AG4: 11 | AH4: 12 | AJ4: 13 | AK4: 14 | AM4: 1 | AN4: 2 | AO4: 3 | AP4: 4 | AQ4: 5 | AS4: 6 | AT4: 7 | AU4: 8 | AV4: 9 | AW4: 10 | AX4: 11 | AY4: 12 | BA4: 12 | BB4: 13 | BC4: 12 | BE4: PEMBIASAAN | BF4: 1 | BG4: 2 | BH4: 3 | BI4: 4 | BJ4: 5 | BL4: 6 | BM4: 7 | BN4: 8 | BO4: 9 | BP4: 10 | BQ4: 11 | BR4: 12 | BT4: 12 | BW4: 1 | BX4: 2 | BY4: 3 | BZ4: 4 | CA4: 5 | CB4: 6 | CC4: 7 | CE4: 8 | CF4: 9 | CG4: 10 | CH4: 11 | CJ4: 12
C5: WAKTU | E5: 06.30 - 07.15 | F5: 07.15 - 08.00 | G5: 08.00 - 08.45 | H5: 08.45 - 09.30 | I5: 09.30 - 10.15 | J5: 10.15 - 10.30 | K5: 10.30 - 11.15 | L5: 11.15 - 12.00 | M5: 12.00 - 12.45 | N5: 12.45 - 13.30 | O5: 13.30 - 14.15 | P5: 14.15 - 15.00 | Q5: 15.00 - 15.45 | R5: 16.00 - 16.45 | S5: 16.45 - 17.30 | U5: 06.30-06.45 | V5: 06.45 - 07.30 | W5: 07.30 - 08.15 | X5: 08.15 - 09.00 | Y5: 09.00 - 09.45 | Z5: 09.45 - 10.30 | AA5: 10.30 - 10.45 | AB5: 10.45 - 11.30 | AC5: 11.30 - 12.15 | AD5: 12.15 - 13.00 | AE5: 13.00 - 13.45 | AF5: 13.45 - 14.30 | AG5: 14.30 - 1515 | AH5: 15.15 - 16.00 | AI5: 16.00 - 16.45 | AJ5: 16.45 - 17.30 | AM5: 06.30 - 07.15 | AN5: 07.15 - 08.00 | AO5: 08.00 - 08.45 | AP5: 08.45 - 09.30 | AQ5: 09.30 - 10.15 | AR5: 10.15 - 10.30 | AS5: 10.30 - 11.15 | AT5: 11.15 - 12.00 | AU5: 12.00 - 12.45 | AV5: 12.45 - 13.30 | AW5: 13.30 - 14.15 | AX5: 14.15 - 15.00 | AY5: 15.00 - 15.45 | AZ5: 15.45 - 16.00 | BA5: 16.00 - 16.45 | BB5: 16.45 - 17.30 | BC5: 16.30 - 17.15 | BE5: 06.30-06.45 | BF5: 06.45 - 07.30 | BG5: 07.30 - 08.15 | BH5: 08.15 - 09.00 | BI5: 09.00 - 09.45 | BJ5: 09.45 - 10.30 | BK5: 10.30 - 10.45 | BL5: 10.45 - 11.30 | BM5: 11.30 - 12.15 | BN5: 12.15 - 13.00 | BO5: 13.00 - 13.45 | BP5: 13.45 - 14.30 | BQ5: 14.30 - 1515 | BR5: 15.15 - 16.00 | BS5: 16.00 - 16.45 | BT5: 16.45 - 17.30 | BW5: 06.30 - 07.15 | BX5: 07.15 - 08.00 | BY5: 08.00 - 08.45 | BZ5: 08.45 - 09.30 | CA5: 09.30 - 10.15 | CB5: 10.15-11.00 | CC5: 11.00 - 11.45 | CD5: 11.45 - 13.00 | CE5: 13.00 - 13.45 | CF5: 13.45 - 14.30 | CG5: 14.30 - 15.15 | CH5: 15.15 - 16.00 | CI5: 16.00 - 16.15 | CJ5: 16.15 - 17.00 | CN5: PABP | CO5: PPAN | CP5: BIND | CQ5: PJOK | CR5: SJRH | CS5: SBDY | CT5: BSUN | CU5: MATH | CV5: BING | CW5: INFR | CX5: IPAS | CY5: DPK | CZ5: KIMIA | DE5: TUGAS MANDIRI | DG5: BPBK
B6: X KA 1 | C6: MAPEL | D6: 6 | E6: UPACARA/ | F6: DPK | G6: DPK | H6: DPK | I6: DPK | K6: DPK | L6: DPK | M6: ISTIRAHAT | N6: DPK | O6: DPK | P6: DPK | Q6: DPK | U6: TADARUS & | V6: PJOK | W6: PJOK | X6: BSUN | Y6: BSUN | Z6: PABP | AB6: PABP | AC6: PABP | AD6: ISTIRAHAT | AE6: BPBK | AF6: BING | AG6: BING | AH6: TUGAS MANDIRI | AM6: SHOLAT | AN6: KIMIA | AO6: KIMIA | AP6: IPAS | AQ6: IPAS | AS6: MATH | AT6: MATH | AU6: ISTIRAHAT | AV6: BIND | AW6: BIND | AX6: SJRH | AY6: SJRH | BE6: TADARUS & | BF6: BING | BG6: BING | BH6: SBDY | BI6: SBDY | BJ6: INFR | BL6: INFR | BM6: PPAN | BN6: ISTIRAHAT | BO6: PPAN | BP6: TUGAS MANDIRI | BQ6: TUGAS MANDIRI | BR6: TUGAS MANDIRI | BW6: SENAM & | BX6: DPK | BY6: DPK | BZ6: MATH | CA6: MATH | CB6: IPAS | CC6: IPAS | CD6: ISTIRAHAT | CE6: INFR | CF6: INFR | CG6: BIND | CH6: BIND | CN6: =COUNTIF($F$6:$CK$6,CN5) -> 3 | CO6: =COUNTIF($F$6:$CK$6,CO5) -> 2 | CP6: =COUNTIF($F$6:$CK$6,CP5) -> 4 | CQ6: =COUNTIF($F$6:$CK$6,CQ5) -> 2 | CR6: =COUNTIF($F$6:$CK$6,CR5) -> 2 | CS6: =COUNTIF($F$6:$CK$6,CS5) -> 2 | CT6: =COUNTIF($F$6:$CK$6,CT5) -> 2 | CU6: =COUNTIF($F$6:$CK$6,CU5) -> 4 | ... DG6: =COUNTIF($F$6:$CK$6,DG5) -> 1 | DH6: =SUM(CN6:DG6) -> 52
C7: RUANG | D7: 7 | E7: PERWALIAN | F7: R.DPK | G7: R.DPK | H7: R.DPK | I7: R.DPK | J7: I | K7: R.DPK | L7: R.DPK | M7: DZUHUR | N7: R.DPK | O7: R.DPK | P7: R.DPK | Q7: R.DPK | U7: SARAPAN | V7: LAP | W7: LAP | X7: R.44 | Y7: R.44 | Z7: R.44 | AA7: I | AB7: R.44 | AC7: R.44 | AD7: DZUHUR | AE7: R.44 | AF7: R.44 | AG7: R.44 | AM7: DHUHA & | AN7: R.44 | AO7: R.44 | AP7: R.44 | AQ7: R.44 | AR7: I | AS7: R.44 | AT7: R.44 | AU7: DZUHUR | AV7: R.44 | AW7: R.44 | AX7: R.44 | AY7: R.44 | BE7: LITERASI | BF7: R.44 | BG7: R.44 | BH7: R.44 | BI7: R.44 | BJ7: R.34 | BK7: I | BL7: R.34 | BM7: R.44 | BN7: DZUHUR | BO7: R.44 | BW7: JUMAT BERSIH | BX7: R.44 | BY7: R.44 | BZ7: R.44 | CA7: R.44 | CB7: R.44 | CC7: R.44 | CD7: DZUHUR | CE7: R.34 | CF7: R.34 | CG7: R.44 | CH7: R.44 | CI7: I
C8: GURU | D8: 8 | F8: ULI | G8: ULI | H8: ULI | I8: ULI | K8: ULI | L8: ULI | M8: MESJID | N8: ULI | O8: ULI | P8: ULI | Q8: ULI | U8: BERGIZI | V8: YENI | W8: YENI | X8: RANI | Y8: RANI | Z8: SAMSU | AB8: SAMSU | AC8: SAMSU | AD8: MESJID | AE8: HALIDA | AF8: UJANG | AG8: UJANG | AH8: DI KELAS | AM8: TADARUS | AN8: TESSA | AO8: TESSA | AP8: OMAN | AQ8: OMAN | AS8: NADIA | AT8: NADIA | AU8: MESJID | AV8: MELI | AW8: MELI | AX8: APRIL | AY8: APRIL | BE8: DI KELAS | BF8: UJANG | BG8: UJANG | BH8: ADIW | BI8: ADIW | BJ8: SABILA | BL8: SABILA | BM8: SUKMA | BN8: MESJID | BO8: SUKMA | BP8: DI KELAS | BQ8: DI KELAS | BR8: DI KELAS | BX8: ULI | BY8: ULI | BZ8: NADIA | CA8: NADIA | CB8: OMAN | CC8: OMAN | CD8: MESJID | CE8: SABILA | CF8: SABILA | CG8: MELI | CH8: MELI
D9: 9 | H9: SUGI | I9: SUGI | K9: SUGI | L9: SUGI | N9: SUGI | O9: SUGI | P9: SUGI | Q9: SUGI | U9: DI KELAS | AM9: DI LAPANG
D10: 10 | J10: S | AA10: S | AR10: S | BK10: S | CI10: S
B11: X KA 2 | C11: MAPEL | D11: 11 | E11: UPACARA/ | F11: PABP | G11: PABP | H11: PABP | I11: KIMIA | K11: KIMIA | L11: BPBK | M11: ISTIRAHAT | N11: MATH | O11: MATH | P11: PPAN | Q11: PPAN | U11: TADARUS & | V11: DPK | W11: DPK | X11: DPK | Y11: DPK | Z11: DPK | AB11: DPK | AC11: DPK | AD11: ISTIRAHAT | AE11: DPK | AF11: DPK | AG11: DPK | AH11: TUGAS MANDIRI | AM11: SHOLAT | AN11: BSUN | AO11: BSUN | AP11: INFR | AQ11: INFR | AS11: SJRH | AT11: SJRH | AU11: ISTIRAHAT | AV11: IPAS | AW11: IPAS | AX11: BIND | AY11: BIND | BE11: TADARUS & | BF11: PJOK | BG11: PJOK | BH11: BING | BI11: BING | BJ11: SBDY | BL11: SBDY | BM11: INFR | BN11: ISTIRAHAT | BO11: INFR | BP11: TUGAS MANDIRI | BQ11: TUGAS MANDIRI | BR11: TUGAS MANDIRI | BW11: SENAM & | BX11: BING | BY11: BING | BZ11: DPK | CA11: DPK | CB11: MATH | CC11: MATH | CD11: ISTIRAHAT | CE11: BIND | CF11: BIND | CG11: IPAS | CH11: IPAS | CN11: =COUNTIF($F$11:$CJ$11,CN5) -> 3 | CO11: =COUNTIF($F$11:$CJ$11,CO5) -> 2 | CP11: =COUNTIF($F$11:$CJ$11,CP5) -> 4 | CQ11: =COUNTIF($F$11:$CJ$11,CQ5) -> 2 | CR11: =COUNTIF($F$11:$CJ$11,CR5) -> 2 | CS11: =COUNTIF($F$11:$CJ$11,CS5) -> 2 | CT11: =COUNTIF($F$11:$CJ$11,CT5) -> 2 | CU11: =COUNTIF($F$11:$CJ$11,CU5) -> 4 | ... DG11: =COUNTIF($F$11:$CJ$11,DG5) -> 1 | DH11: =SUM(CN11:DG11) -> 52
C12: RUANG | D12: 12 | E12: PERWALIAN | F12: R.45 | G12: R.45 | H12: R.45 | I12: R.45 | K12: R.45 | L12: R.45 | M12: DZUHUR | N12: R.45 | O12: R.45 | P12: R.45 | Q12: R.45 | U12: SARAPAN | V12: R.DPK | W12: R.DPK | X12: R.DPK | Y12: R.DPK | Z12: R.DPK | AB12: R.DPK | AC12: R.DPK | AD12: DZUHUR | AE12: R.DPK | AF12: R.DPK | AG12: R.DPK | AM12: DHUHA & | AN12: R.45 | AO12: R.45 | AP12: R.34 | AQ12: R.34 | AS12: R.45 | AT12: R.45 | AU12: DZUHUR | AV12: R.45 | AW12: R.45 | AX12: R.45 | AY12: R.45 | BE12: LITERASI | BF12: LAP | BG12: LAP | BH12: R.45 | BI12: R.45 | BJ12: R.45 | BL12: R.45 | BM12: R.34 | BN12: DZUHUR | BO12: R.34 | BW12: JUMAT BERSIH | BX12: R.45 | BY12: R.45 | BZ12: R.45 | CA12: R.45 | CB12: R.45 | CC12: R.45 | CD12: DZUHUR | CE12: R.45 | CF12: R.45 | CG12: R.45 | CH12: R.45
C13: GURU | D13: 13 | F13: SAMSU | G13: SAMSU | H13: SAMSU | I13: TESSA | J13: T | K13: TESSA | L13: HALIDA | M13: MESJID | N13: NADIA | O13: NADIA | P13: SUKMA | Q13: SUKMA | U13: BERGIZI | V13: ULI | W13: ULI | X13: ULI | Y13: ULI | Z13: ULI | AA13: T | AB13: ULI | AC13: ULI | AD13: MESJID | AE13: ULI | AF13: ULI | AG13: ULI | AH13: DI KELAS | AM13: TADARUS | AN13: RANI | AO13: RANI | AP13: SABILA | AQ13: SABILA | AR13: T | AS13: APRIL | AT13: APRIL | AU13: MESJID | AV13: OMAN | AW13: OMAN | AX13: MELI | AY13: MELI | BE13: DI KELAS | BF13: YENI | BG13: YENI | BH13: UJANG | BI13: UJANG | BJ13: ADIW | BK13: T | BL13: ADIW | BM13: SABILA | BN13: MESJID | BO13: SABILA | BP13: DI KELAS | BQ13: DI KELAS | BR13: DI KELAS | BX13: UJANG | BY13: UJANG | BZ13: ULI | CA13: ULI | CB13: NADIA | CC13: NADIA | CD13: MESJID | CE13: MELI | CF13: MELI | CG13: OMAN | CH13: OMAN | CI13: T
D14: 14 | U14: DI KELAS | X14: TESSA | Y14: TESSA | Z14: TESSA | AB14: TESSA | AC14: TESSA | AE14: TESSA | AF14: TESSA | AG14: TESSA | AM14: DI LAPANG
D15: 15
B16: X KA 3 | C16: MAPEL | D16: 16 | E16: UPACARA/ | F16: KIMIA | G16: KIMIA | H16: IPAS | I16: IPAS | J16: I | K16: INFR | L16: INFR | M16: ISTIRAHAT | N16: BIND | O16: BIND | P16: BING | Q16: BING | U16: TADARUS & | V16: MATH | W16: MATH | X16: PPAN | Y16: PPAN | Z16: DPK | AA16: I | AB16: DPK | AC16: PJOK | AD16: PJOK | AE16: ISTIRAHAT | AF16: BIND | AG16: BIND | AH16: TUGAS MANDIRI | AM16: SHOLAT | AN16: DPK | AO16: DPK | AP16: DPK | AQ16: DPK | AR16: I | AS16: DPK | AT16: DPK | AU16: ISTIRAHAT | AV16: DPK | AW16: DPK | AX16: DPK | AY16: DPK | BE16: TADARUS & | BF16: SJRH | BG16: SJRH | BH16: INFR | BI16: INFR | BJ16: BPBK | BK16: I | BL16: IPAS | BM16: IPAS | BN16: ISTIRAHAT | BO16: SBDY | BP16: SBDY | BQ16: TUGAS MANDIRI | BR16: TUGAS MANDIRI | BW16: SENAM & | BX16: BSUN | BY16: BSUN | BZ16: PABP | CA16: PABP | CB16: PABP | CC16: TUGAS MANDIRI | CD16: ISTIRAHAT | CE16: MATH | CF16: MATH | CG16: BING | CH16: BING | CI16: I | CN16: =COUNTIF($F$16:$CK$16,CN5) -> 3 | CO16: =COUNTIF($F$16:$CK$16,CO5) -> 2 | CP16: =COUNTIF($F$16:$CK$16,CP5) -> 4 | CQ16: =COUNTIF($F$16:$CK$16,CQ5) -> 2 | CR16: =COUNTIF($F$16:$CK$16,CR5) -> 2 | CS16: =COUNTIF($F$16:$CK$16,CS5) -> 2 | CT16: =COUNTIF($F$16:$CK$16,CT5) -> 2 | CU16: =COUNTIF($F$16:$CK$16,CU5) -> 4 | ... DG16: =COUNTIF($F$16:$CK$16,DG5) -> 1 | DH16: =SUM(CN16:DG16) -> 52
C17: RUANG | D17: 17 | E17: PERWALIAN | F17: R.46 | G17: R.46 | H17: R.46 | I17: R.46 | K17: R.46 | L17: R.46 | M17: DZUHUR | N17: R.46 | O17: R.46 | P17: R.46 | Q17: R.46 | U17: SARAPAN | V17: R.46 | W17: R.46 | X17: R.46 | Y17: R.46 | Z17: R.46 | AB17: R.46 | AC17: LAP | AD17: LAP | AE17: DZUHUR | AF17: R.45 | AG17: R.45 | AM17: DHUHA & | AN17: R.KUALI | AO17: R.KUALI | AP17: R.KUALI | AQ17: R.KUALI | AS17: R.KUALI | AT17: R.KUALI | AU17: DZUHUR | AV17: R.KUALI | AW17: R.KUALI | AX17: R.KUALI | AY17: R.KUALI | BE17: LITERASI | BF17: R.46 | BG17: R.46 | BH17: R.34 | BI17: R.34 | BJ17: R.46 | BL17: R.46 | BM17: R.46 | BN17: DZUHUR | BO17: R.46 | BP17: R.46 | BW17: JUMAT BERSIH | BX17: R.46 | BY17: R.46 | BZ17: R.46 | CA17: R.46 | CB17: R.46 | CD17: DZUHUR | CE17: R.46 | CF17: R.46 | CG17: R.46 | CH17: R.46
C18: GURU | D18: 18 | F18: TESSA | G18: TESSA | H18: OMAN | I18: OMAN | K18: SABILA | L18: SABILA | M18: MESJID | N18: MELI | O18: MELI | P18: UJANG | Q18: UJANG | U18: BERGIZI | V18: NADIA | W18: NADIA | X18: TUBAGUS | Y18: TUBAGUS | Z18: SUGI | AB18: SUGI | AC18: YENI | AD18: YENI | AE18: MESJID | AF18: MELI | AG18: MELI | AH18: DI KELAS | AM18: TADARUS | AN18: SUGI | AO18: SUGI | AP18: KIKI | AQ18: KIKI | AS18: KIKI | AT18: KIKI | AU18: MESJID | AV18: KIKI | AW18: KIKI | AX18: KIKI | AY18: KIKI | BE18: DI KELAS | BF18: APRIL | BG18: APRIL | BH18: SABILA | BI18: SABILA | BJ18: HALIDA | BL18: OMAN | BM18: OMAN | BN18: MESJID | BO18: ADIW | BP18: ADIW | BQ18: DI KELAS | BR18: DI KELAS | BX18: RANI | BY18: RANI | BZ18: SAMSU | CA18: SAMSU | CB18: SAMSU | CC18: DI KELAS | CD18: MESJID | CE18: NADIA | CF18: NADIA | CG18: UJANG | CH18: UJANG
D19: 19 | J19: R | U19: DI KELAS | AA19: R | AM19: DI LAPANG | AP19: SUGI | AQ19: SUGI | AR19: R | AS19: SUGI | AT19: SUGI | AV19: SUGI | AW19: SUGI | AX19: SUGI | AY19: SUGI | BK19: R | CI19: R
D20: 20
B21: X KA 4 | C21: MAPEL | D21: 21 | E21: UPACARA/ | F21: BIND | G21: BIND | H21: MATH | I21: MATH | K21: BSUN | L21: BSUN | M21: ISTIRAHAT | N21: KIMIA | O21: KIMIA | P21: IPAS | Q21: IPAS | U21: TADARUS & | V21: INFR | W21: INFR | X21: BIND | Y21: BIND | Z21: MATH | AB21: MATH | AC21: BPBK | AD21: ISTIRAHAT | AE21: PABP | AF21: PABP | AG21: PABP | AH21: TUGAS MANDIRI | AM21: SHOLAT | AN21: DPK | AO21: DPK | AP21: DPK | AQ21: DPK | AS21: DPK | AT21: DPK | AU21: ISTIRAHAT | AV21: DPK | AW21: DPK | AX21: DPK | AY21: DPK | BE21: TADARUS & | BF21: IPAS | BG21: IPAS | BH21: INFR | BI21: INFR | BJ21: BING | BL21: BING | BM21: SJRH | BN21: ISTIRAHAT | BO21: SJRH | BP21: PPAN | BQ21: PPAN | BR21: TUGAS MANDIRI | BW21: SENAM & | BX21: PJOK | BY21: PJOK | BZ21: BING | CA21: BING | CB21: DPK | CC21: DPK | CD21: ISTIRAHAT | CE21: SBDY | CF21: SBDY | CG21: TUGAS MANDIRI | CH21: TUGAS MANDIRI | CN21: =COUNTIF($F$21:$CK$21,CN5) -> 3 | CO21: =COUNTIF($F$21:$CK$21,CO5) -> 2 | CP21: =COUNTIF($F$21:$CK$21,CP5) -> 4 | CQ21: =COUNTIF($F$21:$CK$21,CQ5) -> 2 | CR21: =COUNTIF($F$21:$CK$21,CR5) -> 2 | CS21: =COUNTIF($F$21:$CK$21,CS5) -> 2 | CT21: =COUNTIF($F$21:$CK$21,CT5) -> 2 | CU21: =COUNTIF($F$21:$CK$21,CU5) -> 4 | ... DG21: =COUNTIF($F$21:$CK$21,DG5) -> 1 | DH21: =SUM(CN21:DG21) -> 52
C22: RUANG | D22: 22 | E22: PERWALIAN | F22: R.47 | G22: R.47 | H22: R.47 | I22: R.47 | J22: A | K22: R.47 | L22: R.47 | M22: DZUHUR | N22: R.47 | O22: R.47 | P22: R.47 | Q22: R.47 | U22: SARAPAN | V22: R.34 | W22: R.34 | X22: R.47 | Y22: R.47 | Z22: R.47 | AA22: A | AB22: R.47 | AC22: R.47 | AD22: DZUHUR | AE22: R.47 | AF22: R.47 | AG22: R.47 | AM22: DHUHA & | AN22: R.DPK | AO22: R.DPK | AP22: R.DPK | AQ22: R.DPK | AR22: A | AS22: R.DPK | AT22: R.DPK | AU22: DZUHUR | AV22: R.DPK | AW22: R.DPK | AX22: R.DPK | AY22: R.DPK | BE22: LITERASI | BF22: R.47 | BG22: R.47 | BH22: R.47 | BI22: R.47 | BJ22: R.47 | BK22: A | BL22: R.47 | BM22: R.47 | BN22: DZUHUR | BO22: R.47 | BP22: R.47 | BQ22: R.47 | BW22: JUMAT BERSIH | BX22: LAP | BY22: LAP | BZ22: R.47 | CA22: R.47 | CB22: R.47 | CC22: R.47 | CD22: DZUHUR | CE22: R.47 | CF22: R.47 | CI22: A
C23: GURU | D23: 23 | F23: MELI | G23: MELI | H23: NADIA | I23: NADIA | K23: RANI | L23: RANI | M23: MESJID | N23: TESSA | O23: TESSA | P23: OMAN | Q23: OMAN | U23: BERGIZI | V23: ERMA | W23: ERMA | X23: MELI | Y23: MELI | Z23: NADIA | AB23: NADIA | AC23: HALIDA | AD23: MESJID | AE23: SAMSU | AF23: SAMSU | AG23: SAMSU | AH23: DI KELAS | AM23: TADARUS | AN23: ULI | AO23: ULI | AP23: TITA | AQ23: TITA | AS23: TITA | AT23: TITA | AU23: MESJID | AV23: TITA | AW23: TITA | AX23: TITA | AY23: TITA | BE23: DI KELAS | BF23: OMAN | BG23: OMAN | BH23: ERMA | BI23: ERMA | BJ23: UJANG | BL23: UJANG | BM23: APRIL | BN23: MESJID | BO23: APRIL | BP23: SUKMA | BQ23: SUKMA | BR23: DI KELAS | BX23: YENI | BY23: YENI | BZ23: UJANG | CA23: UJANG | CB23: ULI | CC23: ULI | CD23: MESJID | CE23: ADIW | CF23: ADIW | CG23: DI KELAS | CH23: DI KELAS
D24: 24 | U24: DI KELAS | AM24: DI LAPANG | AP24: TESSA | AQ24: TESSA | AS24: TESSA | AT24: TESSA | AV24: TESSA | AW24: TESSA | AX24: TESSA | AY24: TESSA
D25: 25 | J25: H | AA25: H | AR25: H | BK25: H | CI25: H
B26: X KA 5 | C26: MAPEL | D26: 26 | E26: UPACARA/ | F26: MATH | G26: MATH | H26: BING | I26: BING | K26: INFR | L26: INFR | M26: ISTIRAHAT | N26: PPAN | O26: PPAN | P26: SJRH | Q26: SJRH | U26: TADARUS & | V26: DPK | W26: DPK | X26: INFR | Y26: INFR | Z26: BING | AB26: BING | AC26: BSUN | AD26: BSUN | AE26: ISTIRAHAT | AF26: TUGAS MANDIRI | AG26: TUGAS MANDIRI | AH26: TUGAS MANDIRI | AM26: SHOLAT | AN26: BIND | AO26: BIND | AP26: BPBK | AQ26: PABP | AS26: PABP | AT26: PABP | AU26: ISTIRAHAT | AV26: MATH | AW26: MATH | AX26: IPAS | AY26: IPAS | BE26: TADARUS & | BF26: DPK | BG26: DPK | BH26: DPK | BI26: DPK | BJ26: DPK | BL26: DPK | BM26: DPK | BN26: ISTIRAHAT | BO26: DPK | BP26: DPK | BQ26: DPK | BR26: TUGAS MANDIRI | BW26: SENAM & | BX26: SBDY | BY26: SBDY | BZ26: IPAS | CA26: IPAS | CB26: BIND | CC26: BIND | CD26: ISTIRAHAT | CE26: KIMIA | CF26: KIMIA | CG26: PJOK | CH26: PJOK | CN26: =COUNTIF($F$26:$CK$26,CN5) -> 3 | CO26: =COUNTIF($F$26:$CK$26,CO5) -> 2 | CP26: =COUNTIF($F$26:$CK$26,CP5) -> 4 | CQ26: =COUNTIF($F$26:$CK$26,CQ5) -> 2 | CR26: =COUNTIF($F$26:$CK$26,CR5) -> 2 | CS26: =COUNTIF($F$26:$CK$26,CS5) -> 2 | CT26: =COUNTIF($F$26:$CK$26,CT5) -> 2 | CU26: =COUNTIF($F$26:$CK$26,CU5) -> 4 | ... DG26: =COUNTIF($F$26:$CK$26,DG5) -> 1 | DH26: =SUM(CN26:DG26) -> 52
C27: RUANG | D27: 27 | E27: PERWALIAN | F27: R.48 | G27: R.48 | H27: R.48 | I27: R.48 | K27: R.34 | L27: R.34 | M27: DZUHUR | N27: R.48 | O27: R.48 | P27: R.48 | Q27: R.48 | U27: SARAPAN | V27: R.48 | W27: R.48 | X27: R.48 | Y27: R.48 | Z27: R.48 | AB27: R.48 | AC27: R.48 | AD27: R.48 | AE27: DZUHUR | AM27: DHUHA & | AN27: R.48 | AO27: R.48 | AP27: R.48 | AQ27: R.48 | AS27: R.48 | AT27: R.48 | AU27: DZUHUR | AV27: R.48 | AW27: R.48 | AX27: R.48 | AY27: R.48 | BE27: LITERASI | BF27: R.DPK | BG27: R.DPK | BH27: R.DPK | BI27: R.DPK | BJ27: R.DPK | BL27: R.DPK | BM27: R.DPK | BN27: DZUHUR | BO27: R.DPK | BP27: R.DPK | BQ27: R.DPK | BW27: JUMAT BERSIH | BX27: R.48 | BY27: R.48 | BZ27: R.48 | CA27: R.48 | CB27: R.48 | CC27: R.48 | CD27: DZUHUR | CE27: R.48 | CF27: R.48 | CG27: LAP | CH27: LAP
C28: GURU | D28: 28 | F28: NADIA | G28: NADIA | H28: UJANG | I28: UJANG | J28: A | K28: ERMA | L28: ERMA | M28: MESJID | N28: SUKMA | O28: SUKMA | P28: APRIL | Q28: APRIL | U28: BERGIZI | V28: TITA | W28: TITA | X28: ERMA | Y28: ERMA | Z28: UJANG | AA28: A | AB28: UJANG | AC28: RANI | AD28: RANI | AE28: MESJID | AF28: DI KELAS | AG28: DI KELAS | AH28: DI KELAS | AM28: TADARUS | AN28: MELI | AO28: MELI | AP28: HALIDA | AQ28: SAMSU | AR28: A | AS28: SAMSU | AT28: SAMSU | AU28: MESJID | AV28: NADIA | AW28: NADIA | AX28: OMAN | AY28: OMAN | BE28: DI KELAS | BF28: TITA | BG28: TITA | BH28: TITA | BI28: TITA | BJ28: TITA | BK28: A | BL28: TITA | BM28: TITA | BN28: MESJID | BO28: TITA | BP28: TITA | BQ28: TITA | BR28: DI KELAS | BX28: ADIW | BY28: ADIW | BZ28: OMAN | CA28: OMAN | CB28: MELI | CC28: MELI | CD28: MESJID | CE28: FERTIKA | CF28: FERTIKA | CG28: YENI | CH28: YENI | CI28: A
D29: 29 | U29: DI KELAS | AM29: DI LAPANG | BH29: KIKI | BI29: KIKI | BJ29: KIKI | BL29: KIKI | BM29: KIKI | BO29: KIKI | BP29: KIKI | BQ29: KIKI
D30: 30
B31: X KA 6 | C31: MAPEL | D31: 31 | E31: UPACARA/ | F31: DPK | G31: DPK | H31: INFR | I31: INFR | J31: T | K31: IPAS | L31: IPAS | M31: ISTIRAHAT | N31: PABP | O31: PABP | P31: PABP | Q31: TUGAS MANDIRI | U31: TADARUS & | V31: BIND | W31: BIND | X31: BING | Y31: BING | Z31: BSUN | AA31: T | AB31: BSUN | AC31: MATH | AD31: MATH | AE31: ISTIRAHAT | AF31: PJOK | AG31: PJOK | AH31: TUGAS MANDIRI | AM31: SHOLAT | AN31: INFR | AO31: INFR | AP31: SBDY | AQ31: SBDY | AR31: T | AS31: BIND | AT31: BIND | AU31: ISTIRAHAT | AV31: SJRH | AW31: SJRH | AX31: MATH | AY31: MATH | BE31: TADARUS & | BF31: PPAN | BG31: PPAN | BH31: IPAS | BI31: IPAS | BJ31: KIMIA | BK31: T | BL31: KIMIA | BM31: BING | BN31: ISTIRAHAT | BO31: BING | BP31: BPBK | BQ31: TUGAS MANDIRI | BR31: TUGAS MANDIRI | BW31: SENAM & | BX31: DPK | BY31: DPK | BZ31: DPK | CA31: DPK | CB31: DPK | CC31: DPK | CD31: ISTIRAHAT | CE31: DPK | CF31: DPK | CG31: DPK | CH31: DPK | CI31: T | CN31: =COUNTIF($F$31:$CK$31,CN5) -> 3 | CO31: =COUNTIF($F$31:$CK$31,CO5) -> 2 | CP31: =COUNTIF($F$31:$CK$31,CP5) -> 4 | CQ31: =COUNTIF($F$31:$CK$31,CQ5) -> 2 | CR31: =COUNTIF($F$31:$CK$31,CR5) -> 2 | CS31: =COUNTIF($F$31:$CK$31,CS5) -> 2 | CT31: =COUNTIF($F$31:$CK$31,CT5) -> 2 | CU31: =COUNTIF($F$31:$CK$31,CU5) -> 4 | ... DG31: =COUNTIF($F$31:$CK$31,DG5) -> 1 | DH31: =SUM(CN31:DG31) -> 52
C32: RUANG | D32: 32 | E32: PERWALIAN | F32: R.30 | G32: R.30 | H32: R.30 | I32: R.30 | K32: R.30 | L32: R.30 | M32: DZUHUR | N32: R.30 | O32: R.30 | P32: R.30 | U32: SARAPAN | V32: R.30 | W32: R.30 | X32: R.30 | Y32: R.30 | Z32: R.30 | AB32: R.30 | AC32: R.30 | AD32: R.30 | AE32: DZUHUR | AF32: LAP | AG32: LAP | AM32: DHUHA & | AN32: R.34 | AO32: R.34 | AP32: R.30 | AQ32: R.30 | AS32: R.30 | AT32: R.30 | AU32: DZUHUR | AV32: R.30 | AW32: R.30 | AX32: R.30 | AY32: R.30 | BE32: LITERASI | BF32: R.30 | BG32: R.30 | BH32: R.30 | BI32: R.30 | BJ32: R.30 | BL32: R.30 | BM32: R.30 | BN32: DZUHUR | BO32: R.30 | BP32: R.30 | BW32: JUMAT BERSIH | BX32: R.DPK | BY32: R.DPK | BZ32: R.DPK | CA32: R.DPK | CB32: R.DPK | CC32: R.DPK | CD32: DZUHUR | CE32: R.DPK | CF32: R.DPK | CG32: R.DPK | CH32: R.DPK
C33: GURU | D33: 33 | F33: KIKI | G33: KIKI | H33: ERMA | I33: ERMA | K33: OMAN | L33: OMAN | M33: MESJID | N33: SAMSU | O33: SAMSU | P33: SAMSU | Q33: DI KELAS | U33: BERGIZI | V33: MELI | W33: MELI | X33: UJANG | Y33: UJANG | Z33: RANI | AB33: RANI | AC33: NADIA | AD33: NADIA | AE33: MESJID | AF33: YENI | AG33: YENI | AH33: DI KELAS | AM33: TADARUS | AN33: ERMA | AO33: ERMA | AP33: ADIW | AQ33: ADIW | AS33: MELI | AT33: MELI | AU33: MESJID | AV33: APRIL | AW33: APRIL | AX33: NADIA | AY33: NADIA | BE33: DI KELAS | BF33: SUKMA | BG33: SUKMA | BH33: OMAN | BI33: OMAN | BJ33: FERTIKA | BL33: FERTIKA | BM33: UJANG | BN33: MESJID | BO33: UJANG | BP33: HALIDA | BQ33: DI KELAS | BR33: DI KELAS | BX33: KIKI | BY33: KIKI | BZ33: KIKI | CA33: KIKI | CB33: KIKI | CC33: KIKI | CD33: MESJID | CE33: KIKI | CF33: KIKI | CG33: KIKI | CH33: KIKI
D34: 34 | U34: DI KELAS | AM34: DI LAPANG | BZ34: GINA | CA34: GINA | CB34: GINA | CC34: GINA | CE34: GINA | CF34: GINA | CG34: GINA | CH34: GINA
D35: 35
D36: 36 | CN36: PABP | CO36: PPAN | CP36: BIND | CQ36: PJOK | CR36: SJRH | CT36: BSUN | CU36: MATH | CV36: BING | CY36: ABO | CZ36: ABA | DA36: ATG | DB36: AKI | DC36: STA | DD36: PKK | DE36: TUGAS MANDIRI | DG36: BPBK
B37: XI KA 1 | C37: MAPEL | D37: 37 | E37: UPACARA/ | F37: BPBK | G37: ATG | H37: ATG | I37: ATG | K37: ATG | L37: ATG | M37: ISTIRAHAT | N37: ATG | O37: ATG | P37: ATG | Q37: ATG | U37: TADARUS & | V37: PKK | W37: PKK | X37: PPAN | Y37: PPAN | Z37: ABO | AB37: ABO | AC37: AKI | AD37: AKI | AE37: ISTIRAHAT | AF37: PJOK | AG37: PJOK | AH37: TUGAS MANDIRI | AM37: SHOLAT | AN37: BING | AO37: BING | AP37: ABA | AQ37: ABA | AS37: STA | AT37: STA | AU37: ISTIRAHAT | AV37: PABP | AW37: PABP | AX37: PABP | AY37: TUGAS MANDIRI | BE37: TADARUS & | BF37: BING | BG37: BING | BH37: AKI | BI37: AKI | BJ37: AKI | BL37: AKI | BM37: AKI | BN37: ISTIRAHAT | BO37: SJRH | BP37: SJRH | BQ37: TUGAS MANDIRI | BR37: TUGAS MANDIRI | BW37: SENAM & | BX37: BIND | BY37: BIND | BZ37: BIND | CA37: MATH | CB37: MATH | CC37: MATH | CD37: ISTIRAHAT | CE37: BSUN | CF37: BSUN | CG37: TUGAS MANDIRI | CH37: TUGAS MANDIRI | CN37: =COUNTIF($F$37:$CK$37,CN36) -> 3 | CO37: =COUNTIF($F$37:$CK$37,CO36) -> 2 | CP37: =COUNTIF($F$37:$CK$37,CP36) -> 3 | CQ37: =COUNTIF($F$37:$CK$37,CQ36) -> 2 | CR37: =COUNTIF($F$37:$CK$37,CR36) -> 2 | CS37: =COUNTIF($F$37:$CK$37,CS36) -> 0 | CT37: =COUNTIF($F$37:$CK$37,CT36) -> 2 | CU37: =COUNTIF($F$37:$CK$37,CU36) -> 3 | ... DG37: =COUNTIF($F$37:$CK$37,DG36) -> 1 | DH37: =SUM(CN37:DG37) -> 52
C38: RUANG | D38: 38 | E38: PERWALIAN | F38: R.ATG | G38: R.ATG | H38: R.ATG | I38: R.ATG | J38: I | K38: R.ATG | L38: R.ATG | M38: DZUHUR | N38: R.ATG | O38: R.ATG | P38: R.ATG | Q38: R.ATG | U38: SARAPAN | V38: R.61 | W38: R.61 | X38: R.61 | Y38: R.61 | Z38: R.61 | AA38: I | AB38: R.61 | AC38: R.61 | AD38: R.61 | AE38: DZUHUR | AF38: LAP | AG38: LAP | AM38: DHUHA & | AN38: R.61 | AO38: R.61 | AP38: R.61 | AQ38: R.61 | AR38: I | AS38: R.61 | AT38: R.61 | AU38: DZUHUR | AV38: R.61 | AW38: R.61 | AX38: R.61 | BE38: LITERASI | BF38: R.61 | BG38: R.61 | BH38: R.AKIXI | BI38: R.AKIXI | BJ38: R.AKIXI | BK38: I | BL38: R.AKIXI | BM38: R.AKIXI | BN38: DZUHUR | BO38: R.61 | BP38: R.61 | BW38: JUMAT BERSIH | BX38: R.61 | BY38: R.61 | BZ38: R.61 | CA38: R.61 | CB38: R.61 | CC38: R.61 | CD38: DZUHUR | CE38: R.61 | CF38: R.61 | CI38: I
C39: GURU | D39: 39 | F39: HAZAR | G39: ADE | H39: ADE | I39: ADE | K39: ADE | L39: ADE | M39: MESJID | N39: ADE | O39: ADE | P39: ADE | Q39: ADE | U39: BERGIZI | V39: TESSA | W39: TESSA | X39: ELA | Y39: ELA | Z39: RAHMI | AB39: RAHMI | AC39: IAH | AD39: IAH | AE39: MESJID | AF39: TAUFIK | AG39: TAUFIK | AH39: DI KELAS | AM39: TADARUS | AN39: SHENDY | AO39: SHENDY | AP39: ELA.N | AQ39: ELA.N | AS39: DENA | AT39: DENA | AU39: MESJID | AV39: RUHYA | AW39: RUHYA | AX39: RUHYA | AY39: DI KELAS | BE39: DI KELAS | BF39: SHENDY | BG39: SHENDY | BH39: IAH | BI39: IAH | BJ39: IAH | BL39: IAH | BM39: IAH | BN39: MESJID | BO39: SUDARMI | BP39: SUDARMI | BQ39: DI KELAS | BR39: DI KELAS | BX39: REGINA | BY39: REGINA | BZ39: REGINA | CA39: SARI | CB39: SARI | CC39: SARI | CD39: MESJID | CE39: RANI | CF39: RANI | CG39: DI KELAS | CH39: DI KELAS
D40: 40 | I40: ENDANG | K40: ENDANG | L40: ENDANG | N40: ENDANG | O40: ENDANG | P40: ENDANG | Q40: ENDANG | U40: DI KELAS | AM40: DI LAPANG | BH40: POPONG | BI40: POPONG | BJ40: POPONG | BL40: POPONG | BM40: POPONG
...

Sheet JAM GURU
F1: SENIN | V1: SELASA | AL1: RABU | BF1: KAMIS | BV1: JUMAT
A2: NO | B2: NAMA GURU | C2: KODE | F2: 2 | G2: 3 | H2: 4 | I2: 5 | K2: 6 | L2: 7 | M2: 8 | N2: 9 | O2: 10 | P2: 11 | Q2: 12 | R2: 13 | S2: 11 | T2: JUMLAH | V2: 1 | W2: 2 | X2: 3 | Y2: 4 | Z2: 5 | AB2: 6 | AC2: 7 | AD2: 8 | AE2: 9 | AF2: 10 | AG2: 11 | AH2: 12 | AI2: 13 | AJ2: 16 | AK2: JUMLAH | AM2: 1 | AN2: 2 | AO2: 3 | AP2: 4 | AQ2: 5 | AS2: 6 | AT2: 7 | AU2: 8 | AV2: 9 | AW2: 10 | AX2: 11 | AY2: 12 | BA2: 13 | BB2: JUMLAH | BE2: 1 | BF2: 2 | BG2: 3 | BH2: 4 | BI2: 5 | BK2: 6 | BL2: 7 | BM2: 8 | BN2: 9 | BO2: 10 | BP2: 11 | BQ2: 12 | BR2: 13 | BS2: 14 | BT2: JUMLAH | BV2: 1 | BW2: 2 | BX2: 3 | BY2: 4 | BZ2: 5 | CA2: 6 | CB2: 7 | CD2: 8 | CE2: 9 | CF2: 10 | CG2: 11 | CH2: 12 | CI2: 13 | CJ2: 14 | CK2: JUMLAH
A3: ='MASTER GURU HARIAN'!A5 -> 1 | B3: ='MASTER GURU HARIAN'!B5 -> OMAN SOMANA, M.Pd. | C3: ='MASTER GURU HARIAN'!C5 -> G1 | D3: ='MASTER GURU HARIAN'!D5 -> OMAN | F3: =COUNTIF(JADWAL!F$6:F$195,$D3) -> 0 | G3: =COUNTIF(JADWAL!G$6:G$195,$D3) -> 0 | H3: =COUNTIF(JADWAL!H$6:H$195,$D3) -> 1 | I3: =COUNTIF(JADWAL!I$6:I$195,$D3) -> 1 | J3: =COUNTIF(JADWAL!J$6:J$195,$D3) -> 0 | K3: =COUNTIF(JADWAL!K$6:K$195,$D3) -> 1 | L3: =COUNTIF(JADWAL!L$6:L$195,$D3) -> 1 | M3: =COUNTIF(JADWAL!M$6:M$195,$D3) -> 0 | ... S3: =COUNTIF(JADWAL!S$6:S$195,$D3) -> 0 | T3: =SUM(D3:S3) -> 6 | V3: =COUNTIF(JADWAL!V$6:V$195,$D3) -> 0 | W3: =COUNTIF(JADWAL!W$6:W$195,$D3) -> 0 | X3: =COUNTIF(JADWAL!X$6:X$195,$D3) -> 0 | Y3: =COUNTIF(JADWAL!Y$6:Y$195,$D3) -> 0 | Z3: =COUNTIF(JADWAL!Z$6:Z$195,$D3) -> 0 | AB3: =COUNTIF(JADWAL!AB$6:AB$195,$D3) -> 0 | AC3: =COUNTIF(JADWAL!AC$6:AC$195,$D3) -> 0 | AD3: =COUNTIF(JADWAL!AD$6:AD$195,$D3) -> 0 | AE3: =COUNTIF(JADWAL!AE$6:AE$195,$D3) -> 0 | AF3: =COUNTIF(JADWAL!AF$6:AF$195,$D3) -> 0 | AG3: =COUNTIF(JADWAL!AG$6:AG$195,$D3) -> 0 | AH3: =COUNTIF(JADWAL!AH$6:AH$195,$D3) -> 0 | AK3: =SUM(V3:AJ3) -> 0 | AM3: =COUNTIF(JADWAL!AM$6:AM$195,$D3) -> 0 | AN3: =COUNTIF(JADWAL!AN$6:AN$195,$D3) -> 0 | AO3: =COUNTIF(JADWAL!AO$6:AO$195,$D3) -> 0 | AP3: =COUNTIF(JADWAL!AP$6:AP$195,$D3) -> 1 | AQ3: =COUNTIF(JADWAL!AQ$6:AQ$195,$D3) -> 1 | AS3: =COUNTIF(JADWAL!AS$6:AS$195,$D3) -> 0 | AT3: =COUNTIF(JADWAL!AT$6:AT$195,$D3) -> 0 | AU3: =COUNTIF(JADWAL!AU$6:AU$195,$D3) -> 0 | AV3: =COUNTIF(JADWAL!AV$6:AV$195,$D3) -> 1 | AW3: =COUNTIF(JADWAL!AW$6:AW$195,$D3) -> 1 | AX3: =COUNTIF(JADWAL!AX$6:AX$195,$D3) -> 1 | AY3: =COUNTIF(JADWAL!AY$6:AY$195,$D3) -> 1 | AZ3: =COUNTIF(JADWAL!AZ$6:AZ$195,$D3) -> 0 | BA3: =COUNTIF(JADWAL!BA$6:BA$195,$D3) -> 0 | BB3: =SUM(AL3:BA3) -> 6 | BE3: =COUNTIF(JADWAL!BF$6:BF$195,$D3) -> 1 | BF3: =COUNTIF(JADWAL!BG$6:BG$195,$D3) -> 1 | BG3: =COUNTIF(JADWAL!BH$6:BH$195,$D3) -> 1 | BH3: =COUNTIF(JADWAL!BI$6:BI$195,$D3) -> 1 | BI3: =COUNTIF(JADWAL!BJ$6:BJ$195,$D3) -> 0 | BK3: =COUNTIF(JADWAL!BL$6:BL$195,$D3) -> 1 | BL3: =COUNTIF(JADWAL!BM$6:BM$195,$D3) -> 1 | BM3: =COUNTIF(JADWAL!BN$6:BN$195,$D3) -> 0 | BN3: =COUNTIF(JADWAL!BO$6:BO$195,$D3) -> 0 | BO3: =COUNTIF(JADWAL!BP$6:BP$195,$D3) -> 0 | BP3: =COUNTIF(JADWAL!BQ$6:BQ$195,$D3) -> 0 | BQ3: =COUNTIF(JADWAL!BR$6:BR$195,$D3) -> 0 | BS3: =COUNTIF(JADWAL!BT$6:BT$195,$D3) -> 0 | BT3: =SUM(BE3:BS3) -> 6 | BV3: =COUNTIF(JADWAL!BW$6:BW$195,$D3) -> 0 | BW3: =COUNTIF(JADWAL!BX$6:BX$195,$D3) -> 0 | BX3: =COUNTIF(JADWAL!BY$6:BY$195,$D3) -> 0 | BY3: =COUNTIF(JADWAL!BZ$6:BZ$195,$D3) -> 1 | BZ3: =COUNTIF(JADWAL!CA$6:CA$195,$D3) -> 1 | CA3: =COUNTIF(JADWAL!CB$6:CB$195,$D3) -> 1 | CB3: =COUNTIF(JADWAL!CC$6:CC$195,$D3) -> 1 | CD3: =COUNTIF(JADWAL!CE$6:CE$195,$D3) -> 0 | CE3: =COUNTIF(JADWAL!CF$6:CF$195,$D3) -> 0 | CF3: =COUNTIF(JADWAL!CG$6:CG$195,$D3) -> 1 | CG3: =COUNTIF(JADWAL!CH$6:CH$195,$D3) -> 1 | CH3: =COUNTIF(JADWAL!CI$6:CI$195,$D3) -> 0 | CI3: =COUNTIF(JADWAL!CJ$6:CJ$195,$D3) -> 0 | CK3: =SUM(BV3:CJ3) -> 6 | CL3: =T3+AK3+BB3+BT3+CK3 -> 24
A4: ='MASTER GURU HARIAN'!A6 -> 2 | B4: ='MASTER GURU HARIAN'!B6 -> DADAN RUKMA DIAN DAWAN, S.Pd | C4: ='MASTER GURU HARIAN'!C6 -> G2 | D4: ='MASTER GURU HARIAN'!D6 -> DADAN | F4: =COUNTIF(JADWAL!F$6:F$195,$D4) -> 0 | G4: =COUNTIF(JADWAL!G$6:G$195,$D4) -> 0 | H4: =COUNTIF(JADWAL!H$6:H$195,$D4) -> 0 | I4: =COUNTIF(JADWAL!I$6:I$195,$D4) -> 0 | J4: =COUNTIF(JADWAL!J$6:J$195,$D4) -> 0 | K4: =COUNTIF(JADWAL!K$6:K$195,$D4) -> 0 | L4: =COUNTIF(JADWAL!L$6:L$195,$D4) -> 0 | M4: =COUNTIF(JADWAL!M$6:M$195,$D4) -> 0 | ... S4: =COUNTIF(JADWAL!S$6:S$195,$D4) -> 0 | T4: =SUM(D4:S4) -> 0 | V4: =COUNTIF(JADWAL!V$6:V$195,$D4) -> 1 | W4: =COUNTIF(JADWAL!W$6:W$195,$D4) -> 1 | X4: =COUNTIF(JADWAL!X$6:X$195,$D4) -> 1 | Y4: =COUNTIF(JADWAL!Y$6:Y$195,$D4) -> 0 | Z4: =COUNTIF(JADWAL!Z$6:Z$195,$D4) -> 1 | AB4: =COUNTIF(JADWAL!AB$6:AB$195,$D4) -> 1 | AC4: =COUNTIF(JADWAL!AC$6:AC$195,$D4) -> 1 | AD4: =COUNTIF(JADWAL!AD$6:AD$195,$D4) -> 0 | AE4: =COUNTIF(JADWAL!AE$6:AE$195,$D4) -> 0 | AF4: =COUNTIF(JADWAL!AF$6:AF$195,$D4) -> 0 | AG4: =COUNTIF(JADWAL!AG$6:AG$195,$D4) -> 0 | AH4: =COUNTIF(JADWAL!AH$6:AH$195,$D4) -> 0 | AK4: =SUM(V4:AJ4) -> 6 | AM4: =COUNTIF(JADWAL!AM$6:AM$195,$D4) -> 0 | AN4: =COUNTIF(JADWAL!AN$6:AN$195,$D4) -> 0 | AO4: =COUNTIF(JADWAL!AO$6:AO$195,$D4) -> 0 | AP4: =COUNTIF(JADWAL!AP$6:AP$195,$D4) -> 0 | AQ4: =COUNTIF(JADWAL!AQ$6:AQ$195,$D4) -> 0 | AS4: =COUNTIF(JADWAL!AS$6:AS$195,$D4) -> 0 | AT4: =COUNTIF(JADWAL!AT$6:AT$195,$D4) -> 0 | AU4: =COUNTIF(JADWAL!AU$6:AU$195,$D4) -> 0 | AV4: =COUNTIF(JADWAL!AV$6:AV$195,$D4) -> 0 | AW4: =COUNTIF(JADWAL!AW$6:AW$195,$D4) -> 1 | AX4: =COUNTIF(JADWAL!AX$6:AX$195,$D4) -> 1 | AY4: =COUNTIF(JADWAL!AY$6:AY$195,$D4) -> 1 | AZ4: =COUNTIF(JADWAL!AZ$6:AZ$195,$D4) -> 0 | BA4: =COUNTIF(JADWAL!BA$6:BA$195,$D4) -> 0 | BB4: =SUM(AL4:BA4) -> 3 | BE4: =COUNTIF(JADWAL!BF$6:BF$195,$D4) -> 0 | BF4: =COUNTIF(JADWAL!BG$6:BG$195,$D4) -> 0 | BG4: =COUNTIF(JADWAL!BH$6:BH$195,$D4) -> 0 | BH4: =COUNTIF(JADWAL!BI$6:BI$195,$D4) -> 0 | BI4: =COUNTIF(JADWAL!BJ$6:BJ$195,$D4) -> 1 | BK4: =COUNTIF(JADWAL!BL$6:BL$195,$D4) -> 1 | BL4: =COUNTIF(JADWAL!BM$6:BM$195,$D4) -> 1 | BM4: =COUNTIF(JADWAL!BN$6:BN$195,$D4) -> 0 | BN4: =COUNTIF(JADWAL!BO$6:BO$195,$D4) -> 0 | BO4: =COUNTIF(JADWAL!BP$6:BP$195,$D4) -> 0 | BP4: =COUNTIF(JADWAL!BQ$6:BQ$195,$D4) -> 0 | BQ4: =COUNTIF(JADWAL!BR$6:BR$195,$D4) -> 0 | BS4: =COUNTIF(JADWAL!BT$6:BT$195,$D4) -> 0 | BT4: =SUM(BE4:BS4) -> 3 | BV4: =COUNTIF(JADWAL!BW$6:BW$195,$D4) -> 0 | BW4: =COUNTIF(JADWAL!BX$6:BX$195,$D4) -> 1 | BX4: =COUNTIF(JADWAL!BY$6:BY$195,$D4) -> 1 | BY4: =COUNTIF(JADWAL!BZ$6:BZ$195,$D4) -> 1 | BZ4: =COUNTIF(JADWAL!CA$6:CA$195,$D4) -> 1 | CA4: =COUNTIF(JADWAL!CB$6:CB$195,$D4) -> 1 | CB4: =COUNTIF(JADWAL!CC$6:CC$195,$D4) -> 1 | CD4: =COUNTIF(JADWAL!CE$6:CE$195,$D4) -> 0 | CE4: =COUNTIF(JADWAL!CF$6:CF$195,$D4) -> 0 | CF4: =COUNTIF(JADWAL!CG$6:CG$195,$D4) -> 0 | CG4: =COUNTIF(JADWAL!CH$6:CH$195,$D4) -> 0 | CH4: =COUNTIF(JADWAL!CI$6:CI$195,$D4) -> 0 | CI4: =COUNTIF(JADWAL!CJ$6:CJ$195,$D4) -> 0 | CK4: =SUM(BV4:CJ4) -> 6 | CL4: =T4+AK4+BB4+BT4+CK4 -> 18
A5: ='MASTER GURU HARIAN'!A7 -> 3 | B5: ='MASTER GURU HARIAN'!B7 -> POPONG WARIATI, S.Pd. | C5: ='MASTER GURU HARIAN'!C7 -> G3 | D5: ='MASTER GURU HARIAN'!D7 -> POPONG | F5: =COUNTIF(JADWAL!F$6:F$195,$D5) -> 1 | G5: =COUNTIF(JADWAL!G$6:G$195,$D5) -> 1 | H5: =COUNTIF(JADWAL!H$6:H$195,$D5) -> 1 | I5: =COUNTIF(JADWAL!I$6:I$195,$D5) -> 1 | J5: =COUNTIF(JADWAL!J$6:J$195,$D5) -> 0 | K5: =COUNTIF(JADWAL!K$6:K$195,$D5) -> 1 | L5: =COUNTIF(JADWAL!L$6:L$195,$D5) -> 1 | M5: =COUNTIF(JADWAL!M$6:M$195,$D5) -> 1 | ... S5: =COUNTIF(JADWAL!S$6:S$195,$D5) -> 0 | T5: =SUM(D5:S5) -> 7 | V5: =COUNTIF(JADWAL!V$6:V$195,$D5) -> 1 | W5: =COUNTIF(JADWAL!W$6:W$195,$D5) -> 1 | X5: =COUNTIF(JADWAL!X$6:X$195,$D5) -> 1 | Y5: =COUNTIF(JADWAL!Y$6:Y$195,$D5) -> 1 | Z5: =COUNTIF(JADWAL!Z$6:Z$195,$D5) -> 1 | AB5: =COUNTIF(JADWAL!AB$6:AB$195,$D5) -> 0 | AC5: =COUNTIF(JADWAL!AC$6:AC$195,$D5) -> 1 | AD5: =COUNTIF(JADWAL!AD$6:AD$195,$D5) -> 1 | AE5: =COUNTIF(JADWAL!AE$6:AE$195,$D5) -> 0 | AF5: =COUNTIF(JADWAL!AF$6:AF$195,$D5) -> 0 | AG5: =COUNTIF(JADWAL!AG$6:AG$195,$D5) -> 0 | AH5: =COUNTIF(JADWAL!AH$6:AH$195,$D5) -> 0 | AK5: =SUM(V5:AJ5) -> 7 | AM5: =COUNTIF(JADWAL!AM$6:AM$195,$D5) -> 0 | AN5: =COUNTIF(JADWAL!AN$6:AN$195,$D5) -> 1 | AO5: =COUNTIF(JADWAL!AO$6:AO$195,$D5) -> 1 | AP5: =COUNTIF(JADWAL!AP$6:AP$195,$D5) -> 1 | AQ5: =COUNTIF(JADWAL!AQ$6:AQ$195,$D5) -> 1 | AS5: =COUNTIF(JADWAL!AS$6:AS$195,$D5) -> 1 | AT5: =COUNTIF(JADWAL!AT$6:AT$195,$D5) -> 1 | AU5: =COUNTIF(JADWAL!AU$6:AU$195,$D5) -> 0 | AV5: =COUNTIF(JADWAL!AV$6:AV$195,$D5) -> 0 | AW5: =COUNTIF(JADWAL!AW$6:AW$195,$D5) -> 0 | AX5: =COUNTIF(JADWAL!AX$6:AX$195,$D5) -> 0 | AY5: =COUNTIF(JADWAL!AY$6:AY$195,$D5) -> 0 | AZ5: =COUNTIF(JADWAL!AZ$6:AZ$195,$D5) -> 0 | BA5: =COUNTIF(JADWAL!BA$6:BA$195,$D5) -> 0 | BB5: =SUM(AL5:BA5) -> 6 | BE5: =COUNTIF(JADWAL!BF$6:BF$195,$D5) -> 0 | BF5: =COUNTIF(JADWAL!BG$6:BG$195,$D5) -> 0 | BG5: =COUNTIF(JADWAL!BH$6:BH$195,$D5) -> 1 | BH5: =COUNTIF(JADWAL!BI$6:BI$195,$D5) -> 1 | BI5: =COUNTIF(JADWAL!BJ$6:BJ$195,$D5) -> 1 | BK5: =COUNTIF(JADWAL!BL$6:BL$195,$D5) -> 1 | BL5: =COUNTIF(JADWAL!BM$6:BM$195,$D5) -> 1 | BM5: =COUNTIF(JADWAL!BN$6:BN$195,$D5) -> 0 | BN5: =COUNTIF(JADWAL!BO$6:BO$195,$D5) -> 0 | BO5: =COUNTIF(JADWAL!BP$6:BP$195,$D5) -> 0 | BP5: =COUNTIF(JADWAL!BQ$6:BQ$195,$D5) -> 0 | BQ5: =COUNTIF(JADWAL!BR$6:BR$195,$D5) -> 0 | BS5: =COUNTIF(JADWAL!BT$6:BT$195,$D5) -> 0 | BT5: =SUM(BE5:BS5) -> 5 | BV5: =COUNTIF(JADWAL!BW$6:BW$195,$D5) -> 0 | BW5: =COUNTIF(JADWAL!BX$6:BX$195,$D5) -> 0 | BX5: =COUNTIF(JADWAL!BY$6:BY$195,$D5) -> 0 | BY5: =COUNTIF(JADWAL!BZ$6:BZ$195,$D5) -> 0 | BZ5: =COUNTIF(JADWAL!CA$6:CA$195,$D5) -> 0 | CA5: =COUNTIF(JADWAL!CB$6:CB$195,$D5) -> 0 | CB5: =COUNTIF(JADWAL!CC$6:CC$195,$D5) -> 0 | CD5: =COUNTIF(JADWAL!CE$6:CE$195,$D5) -> 0 | CE5: =COUNTIF(JADWAL!CF$6:CF$195,$D5) -> 0 | CF5: =COUNTIF(JADWAL!CG$6:CG$195,$D5) -> 0 | CG5: =COUNTIF(JADWAL!CH$6:CH$195,$D5) -> 0 | CH5: =COUNTIF(JADWAL!CI$6:CI$195,$D5) -> 0 | CI5: =COUNTIF(JADWAL!CJ$6:CJ$195,$D5) -> 0 | CK5: =SUM(BV5:CJ5) -> 0 | CL5: =T5+AK5+BB5+BT5+CK5 -> 25
A6: ='MASTER GURU HARIAN'!A8 -> 4 | B6: ='MASTER GURU HARIAN'!B8 -> UJANG SUHARA, S.Pd. | C6: ='MASTER GURU HARIAN'!C8 -> G4 | D6: ='MASTER GURU HARIAN'!D8 -> UJANG | F6: =COUNTIF(JADWAL!F$6:F$195,$D6) -> 0 | G6: =COUNTIF(JADWAL!G$6:G$195,$D6) -> 0 | H6: =COUNTIF(JADWAL!H$6:H$195,$D6) -> 1 | I6: =COUNTIF(JADWAL!I$6:I$195,$D6) -> 1 | J6: =COUNTIF(JADWAL!J$6:J$195,$D6) -> 0 | K6: =COUNTIF(JADWAL!K$6:K$195,$D6) -> 0 | L6: =COUNTIF(JADWAL!L$6:L$195,$D6) -> 0 | M6: =COUNTIF(JADWAL!M$6:M$195,$D6) -> 0 | ... S6: =COUNTIF(JADWAL!S$6:S$195,$D6) -> 0 | T6: =SUM(D6:S6) -> 4 | V6: =COUNTIF(JADWAL!V$6:V$195,$D6) -> 0 | W6: =COUNTIF(JADWAL!W$6:W$195,$D6) -> 0 | X6: =COUNTIF(JADWAL!X$6:X$195,$D6) -> 1 | Y6: =COUNTIF(JADWAL!Y$6:Y$195,$D6) -> 1 | Z6: =COUNTIF(JADWAL!Z$6:Z$195,$D6) -> 1 | AB6: =COUNTIF(JADWAL!AB$6:AB$195,$D6) -> 1 | AC6: =COUNTIF(JADWAL!AC$6:AC$195,$D6) -> 0 | AD6: =COUNTIF(JADWAL!AD$6:AD$195,$D6) -> 0 | AE6: =COUNTIF(JADWAL!AE$6:AE$195,$D6) -> 0 | AF6: =COUNTIF(JADWAL!AF$6:AF$195,$D6) -> 1 | AG6: =COUNTIF(JADWAL!AG$6:AG$195,$D6) -> 1 | AH6: =COUNTIF(JADWAL!AH$6:AH$195,$D6) -> 0 | AK6: =SUM(V6:AJ6) -> 6 | AM6: =COUNTIF(JADWAL!AM$6:AM$195,$D6) -> 0 | AN6: =COUNTIF(JADWAL!AN$6:AN$195,$D6) -> 0 | AO6: =COUNTIF(JADWAL!AO$6:AO$195,$D6) -> 0 | AP6: =COUNTIF(JADWAL!AP$6:AP$195,$D6) -> 0 | AQ6: =COUNTIF(JADWAL!AQ$6:AQ$195,$D6) -> 0 | AS6: =COUNTIF(JADWAL!AS$6:AS$195,$D6) -> 0 | AT6: =COUNTIF(JADWAL!AT$6:AT$195,$D6) -> 0 | AU6: =COUNTIF(JADWAL!AU$6:AU$195,$D6) -> 0 | AV6: =COUNTIF(JADWAL!AV$6:AV$195,$D6) -> 0 | AW6: =COUNTIF(JADWAL!AW$6:AW$195,$D6) -> 0 | AX6: =COUNTIF(JADWAL!AX$6:AX$195,$D6) -> 0 | AY6: =COUNTIF(JADWAL!AY$6:AY$195,$D6) -> 0 | AZ6: =COUNTIF(JADWAL!AZ$6:AZ$195,$D6) -> 0 | BA6: =COUNTIF(JADWAL!BA$6:BA$195,$D6) -> 0 | BB6: =SUM(AL6:BA6) -> 0 | BE6: =COUNTIF(JADWAL!BF$6:BF$195,$D6) -> 1 | BF6: =COUNTIF(JADWAL!BG$6:BG$195,$D6) -> 1 | BG6: =COUNTIF(JADWAL!BH$6:BH$195,$D6) -> 1 | BH6: =COUNTIF(JADWAL!BI$6:BI$195,$D6) -> 1 | BI6: =COUNTIF(JADWAL!BJ$6:BJ$195,$D6) -> 1 | BK6: =COUNTIF(JADWAL!BL$6:BL$195,$D6) -> 1 | BL6: =COUNTIF(JADWAL!BM$6:BM$195,$D6) -> 1 | BM6: =COUNTIF(JADWAL!BN$6:BN$195,$D6) -> 0 | BN6: =COUNTIF(JADWAL!BO$6:BO$195,$D6) -> 1 | BO6: =COUNTIF(JADWAL!BP$6:BP$195,$D6) -> 0 | BP6: =COUNTIF(JADWAL!BQ$6:BQ$195,$D6) -> 0 | BQ6: =COUNTIF(JADWAL!BR$6:BR$195,$D6) -> 0 | BS6: =COUNTIF(JADWAL!BT$6:BT$195,$D6) -> 0 | BT6: =SUM(BE6:BS6) -> 8 | BV6: =COUNTIF(JADWAL!BW$6:BW$195,$D6) -> 0 | BW6: =COUNTIF(JADWAL!BX$6:BX$195,$D6) -> 1 | BX6: =COUNTIF(JADWAL!BY$6:BY$195,$D6) -> 1 | BY6: =COUNTIF(JADWAL!BZ$6:BZ$195,$D6) -> 1 | BZ6: =COUNTIF(JADWAL!CA$6:CA$195,$D6) -> 1 | CA6: =COUNTIF(JADWAL!CB$6:CB$195,$D6) -> 0 | CB6: =COUNTIF(JADWAL!CC$6:CC$195,$D6) -> 0 | CD6: =COUNTIF(JADWAL!CE$6:CE$195,$D6) -> 0 | CE6: =COUNTIF(JADWAL!CF$6:CF$195,$D6) -> 0 | CF6: =COUNTIF(JADWAL!CG$6:CG$195,$D6) -> 1 | CG6: =COUNTIF(JADWAL!CH$6:CH$195,$D6) -> 1 | CH6: =COUNTIF(JADWAL!CI$6:CI$195,$D6) -> 0 | CI6: =COUNTIF(JADWAL!CJ$6:CJ$195,$D6) -> 0 | CK6: =SUM(BV6:CJ6) -> 6 | CL6: =T6+AK6+BB6+BT6+CK6 -> 24
A7: ='MASTER GURU HARIAN'!A9 -> 5 | B7: ='MASTER GURU HARIAN'!B9 -> Dra. MIMY ARDIANY, M.Pd | C7: ='MASTER GURU HARIAN'!C9 -> G5 | D7: ='MASTER GURU HARIAN'!D9 -> MIMY | F7: =COUNTIF(JADWAL!F$6:F$195,$D7) -> 1 | G7: =COUNTIF(JADWAL!G$6:G$195,$D7) -> 1 | H7: =COUNTIF(JADWAL!H$6:H$195,$D7) -> 1 | I7: =COUNTIF(JADWAL!I$6:I$195,$D7) -> 1 | J7: =COUNTIF(JADWAL!J$6:J$195,$D7) -> 0 | K7: =COUNTIF(JADWAL!K$6:K$195,$D7) -> 0 | L7: =COUNTIF(JADWAL!L$6:L$195,$D7) -> 0 | M7: =COUNTIF(JADWAL!M$6:M$195,$D7) -> 0 | ... S7: =COUNTIF(JADWAL!S$6:S$195,$D7) -> 0 | T7: =SUM(D7:S7) -> 4 | V7: =COUNTIF(JADWAL!V$6:V$195,$D7) -> 0 | W7: =COUNTIF(JADWAL!W$6:W$195,$D7) -> 1 | X7: =COUNTIF(JADWAL!X$6:X$195,$D7) -> 1 | Y7: =COUNTIF(JADWAL!Y$6:Y$195,$D7) -> 1 | Z7: =COUNTIF(JADWAL!Z$6:Z$195,$D7) -> 1 | AB7: =COUNTIF(JADWAL!AB$6:AB$195,$D7) -> 1 | AC7: =COUNTIF(JADWAL!AC$6:AC$195,$D7) -> 1 | AD7: =COUNTIF(JADWAL!AD$6:AD$195,$D7) -> 0 | AE7: =COUNTIF(JADWAL!AE$6:AE$195,$D7) -> 1 | AF7: =COUNTIF(JADWAL!AF$6:AF$195,$D7) -> 1 | AG7: =COUNTIF(JADWAL!AG$6:AG$195,$D7) -> 1 | AH7: =COUNTIF(JADWAL!AH$6:AH$195,$D7) -> 0 | AK7: =SUM(V7:AJ7) -> 9 | AM7: =COUNTIF(JADWAL!AM$6:AM$195,$D7) -> 0 | AN7: =COUNTIF(JADWAL!AN$6:AN$195,$D7) -> 1 | AO7: =COUNTIF(JADWAL!AO$6:AO$195,$D7) -> 1 | AP7: =COUNTIF(JADWAL!AP$6:AP$195,$D7) -> 0 | AQ7: =COUNTIF(JADWAL!AQ$6:AQ$195,$D7) -> 0 | AS7: =COUNTIF(JADWAL!AS$6:AS$195,$D7) -> 0 | AT7: =COUNTIF(JADWAL!AT$6:AT$195,$D7) -> 1 | AU7: =COUNTIF(JADWAL!AU$6:AU$195,$D7) -> 1 | AV7: =COUNTIF(JADWAL!AV$6:AV$195,$D7) -> 0 | AW7: =COUNTIF(JADWAL!AW$6:AW$195,$D7) -> 1 | AX7: =COUNTIF(JADWAL!AX$6:AX$195,$D7) -> 1 | AY7: =COUNTIF(JADWAL!AY$6:AY$195,$D7) -> 0 | AZ7: =COUNTIF(JADWAL!AZ$6:AZ$195,$D7) -> 0 | BA7: =COUNTIF(JADWAL!BA$6:BA$195,$D7) -> 0 | BB7: =SUM(AL7:BA7) -> 6 | BE7: =COUNTIF(JADWAL!BF$6:BF$195,$D7) -> 1 | BF7: =COUNTIF(JADWAL!BG$6:BG$195,$D7) -> 1 | BG7: =COUNTIF(JADWAL!BH$6:BH$195,$D7) -> 1 | BH7: =COUNTIF(JADWAL!BI$6:BI$195,$D7) -> 1 | BI7: =COUNTIF(JADWAL!BJ$6:BJ$195,$D7) -> 0 | BK7: =COUNTIF(JADWAL!BL$6:BL$195,$D7) -> 0 | BL7: =COUNTIF(JADWAL!BM$6:BM$195,$D7) -> 1 | BM7: =COUNTIF(JADWAL!BN$6:BN$195,$D7) -> 1 | BN7: =COUNTIF(JADWAL!BO$6:BO$195,$D7) -> 0 | BO7: =COUNTIF(JADWAL!BP$6:BP$195,$D7) -> 0 | BP7: =COUNTIF(JADWAL!BQ$6:BQ$195,$D7) -> 0 | BQ7: =COUNTIF(JADWAL!BR$6:BR$195,$D7) -> 0 | BS7: =COUNTIF(JADWAL!BT$6:BT$195,$D7) -> 0 | BT7: =SUM(BE7:BS7) -> 6 | BV7: =COUNTIF(JADWAL!BW$6:BW$195,$D7) -> 0 | BW7: =COUNTIF(JADWAL!BX$6:BX$195,$D7) -> 0 | BX7: =COUNTIF(JADWAL!BY$6:BY$195,$D7) -> 0 | BY7: =COUNTIF(JADWAL!BZ$6:BZ$195,$D7) -> 0 | BZ7: =COUNTIF(JADWAL!CA$6:CA$195,$D7) -> 0 | CA7: =COUNTIF(JADWAL!CB$6:CB$195,$D7) -> 0 | CB7: =COUNTIF(JADWAL!CC$6:CC$195,$D7) -> 0 | CD7: =COUNTIF(JADWAL!CE$6:CE$195,$D7) -> 0 | CE7: =COUNTIF(JADWAL!CF$6:CF$195,$D7) -> 0 | CF7: =COUNTIF(JADWAL!CG$6:CG$195,$D7) -> 0 | CG7: =COUNTIF(JADWAL!CH$6:CH$195,$D7) -> 0 | CH7: =COUNTIF(JADWAL!CI$6:CI$195,$D7) -> 0 | CI7: =COUNTIF(JADWAL!CJ$6:CJ$195,$D7) -> 0 | CK7: =SUM(BV7:CJ7) -> 0 | CL7: =T7+AK7+BB7+BT7+CK7 -> 25
A8: ='MASTER GURU HARIAN'!A10 -> 6 | B8: ='MASTER GURU HARIAN'!B10 -> SARINAH Br GINTING, M.Pd. | C8: ='MASTER GURU HARIAN'!C10 -> G6 | D8: ='MASTER GURU HARIAN'!D10 -> SARI | F8: =COUNTIF(JADWAL!F$6:F$195,$D8) -> 0 | G8: =COUNTIF(JADWAL!G$6:G$195,$D8) -> 0 | H8: =COUNTIF(JADWAL!H$6:H$195,$D8) -> 0 | I8: =COUNTIF(JADWAL!I$6:I$195,$D8) -> 0 | J8: =COUNTIF(JADWAL!J$6:J$195,$D8) -> 0 | K8: =COUNTIF(JADWAL!K$6:K$195,$D8) -> 0 | L8: =COUNTIF(JADWAL!L$6:L$195,$D8) -> 0 | M8: =COUNTIF(JADWAL!M$6:M$195,$D8) -> 0 | ... S8: =COUNTIF(JADWAL!S$6:S$195,$D8) -> 0 | T8: =SUM(D8:S8) -> 3 | V8: =COUNTIF(JADWAL!V$6:V$195,$D8) -> 0 | W8: =COUNTIF(JADWAL!W$6:W$195,$D8) -> 0 | X8: =COUNTIF(JADWAL!X$6:X$195,$D8) -> 0 | Y8: =COUNTIF(JADWAL!Y$6:Y$195,$D8) -> 1 | Z8: =COUNTIF(JADWAL!Z$6:Z$195,$D8) -> 1 | AB8: =COUNTIF(JADWAL!AB$6:AB$195,$D8) -> 1 | AC8: =COUNTIF(JADWAL!AC$6:AC$195,$D8) -> 0 | AD8: =COUNTIF(JADWAL!AD$6:AD$195,$D8) -> 0 | AE8: =COUNTIF(JADWAL!AE$6:AE$195,$D8) -> 1 | AF8: =COUNTIF(JADWAL!AF$6:AF$195,$D8) -> 1 | AG8: =COUNTIF(JADWAL!AG$6:AG$195,$D8) -> 1 | AH8: =COUNTIF(JADWAL!AH$6:AH$195,$D8) -> 0 | AK8: =SUM(V8:AJ8) -> 6 | AM8: =COUNTIF(JADWAL!AM$6:AM$195,$D8) -> 0 | AN8: =COUNTIF(JADWAL!AN$6:AN$195,$D8) -> 0 | AO8: =COUNTIF(JADWAL!AO$6:AO$195,$D8) -> 0 | AP8: =COUNTIF(JADWAL!AP$6:AP$195,$D8) -> 0 | AQ8: =COUNTIF(JADWAL!AQ$6:AQ$195,$D8) -> 0 | AS8: =COUNTIF(JADWAL!AS$6:AS$195,$D8) -> 0 | AT8: =COUNTIF(JADWAL!AT$6:AT$195,$D8) -> 0 | AU8: =COUNTIF(JADWAL!AU$6:AU$195,$D8) -> 0 | AV8: =COUNTIF(JADWAL!AV$6:AV$195,$D8) -> 0 | AW8: =COUNTIF(JADWAL!AW$6:AW$195,$D8) -> 0 | AX8: =COUNTIF(JADWAL!AX$6:AX$195,$D8) -> 0 | AY8: =COUNTIF(JADWAL!AY$6:AY$195,$D8) -> 0 | AZ8: =COUNTIF(JADWAL!AZ$6:AZ$195,$D8) -> 0 | BA8: =COUNTIF(JADWAL!BA$6:BA$195,$D8) -> 0 | BB8: =SUM(AL8:BA8) -> 0 | BE8: =COUNTIF(JADWAL!BF$6:BF$195,$D8) -> 1 | BF8: =COUNTIF(JADWAL!BG$6:BG$195,$D8) -> 1 | BG8: =COUNTIF(JADWAL!BH$6:BH$195,$D8) -> 1 | BH8: =COUNTIF(JADWAL!BI$6:BI$195,$D8) -> 0 | BI8: =COUNTIF(JADWAL!BJ$6:BJ$195,$D8) -> 0 | BK8: =COUNTIF(JADWAL!BL$6:BL$195,$D8) -> 0 | BL8: =COUNTIF(JADWAL!BM$6:BM$195,$D8) -> 1 | BM8: =COUNTIF(JADWAL!BN$6:BN$195,$D8) -> 0 | BN8: =COUNTIF(JADWAL!BO$6:BO$195,$D8) -> 1 | BO8: =COUNTIF(JADWAL!BP$6:BP$195,$D8) -> 1 | BP8: =COUNTIF(JADWAL!BQ$6:BQ$195,$D8) -> 0 | BQ8: =COUNTIF(JADWAL!BR$6:BR$195,$D8) -> 0 | BS8: =COUNTIF(JADWAL!BT$6:BT$195,$D8) -> 0 | BT8: =SUM(BE8:BS8) -> 6 | BV8: =COUNTIF(JADWAL!BW$6:BW$195,$D8) -> 0 | BW8: =COUNTIF(JADWAL!BX$6:BX$195,$D8) -> 1 | BX8: =COUNTIF(JADWAL!BY$6:BY$195,$D8) -> 1 | BY8: =COUNTIF(JADWAL!BZ$6:BZ$195,$D8) -> 1 | BZ8: =COUNTIF(JADWAL!CA$6:CA$195,$D8) -> 1 | CA8: =COUNTIF(JADWAL!CB$6:CB$195,$D8) -> 1 | CB8: =COUNTIF(JADWAL!CC$6:CC$195,$D8) -> 1 | CD8: =COUNTIF(JADWAL!CE$6:CE$195,$D8) -> 1 | CE8: =COUNTIF(JADWAL!CF$6:CF$195,$D8) -> 1 | CF8: =COUNTIF(JADWAL!CG$6:CG$195,$D8) -> 1 | CG8: =COUNTIF(JADWAL!CH$6:CH$195,$D8) -> 0 | CH8: =COUNTIF(JADWAL!CI$6:CI$195,$D8) -> 0 | CI8: =COUNTIF(JADWAL!CJ$6:CJ$195,$D8) -> 0 | CK8: =SUM(BV8:CJ8) -> 9 | CL8: =T8+AK8+BB8+BT8+CK8 -> 24
A9: ='MASTER GURU HARIAN'!A11 -> 7 | B9: ='MASTER GURU HARIAN'!B11 -> TAUFIK HIDAYAT,M.M.Pd | C9: ='MASTER GURU HARIAN'!C11 -> G7 | D9: ='MASTER GURU HARIAN'!D11 -> TAUFIK | F9: =COUNTIF(JADWAL!F$6:F$195,$D9) -> 1 | G9: =COUNTIF(JADWAL!G$6:G$195,$D9) -> 1 | H9: =COUNTIF(JADWAL!H$6:H$195,$D9) -> 1 | I9: =COUNTIF(JADWAL!I$6:I$195,$D9) -> 1 | J9: =COUNTIF(JADWAL!J$6:J$195,$D9) -> 0 | K9: =COUNTIF(JADWAL!K$6:K$195,$D9) -> 0 | L9: =COUNTIF(JADWAL!L$6:L$195,$D9) -> 0 | M9: =COUNTIF(JADWAL!M$6:M$195,$D9) -> 0 | ... S9: =COUNTIF(JADWAL!S$6:S$195,$D9) -> 0 | T9: =SUM(D9:S9) -> 8 | V9: =COUNTIF(JADWAL!V$6:V$195,$D9) -> 1 | W9: =COUNTIF(JADWAL!W$6:W$195,$D9) -> 1 | X9: =COUNTIF(JADWAL!X$6:X$195,$D9) -> 1 | Y9: =COUNTIF(JADWAL!Y$6:Y$195,$D9) -> 1 | Z9: =COUNTIF(JADWAL!Z$6:Z$195,$D9) -> 0 | AB9: =COUNTIF(JADWAL!AB$6:AB$195,$D9) -> 0 | AC9: =COUNTIF(JADWAL!AC$6:AC$195,$D9) -> 0 | AD9: =COUNTIF(JADWAL!AD$6:AD$195,$D9) -> 0 | AE9: =COUNTIF(JADWAL!AE$6:AE$195,$D9) -> 0 | AF9: =COUNTIF(JADWAL!AF$6:AF$195,$D9) -> 1 | AG9: =COUNTIF(JADWAL!AG$6:AG$195,$D9) -> 1 | AH9: =COUNTIF(JADWAL!AH$6:AH$195,$D9) -> 0 | AK9: =SUM(V9:AJ9) -> 6 | AM9: =COUNTIF(JADWAL!AM$6:AM$195,$D9) -> 0 | AN9: =COUNTIF(JADWAL!AN$6:AN$195,$D9) -> 1 | AO9: =COUNTIF(JADWAL!AO$6:AO$195,$D9) -> 1 | AP9: =COUNTIF(JADWAL!AP$6:AP$195,$D9) -> 1 | AQ9: =COUNTIF(JADWAL!AQ$6:AQ$195,$D9) -> 1 | AS9: =COUNTIF(JADWAL!AS$6:AS$195,$D9) -> 0 | AT9: =COUNTIF(JADWAL!AT$6:AT$195,$D9) -> 0 | AU9: =COUNTIF(JADWAL!AU$6:AU$195,$D9) -> 0 | AV9: =COUNTIF(JADWAL!AV$6:AV$195,$D9) -> 1 | AW9: =COUNTIF(JADWAL!AW$6:AW$195,$D9) -> 1 | AX9: =COUNTIF(JADWAL!AX$6:AX$195,$D9) -> 1 | AY9: =COUNTIF(JADWAL!AY$6:AY$195,$D9) -> 1 | AZ9: =COUNTIF(JADWAL!AZ$6:AZ$195,$D9) -> 0 | BA9: =COUNTIF(JADWAL!BA$6:BA$195,$D9) -> 0 | BB9: =SUM(AL9:BA9) -> 8 | BE9: =COUNTIF(JADWAL!BF$6:BF$195,$D9) -> 0 | BF9: =COUNTIF(JADWAL!BG$6:BG$195,$D9) -> 0 | BG9: =COUNTIF(JADWAL!BH$6:BH$195,$D9) -> 1 | BH9: =COUNTIF(JADWAL!BI$6:BI$195,$D9) -> 2 | BI9: =COUNTIF(JADWAL!BJ$6:BJ$195,$D9) -> 1 | BK9: =COUNTIF(JADWAL!BL$6:BL$195,$D9) -> 0 | BL9: =COUNTIF(JADWAL!BM$6:BM$195,$D9) -> 0 | BM9: =COUNTIF(JADWAL!BN$6:BN$195,$D9) -> 0 | BN9: =COUNTIF(JADWAL!BO$6:BO$195,$D9) -> 1 | BO9: =COUNTIF(JADWAL!BP$6:BP$195,$D9) -> 1 | BP9: =COUNTIF(JADWAL!BQ$6:BQ$195,$D9) -> 0 | BQ9: =COUNTIF(JADWAL!BR$6:BR$195,$D9) -> 0 | BS9: =COUNTIF(JADWAL!BT$6:BT$195,$D9) -> 0 | BT9: =SUM(BE9:BS9) -> 6 | BV9: =COUNTIF(JADWAL!BW$6:BW$195,$D9) -> 0 | BW9: =COUNTIF(JADWAL!BX$6:BX$195,$D9) -> 0 | BX9: =COUNTIF(JADWAL!BY$6:BY$195,$D9) -> 0 | BY9: =COUNTIF(JADWAL!BZ$6:BZ$195,$D9) -> 0 | BZ9: =COUNTIF(JADWAL!CA$6:CA$195,$D9) -> 0 | CA9: =COUNTIF(JADWAL!CB$6:CB$195,$D9) -> 0 | CB9: =COUNTIF(JADWAL!CC$6:CC$195,$D9) -> 0 | CD9: =COUNTIF(JADWAL!CE$6:CE$195,$D9) -> 0 | CE9: =COUNTIF(JADWAL!CF$6:CF$195,$D9) -> 0 | CF9: =COUNTIF(JADWAL!CG$6:CG$195,$D9) -> 0 | CG9: =COUNTIF(JADWAL!CH$6:CH$195,$D9) -> 0 | CH9: =COUNTIF(JADWAL!CI$6:CI$195,$D9) -> 0 | CI9: =COUNTIF(JADWAL!CJ$6:CJ$195,$D9) -> 0 | CK9: =SUM(BV9:CJ9) -> 0 | CL9: =T9+AK9+BB9+BT9+CK9 -> 28
A10: ='MASTER GURU HARIAN'!A12 -> 8 | B10: ='MASTER GURU HARIAN'!B12 -> RITA HARTATI, S.Pd, M.T. | C10: ='MASTER GURU HARIAN'!C12 -> G8 | D10: ='MASTER GURU HARIAN'!D12 -> RITA | F10: =COUNTIF(JADWAL!F$6:F$195,$D10) -> 1 | G10: =COUNTIF(JADWAL!G$6:G$195,$D10) -> 1 | H10: =COUNTIF(JADWAL!H$6:H$195,$D10) -> 1 | I10: =COUNTIF(JADWAL!I$6:I$195,$D10) -> 1 | J10: =COUNTIF(JADWAL!J$6:J$195,$D10) -> 0 | K10: =COUNTIF(JADWAL!K$6:K$195,$D10) -> 1 | L10: =COUNTIF(JADWAL!L$6:L$195,$D10) -> 1 | M10: =COUNTIF(JADWAL!M$6:M$195,$D10) -> 0 | ... S10: =COUNTIF(JADWAL!S$6:S$195,$D10) -> 0 | T10: =SUM(D10:S10) -> 6 | V10: =COUNTIF(JADWAL!V$6:V$195,$D10) -> 1 | W10: =COUNTIF(JADWAL!W$6:W$195,$D10) -> 1 | X10: =COUNTIF(JADWAL!X$6:X$195,$D10) -> 1 | Y10: =COUNTIF(JADWAL!Y$6:Y$195,$D10) -> 1 | Z10: =COUNTIF(JADWAL!Z$6:Z$195,$D10) -> 0 | AB10: =COUNTIF(JADWAL!AB$6:AB$195,$D10) -> 1 | AC10: =COUNTIF(JADWAL!AC$6:AC$195,$D10) -> 1 | AD10: =COUNTIF(JADWAL!AD$6:AD$195,$D10) -> 0 | AE10: =COUNTIF(JADWAL!AE$6:AE$195,$D10) -> 1 | AF10: =COUNTIF(JADWAL!AF$6:AF$195,$D10) -> 0 | AG10: =COUNTIF(JADWAL!AG$6:AG$195,$D10) -> 0 | AH10: =COUNTIF(JADWAL!AH$6:AH$195,$D10) -> 0 | AK10: =SUM(V10:AJ10) -> 7 | AM10: =COUNTIF(JADWAL!AM$6:AM$195,$D10) -> 0 | AN10: =COUNTIF(JADWAL!AN$6:AN$195,$D10) -> 1 | AO10: =COUNTIF(JADWAL!AO$6:AO$195,$D10) -> 1 | AP10: =COUNTIF(JADWAL!AP$6:AP$195,$D10) -> 1 | AQ10: =COUNTIF(JADWAL!AQ$6:AQ$195,$D10) -> 0 | AS10: =COUNTIF(JADWAL!AS$6:AS$195,$D10) -> 0 | AT10: =COUNTIF(JADWAL!AT$6:AT$195,$D10) -> 0 | AU10: =COUNTIF(JADWAL!AU$6:AU$195,$D10) -> 0 | AV10: =COUNTIF(JADWAL!AV$6:AV$195,$D10) -> 1 | AW10: =COUNTIF(JADWAL!AW$6:AW$195,$D10) -> 1 | AX10: =COUNTIF(JADWAL!AX$6:AX$195,$D10) -> 1 | AY10: =COUNTIF(JADWAL!AY$6:AY$195,$D10) -> 0 | AZ10: =COUNTIF(JADWAL!AZ$6:AZ$195,$D10) -> 0 | BA10: =COUNTIF(JADWAL!BA$6:BA$195,$D10) -> 0 | BB10: =SUM(AL10:BA10) -> 6 | BE10: =COUNTIF(JADWAL!BF$6:BF$195,$D10) -> 1 | BF10: =COUNTIF(JADWAL!BG$6:BG$195,$D10) -> 1 | BG10: =COUNTIF(JADWAL!BH$6:BH$195,$D10) -> 1 | BH10: =COUNTIF(JADWAL!BI$6:BI$195,$D10) -> 1 | BI10: =COUNTIF(JADWAL!BJ$6:BJ$195,$D10) -> 0 | BK10: =COUNTIF(JADWAL!BL$6:BL$195,$D10) -> 1 | BL10: =COUNTIF(JADWAL!BM$6:BM$195,$D10) -> 1 | BM10: =COUNTIF(JADWAL!BN$6:BN$195,$D10) -> 0 | BN10: =COUNTIF(JADWAL!BO$6:BO$195,$D10) -> 1 | BO10: =COUNTIF(JADWAL!BP$6:BP$195,$D10) -> 1 | BP10: =COUNTIF(JADWAL!BQ$6:BQ$195,$D10) -> 0 | BQ10: =COUNTIF(JADWAL!BR$6:BR$195,$D10) -> 0 | BS10: =COUNTIF(JADWAL!BT$6:BT$195,$D10) -> 0 | BT10: =SUM(BE10:BS10) -> 8 | BV10: =COUNTIF(JADWAL!BW$6:BW$195,$D10) -> 0 | BW10: =COUNTIF(JADWAL!BX$6:BX$195,$D10) -> 0 | BX10: =COUNTIF(JADWAL!BY$6:BY$195,$D10) -> 0 | BY10: =COUNTIF(JADWAL!BZ$6:BZ$195,$D10) -> 0 | BZ10: =COUNTIF(JADWAL!CA$6:CA$195,$D10) -> 0 | CA10: =COUNTIF(JADWAL!CB$6:CB$195,$D10) -> 0 | CB10: =COUNTIF(JADWAL!CC$6:CC$195,$D10) -> 0 | CD10: =COUNTIF(JADWAL!CE$6:CE$195,$D10) -> 0 | CE10: =COUNTIF(JADWAL!CF$6:CF$195,$D10) -> 0 | CF10: =COUNTIF(JADWAL!CG$6:CG$195,$D10) -> 0 | CG10: =COUNTIF(JADWAL!CH$6:CH$195,$D10) -> 0 | CH10: =COUNTIF(JADWAL!CI$6:CI$195,$D10) -> 0 | CI10: =COUNTIF(JADWAL!CJ$6:CJ$195,$D10) -> 0 | CK10: =SUM(BV10:CJ10) -> 0 | CL10: =T10+AK10+BB10+BT10+CK10 -> 27
A11: ='MASTER GURU HARIAN'!A13 -> 9 | B11: ='MASTER GURU HARIAN'!B13 -> ADE HARTONO, S.Pd. | C11: ='MASTER GURU HARIAN'!C13 -> G9 | D11: ='MASTER GURU HARIAN'!D13 -> ADE | F11: =COUNTIF(JADWAL!F$6:F$195,$D11) -> 0 | G11: =COUNTIF(JADWAL!G$6:G$195,$D11) -> 1 | H11: =COUNTIF(JADWAL!H$6:H$195,$D11) -> 1 | I11: =COUNTIF(JADWAL!I$6:I$195,$D11) -> 1 | J11: =COUNTIF(JADWAL!J$6:J$195,$D11) -> 0 | K11: =COUNTIF(JADWAL!K$6:K$195,$D11) -> 1 | L11: =COUNTIF(JADWAL!L$6:L$195,$D11) -> 1 | M11: =COUNTIF(JADWAL!M$6:M$195,$D11) -> 0 | ... S11: =COUNTIF(JADWAL!S$6:S$195,$D11) -> 0 | T11: =SUM(D11:S11) -> 9 | V11: =COUNTIF(JADWAL!V$6:V$195,$D11) -> 0 | W11: =COUNTIF(JADWAL!W$6:W$195,$D11) -> 0 | X11: =COUNTIF(JADWAL!X$6:X$195,$D11) -> 0 | Y11: =COUNTIF(JADWAL!Y$6:Y$195,$D11) -> 0 | Z11: =COUNTIF(JADWAL!Z$6:Z$195,$D11) -> 0 | AB11: =COUNTIF(JADWAL!AB$6:AB$195,$D11) -> 0 | AC11: =COUNTIF(JADWAL!AC$6:AC$195,$D11) -> 0 | AD11: =COUNTIF(JADWAL!AD$6:AD$195,$D11) -> 0 | AE11: =COUNTIF(JADWAL!AE$6:AE$195,$D11) -> 0 | AF11: =COUNTIF(JADWAL!AF$6:AF$195,$D11) -> 0 | AG11: =COUNTIF(JADWAL!AG$6:AG$195,$D11) -> 0 | AH11: =COUNTIF(JADWAL!AH$6:AH$195,$D11) -> 0 | AK11: =SUM(V11:AJ11) -> 0 | AM11: =COUNTIF(JADWAL!AM$6:AM$195,$D11) -> 0 | AN11: =COUNTIF(JADWAL!AN$6:AN$195,$D11) -> 0 | AO11: =COUNTIF(JADWAL!AO$6:AO$195,$D11) -> 0 | AP11: =COUNTIF(JADWAL!AP$6:AP$195,$D11) -> 0 | AQ11: =COUNTIF(JADWAL!AQ$6:AQ$195,$D11) -> 0 | AS11: =COUNTIF(JADWAL!AS$6:AS$195,$D11) -> 0 | AT11: =COUNTIF(JADWAL!AT$6:AT$195,$D11) -> 0 | AU11: =COUNTIF(JADWAL!AU$6:AU$195,$D11) -> 0 | AV11: =COUNTIF(JADWAL!AV$6:AV$195,$D11) -> 0 | AW11: =COUNTIF(JADWAL!AW$6:AW$195,$D11) -> 0 | AX11: =COUNTIF(JADWAL!AX$6:AX$195,$D11) -> 0 | AY11: =COUNTIF(JADWAL!AY$6:AY$195,$D11) -> 0 | AZ11: =COUNTIF(JADWAL!AZ$6:AZ$195,$D11) -> 0 | BA11: =COUNTIF(JADWAL!BA$6:BA$195,$D11) -> 0 | BB11: =SUM(AL11:BA11) -> 0 | BE11: =COUNTIF(JADWAL!BF$6:BF$195,$D11) -> 1 | BF11: =COUNTIF(JADWAL!BG$6:BG$195,$D11) -> 1 | BG11: =COUNTIF(JADWAL!BH$6:BH$195,$D11) -> 1 | BH11: =COUNTIF(JADWAL!BI$6:BI$195,$D11) -> 1 | BI11: =COUNTIF(JADWAL!BJ$6:BJ$195,$D11) -> 1 | BK11: =COUNTIF(JADWAL!BL$6:BL$195,$D11) -> 1 | BL11: =COUNTIF(JADWAL!BM$6:BM$195,$D11) -> 1 | BM11: =COUNTIF(JADWAL!BN$6:BN$195,$D11) -> 0 | BN11: =COUNTIF(JADWAL!BO$6:BO$195,$D11) -> 1 | BO11: =COUNTIF(JADWAL!BP$6:BP$195,$D11) -> 1 | BP11: =COUNTIF(JADWAL!BQ$6:BQ$195,$D11) -> 0 | BQ11: =COUNTIF(JADWAL!BR$6:BR$195,$D11) -> 0 | BS11: =COUNTIF(JADWAL!BT$6:BT$195,$D11) -> 0 | BT11: =SUM(BE11:BS11) -> 9 | BV11: =COUNTIF(JADWAL!BW$6:BW$195,$D11) -> 0 | BW11: =COUNTIF(JADWAL!BX$6:BX$195,$D11) -> 1 | BX11: =COUNTIF(JADWAL!BY$6:BY$195,$D11) -> 1 | BY11: =COUNTIF(JADWAL!BZ$6:BZ$195,$D11) -> 1 | BZ11: =COUNTIF(JADWAL!CA$6:CA$195,$D11) -> 1 | CA11: =COUNTIF(JADWAL!CB$6:CB$195,$D11) -> 1 | CB11: =COUNTIF(JADWAL!CC$6:CC$195,$D11) -> 1 | CD11: =COUNTIF(JADWAL!CE$6:CE$195,$D11) -> 1 | CE11: =COUNTIF(JADWAL!CF$6:CF$195,$D11) -> 1 | CF11: =COUNTIF(JADWAL!CG$6:CG$195,$D11) -> 1 | CG11: =COUNTIF(JADWAL!CH$6:CH$195,$D11) -> 0 | CH11: =COUNTIF(JADWAL!CI$6:CI$195,$D11) -> 0 | CI11: =COUNTIF(JADWAL!CJ$6:CJ$195,$D11) -> 0 | CK11: =SUM(BV11:CJ11) -> 9 | CL11: =T11+AK11+BB11+BT11+CK11 -> 27
A12: ='MASTER GURU HARIAN'!A14 -> 10 | B12: ='MASTER GURU HARIAN'!B14 -> TITA HERIYANTI, S.Pd. | C12: ='MASTER GURU HARIAN'!C14 -> G10 | D12: ='MASTER GURU HARIAN'!D14 -> TITA | F12: =COUNTIF(JADWAL!F$6:F$195,$D12) -> 0 | G12: =COUNTIF(JADWAL!G$6:G$195,$D12) -> 0 | H12: =COUNTIF(JADWAL!H$6:H$195,$D12) -> 0 | I12: =COUNTIF(JADWAL!I$6:I$195,$D12) -> 1 | J12: =COUNTIF(JADWAL!J$6:J$195,$D12) -> 0 | K12: =COUNTIF(JADWAL!K$6:K$195,$D12) -> 1 | L12: =COUNTIF(JADWAL!L$6:L$195,$D12) -> 1 | M12: =COUNTIF(JADWAL!M$6:M$195,$D12) -> 0 | ... S12: =COUNTIF(JADWAL!S$6:S$195,$D12) -> 0 | T12: =SUM(D12:S12) -> 7 | V12: =COUNTIF(JADWAL!V$6:V$195,$D12) -> 1 | W12: =COUNTIF(JADWAL!W$6:W$195,$D12) -> 1 | X12: =COUNTIF(JADWAL!X$6:X$195,$D12) -> 0 | Y12: =COUNTIF(JADWAL!Y$6:Y$195,$D12) -> 0 | Z12: =COUNTIF(JADWAL!Z$6:Z$195,$D12) -> 0 | AB12: =COUNTIF(JADWAL!AB$6:AB$195,$D12) -> 0 | AC12: =COUNTIF(JADWAL!AC$6:AC$195,$D12) -> 0 | AD12: =COUNTIF(JADWAL!AD$6:AD$195,$D12) -> 0 | AE12: =COUNTIF(JADWAL!AE$6:AE$195,$D12) -> 0 | AF12: =COUNTIF(JADWAL!AF$6:AF$195,$D12) -> 0 | AG12: =COUNTIF(JADWAL!AG$6:AG$195,$D12) -> 0 | AH12: =COUNTIF(JADWAL!AH$6:AH$195,$D12) -> 0 | AK12: =SUM(V12:AJ12) -> 2 | AM12: =COUNTIF(JADWAL!AM$6:AM$195,$D12) -> 0 | AN12: =COUNTIF(JADWAL!AN$6:AN$195,$D12) -> 0 | AO12: =COUNTIF(JADWAL!AO$6:AO$195,$D12) -> 0 | AP12: =COUNTIF(JADWAL!AP$6:AP$195,$D12) -> 1 | AQ12: =COUNTIF(JADWAL!AQ$6:AQ$195,$D12) -> 1 | AS12: =COUNTIF(JADWAL!AS$6:AS$195,$D12) -> 1 | AT12: =COUNTIF(JADWAL!AT$6:AT$195,$D12) -> 1 | AU12: =COUNTIF(JADWAL!AU$6:AU$195,$D12) -> 0 | AV12: =COUNTIF(JADWAL!AV$6:AV$195,$D12) -> 1 | AW12: =COUNTIF(JADWAL!AW$6:AW$195,$D12) -> 1 | AX12: =COUNTIF(JADWAL!AX$6:AX$195,$D12) -> 1 | AY12: =COUNTIF(JADWAL!AY$6:AY$195,$D12) -> 1 | AZ12: =COUNTIF(JADWAL!AZ$6:AZ$195,$D12) -> 0 | BA12: =COUNTIF(JADWAL!BA$6:BA$195,$D12) -> 0 | BB12: =SUM(AL12:BA12) -> 8 | BE12: =COUNTIF(JADWAL!BF$6:BF$195,$D12) -> 1 | BF12: =COUNTIF(JADWAL!BG$6:BG$195,$D12) -> 1 | BG12: =COUNTIF(JADWAL!BH$6:BH$195,$D12) -> 1 | BH12: =COUNTIF(JADWAL!BI$6:BI$195,$D12) -> 1 | BI12: =COUNTIF(JADWAL!BJ$6:BJ$195,$D12) -> 1 | BK12: =COUNTIF(JADWAL!BL$6:BL$195,$D12) -> 1 | BL12: =COUNTIF(JADWAL!BM$6:BM$195,$D12) -> 1 | BM12: =COUNTIF(JADWAL!BN$6:BN$195,$D12) -> 0 | BN12: =COUNTIF(JADWAL!BO$6:BO$195,$D12) -> 1 | BO12: =COUNTIF(JADWAL!BP$6:BP$195,$D12) -> 1 | BP12: =COUNTIF(JADWAL!BQ$6:BQ$195,$D12) -> 1 | BQ12: =COUNTIF(JADWAL!BR$6:BR$195,$D12) -> 0 | BS12: =COUNTIF(JADWAL!BT$6:BT$195,$D12) -> 0 | BT12: =SUM(BE12:BS12) -> 10 | BV12: =COUNTIF(JADWAL!BW$6:BW$195,$D12) -> 0 | BW12: =COUNTIF(JADWAL!BX$6:BX$195,$D12) -> 0 | BX12: =COUNTIF(JADWAL!BY$6:BY$195,$D12) -> 0 | BY12: =COUNTIF(JADWAL!BZ$6:BZ$195,$D12) -> 0 | BZ12: =COUNTIF(JADWAL!CA$6:CA$195,$D12) -> 0 | CA12: =COUNTIF(JADWAL!CB$6:CB$195,$D12) -> 0 | CB12: =COUNTIF(JADWAL!CC$6:CC$195,$D12) -> 0 | CD12: =COUNTIF(JADWAL!CE$6:CE$195,$D12) -> 0 | CE12: =COUNTIF(JADWAL!CF$6:CF$195,$D12) -> 0 | CF12: =COUNTIF(JADWAL!CG$6:CG$195,$D12) -> 0 | CG12: =COUNTIF(JADWAL!CH$6:CH$195,$D12) -> 0 | CH12: =COUNTIF(JADWAL!CI$6:CI$195,$D12) -> 0 | CI12: =COUNTIF(JADWAL!CJ$6:CJ$195,$D12) -> 0 | CK12: =SUM(BV12:CJ12) -> 0 | CL12: =T12+AK12+BB12+BT12+CK12 -> 27
