Workbook

Sheet Short NIS
A1: NIS | B1: NISN | C1: Nama | D1: LP | E1: KLS
A2: 102519525 | B2: 3106989660 | C2: ABGARI RADITYA AHMAD | D2: L | E2: X KA 1 | K2: 101616368
A3: 102519526 | B3: 0094413313 | C3: ADINDA PUTRI | D3: P | E3: X KA 1 | K3: 101716761 | L3: akhir 2017
A4: 102519527 | B4: 0101004818 | C4: ALIFA JIHAN IFTINAH | D4: P | E4: X KA 1 | K4: 101816762
A5: 102519528 | B5: 0099555110 | C5: ALMIRA ATHYYA HUSNIAH | D5: P | E5: X KA 1
A6: 102519529 | B6: 0099117757 | C6: ALYYA RAHMAWATI | D6: P | E6: X KA 1
A7: 102519530 | B7: 0106834163 | C7: AMEERA PUTRI AL ZAHRA | D7: P | E7: X KA 1 | K7: 101817155 | L7: AHKIR 2018
A8: 102519531 | B8: 0099850277 | C8: ARVINO YUMA PRATAMA | D8: L | E8: X KA 1 | K8: 101917156
A9: 102519532 | B9: 0104157931 | C9: AYESHA ZEPHANIA | D9: P | E9: X KA 1
A10: 102519533 | B10: 0095348926 | C10: CIKAL ABDUL MUIZ MUTSAQIF | D10: L | E10: X KA 1
A11: 102519534 | B11: 0105056370 | C11: DANAR PRAWIRA | D11: L | E11: X KA 1 | K11: 101917549 | L11: AHKIR 2019
A12: 102519535 | B12: 0098323888 | C12: DEVINA YULIA | D12: P | E12: X KA 1 | K12: 102017550
A13: 102519536 | B13: 0101455732 | C13: ERLANGGA AL FIKRI | D13: L | E13: X KA 1
A14: 102519537 | B14: 0107283385 | C14: FARID KHAIRUL AZMI | D14: L | E14: X KA 1
A15: 102519538 | B15: 0091534514 | C15: FUAN NOER ASSYFA GINTING | D15: P | E15: X KA 1
A16: 102519539 | B16: 0093275414 | C16: GHAITSA ZAHIRA SHOFA | D16: P | E16: X KA 1 | K16: 102017945 | L16: AKHIR 2020
A17: 102519540 | B17: 0102080145 | C17: HILMAN SAPUTRA | D17: L | E17: X KA 1 | K17: 102017947 | L17: AKHIR 2020
A18: 102519541 | B18: 0092436932 | C18: ISMI ANANDA PUTRI | D18: P | E18: X KA 1 | K18: 102017948 | L18: AKHIR 2020 | M18: JEC
A19: 102519542 | C19: JASMINE ANGELIE MAURINA | D19: P | E19: X KA 1
A20: 102519543 | B20: 0099699911 | C20: KHAERILDA AYESHA REZKI | D20: P | E20: X KA 1 | K20: 102117949 | L20: awal 2021
A21: 102519544 | B21: 0095196716 | C21: LUTHFIYAH HAZANAH AL-KHOFIDH | D21: P | E21: X KA 1 | K21: 102118340 | L21: akhir 2021
A22: 102519545 | B22: 0095491585 | C22: MOCHAMMAD FARIZ ADITYA | D22: L | E22: X KA 1 | J22: siswa masuk 2org | K22: 102118342 | L22: akhir 2021
A23: 102519546 | B23: 0096471531 | C23: MUHAMMAD ARVAN ZHARIV | D23: L | E23: X KA 1
A24: 102519547 | B24: 0096690592 | C24: MUHAMMAD FAHMI NUR IHSAN | D24: L | E24: X KA 1 | K24: 102218343 | L24: awal 2022
A25: 102519548 | B25: 0093683299 | C25: MUHAMMAD ZIDANE FIKRUL 'AZIZ | D25: L | E25: X KA 1 | K25: 102218736 | L25: AKHIR 2022
A26: 102519549 | B26: 0092565914 | C26: NAZWA PUSPA NINGRUM | D26: P | E26: X KA 1 | J26: SISWA MASUK | K26: 102218737 | L26: AKHIR 2022
A27: 102519550 | B27: 0092277023 | C27: NOER KEYLA | D27: P | E27: X KA 1
A28: 102519551 | B28: 0106815228 | C28: PURI AY UNTARI | D28: P | E28: X KA 1 | K28: 102318738 | L28: Awal 2023
A29: 102519552 | B29: 0099103173 | C29: PUTRI KIARA KENCANA | D29: P | E29: X KA 1 | K29: 102319133 | L29: Akhir 2023
A30: 102519553 | B30: 3101903581 | C30: RAFFA AL-FIQRI FEBRIAN | D30: L | E30: X KA 1 | K30: 102319134 | L30: Masuk Dina AK4
A31: 102519554 | B31: 0091434903 | C31: RAHMA ALIA WULANDARI | D31: P | E31: X KA 1
A32: 102519555 | B32: 3107206260 | C32: RAISA RAHADATUL ALIMAH | D32: P | E32: X KA 1 | K32: 102419135 | L32: Awal 2024
A33: 102519556 | B33: 0099094879 | C33: RAMADHANI ALDIANO | D33: L | E33: X KA 1 | K33: 102419523 | L33: Akhir 2024 (Kls X)
A34: 102519557 | B34: 0102675875 | C34: SAFIRA AMARA PUTRI | D34: P | E34: X KA 1 | K34: 102419524 | L34: Masuk XI TKJ 1 M. Nadlif
A35: 102519558 | B35: 0095264635 | C35: SILVI NURSIVA | D35: P | E35: X KA 1
A36: 102519559 | B36: 0102522354 | C36: SONYA MELINDA | D36: P | E36: X KA 1 | K36: 102519525 | L36: Awal 2025
A37: 102519560 | B37: 0091940310 | C37: SYIFA RESTU PURWAKANTI | D37: P | E37: X KA 1 | K37: 102519950 | L37: Akhir 2025
A38: 102519561 | C38: TAQI DZAKWAN | D38: L | E38: X KA 1
A39: 102519562 | B39: 0096879664 | C39: ZULFA HIKMATUL MAULA | D39: P | E39: X KA 1
A40: 102519563 | B40: 0099180280 | C40: ADINDA SAEPUTRI PRATAMA | D40: P | E40: X KA 2
...

Sheet Baru NIS
A1: =H1&B1
A2: =H2&B2 -> X KA 1 | C2: ='Short NIS'!A2 -> 102519525 | D2: ='Short NIS'!B2 -> 3106989660 | E2: =C2&" / "&D2 -> 102519525 / 3106989660 | F2: ='Short NIS'!C2 -> ABGARI RADITYA AHMAD | G2: ='Short NIS'!D2 -> L | H2: ='Short NIS'!E2 -> X KA 1 | I2: KA 1 | J2: 1
A3: =H3&B3 -> X KA 1 | C3: ='Short NIS'!A3 -> 102519526 | D3: ='Short NIS'!B3 -> 0094413313 | E3: =C3&" / "&D3 -> 102519526 / 0094413313 | F3: ='Short NIS'!C3 -> ADINDA PUTRI | G3: ='Short NIS'!D3 -> P | H3: ='Short NIS'!E3 -> X KA 1 | I3: KA 1 | J3: 2
A4: =H4&B4 -> X KA 1 | C4: ='Short NIS'!A4 -> 102519527 | D4: ='Short NIS'!B4 -> 0101004818 | E4: =C4&" / "&D4 -> 102519527 / 0101004818 | F4: ='Short NIS'!C4 -> ALIFA JIHAN IFTINAH | G4: ='Short NIS'!D4 -> P | H4: ='Short NIS'!E4 -> X KA 1 | I4: KA 1 | J4: 3
A5: =H5&B5 -> X KA 1 | C5: ='Short NIS'!A5 -> 102519528 | D5: ='Short NIS'!B5 -> 0099555110 | E5: =C5&" / "&D5 -> 102519528 / 0099555110 | F5: ='Short NIS'!C5 -> ALMIRA ATHYYA HUSNIAH | G5: ='Short NIS'!D5 -> P | H5: ='Short NIS'!E5 -> X KA 1 | I5: KA 1 | J5: 4
A6: =H6&B6 -> X KA 1 | C6: ='Short NIS'!A6 -> 102519529 | D6: ='Short NIS'!B6 -> 0099117757 | E6: =C6&" / "&D6 -> 102519529 / 0099117757 | F6: ='Short NIS'!C6 -> ALYYA RAHMAWATI | G6: ='Short NIS'!D6 -> P | H6: ='Short NIS'!E6 -> X KA 1 | I6: KA 1 | J6: 5
A7: =H7&B7 -> X KA 1 | C7: ='Short NIS'!A7 -> 102519530 | D7: ='Short NIS'!B7 -> 0106834163 | E7: =C7&" / "&D7 -> 102519530 / 0106834163 | F7: ='Short NIS'!C7 -> AMEERA PUTRI AL ZAHRA | G7: ='Short NIS'!D7 -> P | H7: ='Short NIS'!E7 -> X KA 1 | I7: KA 1 | J7: 6
A8: =H8&B8 -> X KA 1 | C8: ='Short NIS'!A8 -> 102519531 | D8: ='Short NIS'!B8 -> 0099850277 | E8: =C8&" / "&D8 -> 102519531 / 0099850277 | F8: ='Short NIS'!C8 -> ARVINO YUMA PRATAMA | G8: ='Short NIS'!D8 -> L | H8: ='Short NIS'!E8 -> X KA 1 | I8: KA 1 | J8: 7
A9: =H9&B9 -> X KA 1 | C9: ='Short NIS'!A9 -> 102519532 | D9: ='Short NIS'!B9 -> 0104157931 | E9: =C9&" / "&D9 -> 102519532 / 0104157931 | F9: ='Short NIS'!C9 -> AYESHA ZEPHANIA | G9: ='Short NIS'!D9 -> P | H9: ='Short NIS'!E9 -> X KA 1 | I9: KA 1 | J9: 8
A10: =H10&B10 -> X KA 1 | C10: ='Short NIS'!A10 -> 102519533 | D10: ='Short NIS'!B10 -> 0095348926 | E10: =C10&" / "&D10 -> 102519533 / 0095348926 | F10: ='Short NIS'!C10 -> CIKAL ABDUL MUIZ MUTSAQIF | G10: ='Short NIS'!D10 -> L | H10: ='Short NIS'!E10 -> X KA 1 | I10: KA 1 | J10: 9
A11: =H11&B11 -> X KA 1 | C11: ='Short NIS'!A11 -> 102519534 | D11: ='Short NIS'!B11 -> 0105056370 | E11: =C11&" / "&D11 -> 102519534 / 0105056370 | F11: ='Short NIS'!C11 -> DANAR PRAWIRA | G11: ='Short NIS'!D11 -> L | H11: ='Short NIS'!E11 -> X KA 1 | I11: KA 1 | J11: 10
A12: =H12&B12 -> X KA 1 | C12: ='Short NIS'!A12 -> 102519535 | D12: ='Short NIS'!B12 -> 0098323888 | E12: =C12&" / "&D12 -> 102519535 / 0098323888 | F12: ='Short NIS'!C12 -> DEVINA YULIA | G12: ='Short NIS'!D12 -> P | H12: ='Short NIS'!E12 -> X KA 1 | I12: KA 1 | J12: 11
A13: =H13&B13 -> X KA 1 | C13: ='Short NIS'!A13 -> 102519536 | D13: ='Short NIS'!B13 -> 0101455732 | E13: =C13&" / "&D13 -> 102519536 / 0101455732 | F13: ='Short NIS'!C13 -> ERLANGGA AL FIKRI | G13: ='Short NIS'!D13 -> L | H13: ='Short NIS'!E13 -> X KA 1 | I13: KA 1 | J13: 12
... A158: =H158&B158 -> X KA 5 | C158: ='Short NIS'!A158 -> 102519681 | D158: ='Short NIS'!B158 -> 0104656986 | E158: =C158&" / "&D158 -> 102519681 / 0104656986 | F158: ='Short NIS'!C158 -> AZKIRA HUMAIRAH SOPIAN | G158: ='Short NIS'!D158 -> P | H158: ='Short NIS'!E158 -> X KA 5 | I158: KA 5 | J158: 12
A159: =H159&B159 -> X KA 5 | C159: ='Short NIS'!A159 -> 102519682 | D159: ='Short NIS'!B159 -> 0095290875 | E159: =C159&" / "&D159 -> 102519682 / 0095290875 | F159: ='Short NIS'!C159 -> DHEA IRFANI | G159: ='Short NIS'!D159 -> P | H159: ='Short NIS'!E159 -> X KA 5 | I159: KA 5 | J159: 13 | N159: KATOLIK
A160: =H160&B160 -> X KA 5 | C160: ='Short NIS'!A160 -> 102519683 | D160: ='Short NIS'!B160 -> 0 | E160: =C160&" / "&D160 -> 102519683 / 0 | F160: ='Short NIS'!C160 -> DHEANA ZAINA RAISSA | G160: ='Short NIS'!D160 -> P | H160: ='Short NIS'!E160 -> X KA 5 | I160: KA 5 | J160: 14
A161: =H161&B161 -> X KA 5 | C161: ='Short NIS'!A161 -> 102519684 | D161: ='Short NIS'!B161 -> 0095512649 | E161: =C161&" / "&D161 -> 102519684 / 0095512649 | F161: ='Short NIS'!C161 -> FACHTIRA JULIYANSYAH YULISTIAWAN | G161: ='Short NIS'!D161 -> L | H161: ='Short NIS'!E161 -> X KA 5 | I161: KA 5 | J161: 15
A162: =H162&B162 -> X KA 5 | C162: ='Short NIS'!A162 -> 102519685 | D162: ='Short NIS'!B162 -> 0099154065 | E162: =C162&" / "&D162 -> 102519685 / 0099154065 | F162: ='Short NIS'!C162 -> FAHRI RAMADHAN | G162: ='Short NIS'!D162 -> L | H162: ='Short NIS'!E162 -> X KA 5 | I162: KA 5 | J162: 16
A163: =H163&B163 -> X KA 5 | C163: ='Short NIS'!A163 -> 102519686 | D163: ='Short NIS'!B163 -> 0094145271 | E163: =C163&" / "&D163 -> 102519686 / 0094145271 | F163: ='Short NIS'!C163 -> FATHI RIZKY MADANI | G163: ='Short NIS'!D163 -> L | H163: ='Short NIS'!E163 -> X KA 5 | I163: KA 5 | J163: 17
A164: =H164&B164 -> X KA 5 | C164: ='Short NIS'!A164 -> 102519687 | D164: ='Short NIS'!B164 -> 0108567925 | E164: =C164&" / "&D164 -> 102519687 / 0108567925 | F164: ='Short NIS'!C164 -> FIRMAN NURRAYYAN | G164: ='Short NIS'!D164 -> L | H164: ='Short NIS'!E164 -> X KA 5 | I164: KA 5 | J164: 18
A165: =H165&B165 -> X KA 5 | C165: ='Short NIS'!A165 -> 102519688 | D165: ='Short NIS'!B165 -> 0103249974 | E165: =C165&" / "&D165 -> 102519688 / 0103249974 | F165: ='Short NIS'!C165 -> FRISILIA PUTRI | G165: ='Short NIS'!D165 -> P | H165: ='Short NIS'!E165 -> X KA 5 | I165: KA 5 | J165: 19
A166: =H166&B166 -> X KA 5 | C166: ='Short NIS'!A166 -> 102519689 | D166: ='Short NIS'!B166 -> 0094762588 | E166: =C166&" / "&D166 -> 102519689 / 0094762588 | F166: ='Short NIS'!C166 -> GALIH SAPUTRA | G166: ='Short NIS'!D166 -> L | H166: ='Short NIS'!E166 -> X KA 5 | I166: KA 5 | J166: 20
A167: =H167&B167 -> X KA 5 | C167: ='Short NIS'!A167 -> 102519690 | D167: ='Short NIS'!B167 -> 0102695868 | E167: =C167&" / "&D167 -> 102519690 / 0102695868 | F167: ='Short NIS'!C167 -> HASNA NURUL AZKIYA | G167: ='Short NIS'!D167 -> P | H167: ='Short NIS'!E167 -> X KA 5 | I167: KA 5 | J167: 21
A168: =H168&B168 -> X KA 5 | C168: ='Short NIS'!A168 -> 102519691 | D168: ='Short NIS'!B168 -> 0096461480 | E168: =C168&" / "&D168 -> 102519691 / 0096461480 | F168: ='Short NIS'!C168 -> INDAH FITRIA HARUM | G168: ='Short NIS'!D168 -> P | H168: ='Short NIS'!E168 -> X KA 5 | I168: KA 5 | J168: 22
A169: =H169&B169 -> X KA 5 | C169: ='Short NIS'!A169 -> 102519692 | D169: ='Short NIS'!B169 -> 0102879514 | E169: =C169&" / "&D169 -> 102519692 / 0102879514 | F169: ='Short NIS'!C169 -> KEYLA ADITYA PUTRI | G169: ='Short NIS'!D169 -> P | H169: ='Short NIS'!E169 -> X KA 5 | I169: KA 5 | J169: 23
A170: =H170&B170 -> X KA 5 | C170: ='Short NIS'!A170 -> 102519693 | D170: ='Short NIS'!B170 -> 0098038591 | E170: =C170&" / "&D170 -> 102519693 / 0098038591 | F170: ='Short NIS'!C170 -> KIARA ANGELIA CONDOLIZA | G170: ='Short NIS'!D170 -> P | H170: ='Short NIS'!E170 -> X KA 5 | I170: KA 5 | J170: 24
A171: =H171&B171 -> X KA 5 | C171: ='Short NIS'!A171 -> 102519694 | D171: ='Short NIS'!B171 -> 0101627775 | E171: =C171&" / "&D171 -> 102519694 / 0101627775 | F171: ='Short NIS'!C171 -> LANGIT RAJA ATTALLA CANAECCARA | G171: ='Short NIS'!D171 -> L | H171: ='Short NIS'!E171 -> X KA 5 | I171: KA 5 | J171: 25
... A214: =H214&B214 -> X KA 6 | C214: ='Short NIS'!A214 -> 102519737 | D214: ='Short NIS'!B214 -> 0103441274 | E214: =C214&" / "&D214 -> 102519737 / 0103441274 | F214: ='Short NIS'!C214 -> NEYSA NUR KAMELIA | G214: ='Short NIS'!D214 -> P | H214: ='Short NIS'!E214 -> X KA 6 | I214: KA 6 | J214: 33
A215: =H215&B215 -> X KA 6 | C215: ='Short NIS'!A215 -> 102519738 | D215: ='Short NIS'!B215 -> 0104797186 | E215: =C215&" / "&D215 -> 102519738 / 0104797186 | F215: ='Short NIS'!C215 -> NIKEN MARSHA ANDREA | G215: ='Short NIS'!D215 -> P | H215: ='Short NIS'!E215 -> X KA 6 | I215: KA 6
A216: =H216&B216 -> X KA 6 | C216: ='Short NIS'!A216 -> 102519739 | D216: ='Short NIS'!B216 -> 0097433580 | E216: =C216&" / "&D216 -> 102519739 / 0097433580 | F216: ='Short NIS'!C216 -> PAISAL PIRMANSAH | G216: ='Short NIS'!D216 -> L | H216: ='Short NIS'!E216 -> X KA 6 | I216: KA 6
A217: =H217&B217 -> X KA 6 | C217: ='Short NIS'!A217 -> 102519740 | D217: ='Short NIS'!B217 -> 0107149425 | E217: =C217&" / "&D217 -> 102519740 / 0107149425 | F217: ='Short NIS'!C217 -> RADITHYA RAMADHANI | G217: ='Short NIS'!D217 -> L | H217: ='Short NIS'!E217 -> X KA 6 | I217: KA 6
A218: =H218&B218 -> X KA 6 | C218: ='Short NIS'!A218 -> 102519741 | D218: ='Short NIS'!B218 -> 0104088787 | E218: =C218&" / "&D218 -> 102519741 / 0104088787 | F218: ='Short NIS'!C218 -> RAHMA MAULIDA AZAHRA | G218: ='Short NIS'!D218 -> P | H218: ='Short NIS'!E218 -> X KA 6 | I218: KA 6
A219: =H219&B219 -> X KA 6 | C219: ='Short NIS'!A219 -> 102519742 | D219: ='Short NIS'!B219 -> 3106778797 | E219: =C219&" / "&D219 -> 102519742 / 3106778797 | F219: ='Short NIS'!C219 -> RAIDAH FATHIN HAFIDZAH | G219: ='Short NIS'!D219 -> P | H219: ='Short NIS'!E219 -> X KA 6 | I219: KA 6
A220: =H220&B220 -> X KA 6 | C220: ='Short NIS'!A220 -> 102519743 | D220: ='Short NIS'!B220 -> 0101887176 | E220: =C220&" / "&D220 -> 102519743 / 0101887176 | F220: ='Short NIS'!C220 -> RIDVAN EL ZHAR ARVELADZE | G220: ='Short NIS'!D220 -> L | H220: ='Short NIS'!E220 -> X KA 6 | I220: KA 6
A221: =H221&B221 -> X KA 6 | C221: ='Short NIS'!A221 -> 102519744 | D221: ='Short NIS'!B221 -> 0092347863 | E221: =C221&" / "&D221 -> 102519744 / 0092347863 | F221: ='Short NIS'!C221 -> SELIA RAHMAYUNISA | G221: ='Short NIS'!D221 -> P | H221: ='Short NIS'!E221 -> X KA 6 | I221: KA 6
A222: =H222&B222 -> X KA 6 | C222: ='Short NIS'!A222 -> 102519745 | D222: ='Short NIS'!B222 -> 0102817772 | E222: =C222&" / "&D222 -> 102519745 / 0102817772 | F222: ='Short NIS'!C222 -> SHILLA QUENSA KIRANA | G222: ='Short NIS'!D222 -> P | H222: ='Short NIS'!E222 -> X KA 6 | I222: KA 6
A223: =H223&B223 -> X KA 6 | C223: ='Short NIS'!A223 -> 102519746 | D223: ='Short NIS'!B223 -> 0091586526 | E223: =C223&" / "&D223 -> 102519746 / 0091586526 | F223: ='Short NIS'!C223 -> SITI RAHMA KHOIRUNNISA | G223: ='Short NIS'!D223 -> P | H223: ='Short NIS'!E223 -> X KA 6 | I223: KA 6
A224: =H224&B224 -> X KA 6 | C224: ='Short NIS'!A224 -> 102519747 | D224: ='Short NIS'!B224 -> 0119719112 | E224: =C224&" / "&D224 -> 102519747 / 0119719112 | F224: ='Short NIS'!C224 -> VIRTA SETIA AULIA IKA | G224: ='Short NIS'!D224 -> P | H224: ='Short NIS'!E224 -> X KA 6 | I224: KA 6
A225: =H225&B225 -> X KA 6 | C225: ='Short NIS'!A225 -> 102519748 | D225: ='Short NIS'!B225 -> 0095515830 | E225: =C225&" / "&D225 -> 102519748 / 0095515830 | F225: ='Short NIS'!C225 -> YASMINE KAMILA QAISYARA | G225: ='Short NIS'!D225 -> P | H225: ='Short NIS'!E225 -> X KA 6 | I225: KA 6
A226: =H226&B226 -> X KA 6 | C226: ='Short NIS'!A226 -> 102519749 | D226: ='Short NIS'!B226 -> 0096522338 | E226: =C226&" / "&D226 -> 102519749 / 0096522338 | F226: ='Short NIS'!C226 -> YOGA KURNIA ALGIFARI | G226: ='Short NIS'!D226 -> L | H226: ='Short NIS'!E226 -> X KA 6 | I226: KA 6
...

Sheet Klaper
A1: No | B1: NIS | C1: NISN | D1: NIS/NISN | E1: NAMA SISWA | F1: L/P | G1: TAHUN MASUK | P1: KET
G2: 2018/2019 | H2: 2019/2020 | I2: 2020/2021 | J2: 2021/2022 | K2: 2022/2023 | L2: 2023/2024 | M2: 2024/2025 | N2: 2025/2026 | O2: 2026/2027
A3: 1 | B3: 101816762 | C3: 0034452167 | D3: =B3&" /"&C3 -> 101816762 /0034452167 | E3: ABELLYA NADINE PANGESTU | F3: P | G3: XIII AK 4 | P3: Lulus 4 Juni 2022
A4: 2 | B4: 101816765 | C4: 0028014768 | D4: =B4&" /"&C4 -> 101816765 /0028014768 | E4: ADHIFIAN DHIYA 'ULHAQ | F4: L | G4: XIII AK 4 | P4: Lulus 4 Juni 2022
A5: 3 | B5: 101816770 | C5: 0034475483 | D5: =B5&" /"&C5 -> 101816770 /0034475483 | E5: AENY RACHMY HODIZAH | F5: P | G5: XIII AK 2 | P5: Lulus 4 Juni 2022
A6: 4 | B6: 101816771 | C6: 0033681597 | D6: =B6&" /"&C6 -> 101816771 /0033681597 | E6: AFRILLA MUTHI ARIZONA | F6: P | G6: XIII AK 6 | P6: Lulus 4 Juni 2022
A7: 5 | B7: 101816772 | C7: 0028941471 | D7: =B7&" /"&C7 -> 101816772 /0028941471 | E7: AGHNIYA NUR RIZKA FADILA | F7: P | G7: XIII AK 3 | P7: Lulus 4 Juni 2022
A8: 6 | B8: 101816774 | C8: 0033370746 | D8: =B8&" /"&C8 -> 101816774 /0033370746 | E8: AGUNG RAKHMADI | F8: L | G8: XIII AK 2 | P8: Lulus 4 Juni 2022
A9: 7 | B9: 101816775 | C9: 0037735544 | D9: =B9&" /"&C9 -> 101816775 /0037735544 | E9: AGUNG SOLEHUDIN | F9: L | G9: XIII AK 4 | P9: Lulus 4 Juni 2022
A10: 8 | B10: 101816779 | C10: 0031331031 | D10: =B10&" /"&C10 -> 101816779 /0031331031 | E10: AIDA KHOIRUNISA | F10: P | G10: XIII AK 5 | P10: Lulus 4 Juni 2022
A11: 9 | B11: 101816780 | C11: 0037593018 | D11: =B11&" /"&C11 -> 101816780 /0037593018 | E11: AKBAR DWI YULIANTO | F11: L | G11: XIII AK 3 | P11: Lulus 4 Juni 2022
A12: 10 | B12: 101816784 | C12: 0009155871 | D12: =B12&" /"&C12 -> 101816784 /0009155871 | E12: ALIEF RAVALDHO | F12: L | G12: XIII AK 2 | P12: Lulus 4 Juni 2022
A13: 11 | B13: 101816789 | C13: 0029831699 | D13: =B13&" /"&C13 -> 101816789 /0029831699 | E13: ALYA RAMADHANI | F13: P | G13: XIII AK 2 | P13: Lulus 4 Juni 2022
A14: 12 | B14: 101816791 | C14: 0033864103 | D14: =B14&" /"&C14 -> 101816791 /0033864103 | E14: AMBAR SARI FITRIANNY | F14: P | G14: XIII AK 2 | P14: Lulus 4 Juni 2022
... A93: 91 | B93: 101816933 | C93: 0025428633 | D93: =B93&" /"&C93 -> 101816933 /0025428633 | E93: KHAIRUN NISA | F93: P | G93: XIII AK 4 | P93: Lulus 4 Juni 2022
A94: 92 | B94: 101816934 | C94: 0021143727 | D94: 101816934 /0021143727 | E94: KHANZA AMALIA | F94: P | G94: XIII AK 3 | P94: Lulus 4 Juni 2022
A95: 93 | B95: 101816935 | C95: 0013827411 | D95: =B95&" /"&C95 -> 101816935 /0013827411 | E95: KHARISMA HERLIADI PUTERA | F95: L | G95: XIII AK 3 | P95: Lulus 4 Juni 2022
A96: 94 | B96: 101816936 | C96: 0035971864 | D96: =B96&" /"&C96 -> 101816936 /0035971864 | E96: KHASAN NURSALIM | F96: L | G96: XIII AK 6 | P96: Lulus 4 Juni 2022
A97: 95 | B97: 101816941 | C97: 0045255978 | D97: =B97&" /"&C97 -> 101816941 /0045255978 | E97: LATHIFAH EKA KUSUMA PUTRI | F97: P | G97: XIII AK 3 | P97: Lulus 4 Juni 2022
A98: 96 | B98: 101816942 | C98: 0025894854 | D98: =B98&" /"&C98 -> 101816942 /0025894854 | E98: LAURA ALVERINA FERNANDA | F98: P | G98: XIII AK 4 | P98: Lulus 4 Juni 2022
A99: 97 | B99: 101816944 | C99: 0033068854 | D99: =B99&" /"&C99 -> 101816944 /0033068854 | E99: LINGGA SATRIA PERDANA | F99: L | G99: XIII AK 5 | P99: Lulus 4 Juni 2022
A100: 98 | B100: 101816945 | C100: 0033735339 | D100: =B100&" /"&C100 -> 101816945 /0033735339 | E100: LIRA NIRMALA PUTRI | F100: P | G100: XIII AK 3 | P100: Lulus 4 Juni 2022
A101: 99 | B101: 101816946 | C101: 0034435681 | D101: =B101&" /"&C101 -> 101816946 /0034435681 | E101: LISVY RHEINA PUTRI | F101: P | G101: XIII AK 6 | P101: Lulus 4 Juni 2022
A102: 100 | B102: 101816947 | C102: 0037588053 | D102: =B102&" /"&C102 -> 101816947 /0037588053 | E102: LOLA AMELIA AZAHRA | F102: P | G102: XIII AK 2 | P102: Lulus 4 Juni 2022
A103: 101 | B103: 101816948 | C103: 0035845630 | D103: =B103&" /"&C103 -> 101816948 /0035845630 | E103: LUKMAN NULHAKIM MUSTAFA | F103: L | G103: XIII AK 6 | P103: Lulus 4 Juni 2022
A104: 102 | B104: 101816954 | C104: 0026557218 | D104: =B104&" /"&C104 -> 101816954 /0026557218 | E104: MAITSA LUTHFIYYAH DURROTUNNISA | F104: P | G104: XIII AK 5 | P104: Lulus 4 Juni 2022
A105: 103 | B105: 101816955 | C105: 0022669232 | D105: =B105&" /"&C105 -> 101816955 /0022669232 | E105: MARSYA SANDRA AVISTA | F105: P | G105: XIII AK 6 | P105: Lulus 4 Juni 2022
A106: 104 | B106: 101816956 | C106: 0031797461 | D106: =B106&" /"&C106 -> 101816956 /0031797461 | E106: MARSYA ZAHRANI | F106: P | G106: XIII AK 3 | P106: Lulus 4 Juni 2022
... A195: 193 | B195: 101817152 | C195: 0027574578 | D195: =B195&" /"&C195 -> 101817152 /0027574578 | E195: ZHILLAN IBADURROHMAN | F195: L | G195: XIII AK 5 | P195: Lulus 4 Juni 2022
P196: Lulus 3 Mei 2023
A197: 1 | B197: 101917156 | C197: 0042730521 | D197: =B197&"/"&C197 -> 101917156/0042730521 | E197: ADDY PERMANA PUTRA | F197: L | H197: XII AK 1 | P197: Lulus 3 Mei 2023
A198: 2 | B198: 101917192 | C198: 0047451133 | D198: =B198&"/"&C198 -> 101917192/0047451133 | E198: ADIA ENDRIHARTONO | F198: L | H198: XII AK 2 | P198: Lulus 3 Mei 2023
A199: 3 | B199: 101917444 | C199: 0035004289 | D199: =B199&"/"&C199 -> 101917444/0035004289 | E199: ADITYA FIRMAN NUGROHO | F199: L | H199: XII TKJ 1 | P199: Lulus 4 Juni 2022
A200: 4 | B200: 101917480 | C200: 0033447291 | D200: =B200&"/"&C200 -> 101917480/0033447291 | E200: ADITYA FIRMAN SAPUTRA | F200: L | H200: XII TKJ 2 | P200: Lulus 4 Juni 2022
A201: 5 | B201: 101917481 | C201: 0046314331 | D201: =B201&"/"&C201 -> 101917481/0046314331 | E201: ADITYA PERBAWA | F201: L | H201: XII TKJ 2 | P201: Lulus 4 Juni 2022
A202: 6 | B202: 101917264 | C202: 0042633534 | D202: =B202&"/"&C202 -> 101917264/0042633534 | E202: ADITYA ZHAFIR GHUFRAN | F202: L | H202: XII AK 4 | P202: Lulus 3 Mei 2023
A203: 7 | B203: 101917408 | C203: 0043678101 | D203: =B203&"/"&C203 -> 101917408/0043678101 | E203: ADYA IZZATI NASRULLOH | F203: L | H203: XII RPL 2 | P203: Lulus 4 Juni 2022
A204: 8 | B204: 101917482 | C204: 0045109808 | D204: =B204&"/"&C204 -> 101917482/0045109808 | E204: ADYTTIA | F204: L | H204: XII TKJ 2 | P204: Lulus 4 Juni 2022
A205: 9 | B205: 101917483 | C205: 0012606642 | D205: =B205&"/"&C205 -> 101917483/0012606642 | E205: AGAM KURNIAWAN | F205: L | H205: XII TKJ 2 | P205: Lulus 4 Juni 2022
A206: 10 | B206: 101917409 | C206: 0042337357 | D206: =B206&"/"&C206 -> 101917409/0042337357 | E206: AGNA FIKRI AL RIFAI | F206: L | H206: XII RPL 2 | P206: Lulus 4 Juni 2022
...

Sheet Baru
A1: Kls/No | B1: No | C1: NIS | D1: NISN | E1: NIS/NISN | F1: NAMA SISWA | G1: L/P | H1: KLS | I1: Kls/Jur | J1: Jur | K1: Kls/LP | L1: ket | M1: Agama
A2: =H2&B2 -> X KA 11 | B2: =COUNTIF(H$2:H2,H2) -> 1 | C2: ='Baru NIS'!C2 -> 102519525 | D2: ='Baru NIS'!D2 -> 3106989660 | E2: ='Baru NIS'!E2 -> 102519525 / 3106989660 | F2: ='Baru NIS'!F2 -> ABGARI RADITYA AHMAD | G2: ='Baru NIS'!G2 -> L | H2: ='Baru NIS'!H2 -> X KA 1 | I2: X KA | J2: KA | K2: =G2&J2 -> LKA
A3: =H3&B3 -> X KA 12 | B3: =COUNTIF(H$2:H3,H3) -> 2 | C3: ='Baru NIS'!C3 -> 102519526 | D3: ='Baru NIS'!D3 -> 0094413313 | E3: ='Baru NIS'!E3 -> 102519526 / 0094413313 | F3: ='Baru NIS'!F3 -> ADINDA PUTRI | G3: ='Baru NIS'!G3 -> P | H3: ='Baru NIS'!H3 -> X KA 1 | I3: X KA | J3: KA | K3: =G3&J3 -> PKA
A4: =H4&B4 -> X KA 13 | B4: =COUNTIF(H$2:H4,H4) -> 3 | C4: ='Baru NIS'!C4 -> 102519527 | D4: ='Baru NIS'!D4 -> 0101004818 | E4: ='Baru NIS'!E4 -> 102519527 / 0101004818 | F4: ='Baru NIS'!F4 -> ALIFA JIHAN IFTINAH | G4: ='Baru NIS'!G4 -> P | H4: ='Baru NIS'!H4 -> X KA 1 | I4: X KA | J4: KA | K4: =G4&J4 -> PKA
A5: =H5&B5 -> X KA 14 | B5: =COUNTIF(H$2:H5,H5) -> 4 | C5: ='Baru NIS'!C5 -> 102519528 | D5: ='Baru NIS'!D5 -> 0099555110 | E5: ='Baru NIS'!E5 -> 102519528 / 0099555110 | F5: ='Baru NIS'!F5 -> ALMIRA ATHYYA HUSNIAH | G5: ='Baru NIS'!G5 -> P | H5: ='Baru NIS'!H5 -> X KA 1 | I5: X KA | J5: KA | K5: =G5&J5 -> PKA
A6: =H6&B6 -> X KA 15 | B6: =COUNTIF(H$2:H6,H6) -> 5 | C6: ='Baru NIS'!C6 -> 102519529 | D6: ='Baru NIS'!D6 -> 0099117757 | E6: ='Baru NIS'!E6 -> 102519529 / 0099117757 | F6: ='Baru NIS'!F6 -> ALYYA RAHMAWATI | G6: ='Baru NIS'!G6 -> P | H6: ='Baru NIS'!H6 -> X KA 1 | I6: X KA | J6: KA | K6: =G6&J6 -> PKA
A7: =H7&B7 -> X KA 16 | B7: =COUNTIF(H$2:H7,H7) -> 6 | C7: ='Baru NIS'!C7 -> 102519530 | D7: ='Baru NIS'!D7 -> 0106834163 | E7: ='Baru NIS'!E7 -> 102519530 / 0106834163 | F7: ='Baru NIS'!F7 -> AMEERA PUTRI AL ZAHRA | G7: ='Baru NIS'!G7 -> P | H7: ='Baru NIS'!H7 -> X KA 1 | I7: X KA | J7: KA | K7: =G7&J7 -> PKA
A8: =H8&B8 -> X KA 17 | B8: =COUNTIF(H$2:H8,H8) -> 7 | C8: ='Baru NIS'!C8 -> 102519531 | D8: ='Baru NIS'!D8 -> 0099850277 | E8: ='Baru NIS'!E8 -> 102519531 / 0099850277 | F8: ='Baru NIS'!F8 -> ARVINO YUMA PRATAMA | G8: ='Baru NIS'!G8 -> L | H8: ='Baru NIS'!H8 -> X KA 1 | I8: X KA | J8: KA | K8: =G8&J8 -> LKA
A9: =H9&B9 -> X KA 18 | B9: =COUNTIF(H$2:H9,H9) -> 8 | C9: ='Baru NIS'!C9 -> 102519532 | D9: ='Baru NIS'!D9 -> 0104157931 | E9: ='Baru NIS'!E9 -> 102519532 / 0104157931 | F9: ='Baru NIS'!F9 -> AYESHA ZEPHANIA | G9: ='Baru NIS'!G9 -> P | H9: ='Baru NIS'!H9 -> X KA 1 | I9: X KA | J9: KA | K9: =G9&J9 -> PKA
A10: =H10&B10 -> X KA 19 | B10: =COUNTIF(H$2:H10,H10) -> 9 | C10: ='Baru NIS'!C10 -> 102519533 | D10: ='Baru NIS'!D10 -> 0095348926 | E10: ='Baru NIS'!E10 -> 102519533 / 0095348926 | F10: ='Baru NIS'!F10 -> CIKAL ABDUL MUIZ MUTSAQIF | G10: ='Baru NIS'!G10 -> L | H10: ='Baru NIS'!H10 -> X KA 1 | I10: X KA | J10: KA | K10: =G10&J10 -> LKA
A11: =H11&B11 -> X KA 110 | B11: =COUNTIF(H$2:H11,H11) -> 10 | C11: ='Baru NIS'!C11 -> 102519534 | D11: ='Baru NIS'!D11 -> 0105056370 | E11: ='Baru NIS'!E11 -> 102519534 / 0105056370 | F11: ='Baru NIS'!F11 -> DANAR PRAWIRA | G11: ='Baru NIS'!G11 -> L | H11: ='Baru NIS'!H11 -> X KA 1 | I11: X KA | J11: KA | K11: =G11&J11 -> LKA
A12: =H12&B12 -> X KA 111 | B12: =COUNTIF(H$2:H12,H12) -> 11 | C12: ='Baru NIS'!C12 -> 102519535 | D12: ='Baru NIS'!D12 -> 0098323888 | E12: ='Baru NIS'!E12 -> 102519535 / 0098323888 | F12: ='Baru NIS'!F12 -> DEVINA YULIA | G12: ='Baru NIS'!G12 -> P | H12: ='Baru NIS'!H12 -> X KA 1 | I12: X KA | J12: KA | K12: =G12&J12 -> PKA
A13: =H13&B13 -> X KA 112 | B13: =COUNTIF(H$2:H13,H13) -> 12 | C13: ='Baru NIS'!C13 -> 102519536 | D13: ='Baru NIS'!D13 -> 0101455732 | E13: ='Baru NIS'!E13 -> 102519536 / 0101455732 | F13: ='Baru NIS'!F13 -> ERLANGGA AL FIKRI | G13: ='Baru NIS'!G13 -> L | H13: ='Baru NIS'!H13 -> X KA 1 | I13: X KA | J13: KA | K13: =G13&J13 -> LKA
... A394: =H394&B394 -> X TJKT 38 | B394: =COUNTIF(H$2:H394,H394) -> 8 | C394: ='Baru NIS'!C394 -> 102519917 | D394: ='Baru NIS'!D394 -> 0 | E394: ='Baru NIS'!E394 -> 102519917 / 0 | F394: ='Baru NIS'!F394 -> EBRAN JIBRIL EARLY | G394: ='Baru NIS'!G394 -> L | H394: ='Baru NIS'!H394 -> X TJKT 3 | I394: X TKJ | J394: TKJ | K394: =G394&J394 -> LTKJ
A395: =H395&B395 -> X TJKT 39 | B395: =COUNTIF(H$2:H395,H395) -> 9 | C395: ='Baru NIS'!C396 -> 102519919 | D395: ='Baru NIS'!D396 -> 0091685872 | E395: ='Baru NIS'!E396 -> 102519919 / 0091685872 | F395: ='Baru NIS'!F396 -> FARHAN LUTFIANSYAH | G395: ='Baru NIS'!G396 -> L | H395: ='Baru NIS'!H396 -> X TJKT 3 | I395: X TKJ | J395: TKJ | K395: =G395&J395 -> LTKJ
A396: =H396&B396 -> X TJKT 310 | B396: =COUNTIF(H$2:H396,H396) -> 10 | C396: ='Baru NIS'!C397 -> 102519920 | D396: ='Baru NIS'!D397 -> 0089884756 | E396: ='Baru NIS'!E397 -> 102519920 / 0089884756 | F396: ='Baru NIS'!F397 -> FAUZAN KUSTIAWAN | G396: ='Baru NIS'!G397 -> L | H396: ='Baru NIS'!H397 -> X TJKT 3 | I396: X TKJ | J396: TKJ | K396: =G396&J396 -> LTKJ
A397: =H397&B397 -> X TJKT 311 | B397: =COUNTIF(H$2:H397,H397) -> 11 | C397: ='Baru NIS'!C398 -> 102519921 | D397: ='Baru NIS'!D398 -> 0096776530 | E397: ='Baru NIS'!E398 -> 102519921 / 0096776530 | F397: ='Baru NIS'!F398 -> GALUH RAMADAN | G397: ='Baru NIS'!G398 -> L | H397: ='Baru NIS'!H398 -> X TJKT 3 | I397: X TKJ | J397: TKJ | K397: =G397&J397 -> LTKJ
A398: =H398&B398 -> X TJKT 312 | B398: =COUNTIF(H$2:H398,H398) -> 12 | C398: ='Baru NIS'!C399 -> 102519922 | D398: ='Baru NIS'!D399 -> 0108065085 | E398: ='Baru NIS'!E399 -> 102519922 / 0108065085 | F398: ='Baru NIS'!F399 -> HILMI TAUFIQURRAHMAN | G398: ='Baru NIS'!G399 -> L | H398: ='Baru NIS'!H399 -> X TJKT 3 | I398: X TKJ | J398: TKJ | K398: =G398&J398 -> LTKJ
A399: =H399&B399 -> X TJKT 313 | B399: =COUNTIF(H$2:H399,H399) -> 13 | C399: ='Baru NIS'!C400 -> 102519923 | D399: ='Baru NIS'!D400 -> 0106368743 | E399: ='Baru NIS'!E400 -> 102519923 / 0106368743 | F399: ='Baru NIS'!F400 -> KELVIN ARKENZY SALMANSYAH | G399: ='Baru NIS'!G400 -> L | H399: ='Baru NIS'!H400 -> X TJKT 3 | I399: X TKJ | J399: TKJ | K399: =G399&J399 -> LTKJ
A400: =H400&B400 -> X TJKT 314 | B400: =COUNTIF(H$2:H400,H400) -> 14 | C400: ='Baru NIS'!C401 -> 102519924 | D400: ='Baru NIS'!D401 -> 0093029487 | E400: ='Baru NIS'!E401 -> 102519924 / 0093029487 | F400: ='Baru NIS'!F401 -> KEYLA SELVIA AZAHRA | G400: ='Baru NIS'!G401 -> P | H400: ='Baru NIS'!H401 -> X TJKT 3 | I400: X TKJ | J400: TKJ | K400: =G400&J400 -> PTKJ
A401: =H401&B401 -> X TJKT 315 | B401: =COUNTIF(H$2:H401,H401) -> 15 | C401: ='Baru NIS'!C402 -> 102519925 | D401: ='Baru NIS'!D402 -> 0 | E401: ='Baru NIS'!E402 -> 102519925 / 0 | F401: ='Baru NIS'!F402 -> MILAN RAMDHANI | G401: ='Baru NIS'!G402 -> P | H401: ='Baru NIS'!H402 -> X TJKT 3 | I401: X TKJ | J401: TKJ | K401: =G401&J401 -> PTKJ
A402: =H402&B402 -> X TJKT 316 | B402: =COUNTIF(H$2:H402,H402) -> 16 | C402: ='Baru NIS'!C403 -> 102519926 | D402: ='Baru NIS'!D403 -> 0095163747 | E402: ='Baru NIS'!E403 -> 102519926 / 0095163747 | F402: ='Baru NIS'!F403 -> MOHAMAD FAHMI RAHADIANSYAH | G402: ='Baru NIS'!G403 -> L | H402: ='Baru NIS'!H403 -> X TJKT 3 | I402: X TKJ | J402: TKJ | K402: =G402&J402 -> LTKJ
A403: =H403&B403 -> X TJKT 317 | B403: =COUNTIF(H$2:H403,H403) -> 17 | C403: ='Baru NIS'!C404 -> 102519927 | D403: ='Baru NIS'!D404 -> 0107695957 | E403: ='Baru NIS'!E404 -> 102519927 / 0107695957 | F403: ='Baru NIS'!F404 -> MOHAMAD HAIKAL | G403: ='Baru NIS'!G404 -> L | H403: ='Baru NIS'!H404 -> X TJKT 3 | I403: X TKJ | J403: TKJ | K403: =G403&J403 -> LTKJ
A404: =H404&B404 -> X TJKT 318 | B404: =COUNTIF(H$2:H404,H404) -> 18 | C404: ='Baru NIS'!C405 -> 102519928 | D404: ='Baru NIS'!D405 -> 0 | E404: ='Baru NIS'!E405 -> 102519928 / 0 | F404: ='Baru NIS'!F405 -> MOHAMMAD ADITYA ALI PRADANA | G404: ='Baru NIS'!G405 -> L | H404: ='Baru NIS'!H405 -> X TJKT 3 | I404: X TKJ | J404: TKJ | K404: =G404&J404 -> LTKJ
A405: =H405&B405 -> X TJKT 319 | B405: =COUNTIF(H$2:H405,H405) -> 19 | C405: ='Baru NIS'!C406 -> 102519929 | D405: ='Baru NIS'!D406 -> 0095233073 | E405: ='Baru NIS'!E406 -> 102519929 / 0095233073 | F405: ='Baru NIS'!F406 -> MUHAMAD ADRIANSAH | G405: ='Baru NIS'!G406 -> L | H405: ='Baru NIS'!H406 -> X TJKT 3 | I405: X TKJ | J405: TKJ | K405: =G405&J405 -> LTKJ
A406: =H406&B406 -> X TJKT 320 | B406: =COUNTIF(H$2:H406,H406) -> 20 | C406: ='Baru NIS'!C407 -> 102519930 | D406: ='Baru NIS'!D407 -> 0102625019 | E406: ='Baru NIS'!E407 -> 102519930 / 0102625019 | F406: ='Baru NIS'!F407 -> MUHAMAD NUR HIZAM | G406: ='Baru NIS'!G407 -> L | H406: ='Baru NIS'!H407 -> X TJKT 3 | I406: X TKJ | J406: TKJ | K406: =G406&J406 -> LTKJ
... A425: =H425&B425 -> X TJKT 339 | B425: =COUNTIF(H$2:H425,H425) -> 39 | C425: ='Baru NIS'!C426 -> 102519949 | D425: ='Baru NIS'!D426 -> 0 | E425: ='Baru NIS'!E426 -> 102519949 / 0 | F425: ='Baru NIS'!F426 -> ZIYAD HELMI | G425: ='Baru NIS'!G426 -> L | H425: ='Baru NIS'!H426 -> X TJKT 3 | I425: X TKJ | J425: TKJ | K425: =G425&J425 -> LTKJ
A426: =H426&B426 -> XI KA 11 | B426: =COUNTIF(H$2:H426,H426) -> 1 | C426: 102419135 | D426: 0086985872 | E426: 102419135 / 0086985872 | F426: AKHTAR ANARGYA WAHYUDI | G426: L | H426: XI KA 1 | I426: XI KA | J426: KA | K426: =G426&J426 -> LKA | P426: L
A427: =H427&B427 -> XI KA 12 | B427: =COUNTIF(H$2:H427,H427) -> 2 | C427: 102419136 | D427: 0082738092 | E427: 102419136 / 0082738092 | F427: AKMAL NUR HAKIM | G427: L | H427: XI KA 1 | I427: XI KA | J427: KA | K427: =G427&J427 -> LKA | P427: L
A428: =H428&B428 -> XI KA 13 | B428: =COUNTIF(H$2:H428,H428) -> 3 | C428: 102419137 | D428: 0085056739 | E428: 102419137 / 0085056739 | F428: ANDHIKA DWI PUTRA KUSTYAN | G428: L | H428: XI KA 1 | I428: XI KA | J428: KA | K428: =G428&J428 -> LKA | P428: L
A429: =H429&B429 -> XI KA 14 | B429: =COUNTIF(H$2:H429,H429) -> 4 | C429: 102419138 | D429: 0096040843 | E429: 102419138 / 0096040843 | F429: ARRUBI NAZMA HIDAYAT | G429: P | H429: XI KA 1 | I429: XI KA | J429: KA | K429: =G429&J429 -> PKA | P429: P
A430: =H430&B430 -> XI KA 15 | B430: =COUNTIF(H$2:H430,H430) -> 5 | C430: 102419139 | D430: 0091552057 | E430: 102419139 / 0091552057 | F430: AVISA VALERIE INDRA PUTRI | G430: P | H430: XI KA 1 | I430: XI KA | J430: KA | K430: =G430&J430 -> PKA | P430: P
A431: =H431&B431 -> XI KA 16 | B431: =COUNTIF(H$2:H431,H431) -> 6 | C431: 102419140 | D431: 0081306089 | E431: 102419140 / 0081306089 | F431: CHARISA FITRIYANTI | G431: P | H431: XI KA 1 | I431: XI KA | J431: KA | K431: =G431&J431 -> PKA | P431: P
A432: =H432&B432 -> XI KA 17 | B432: =COUNTIF(H$2:H432,H432) -> 7 | C432: 102419141 | D432: 0084014496 | E432: 102419141 / 0084014496 | F432: FATMA RIZKYANI FADILAH | G432: P | H432: XI KA 1 | I432: XI KA | J432: KA | K432: =G432&J432 -> PKA | P432: P
A433: =H433&B433 -> XI KA 18 | B433: =COUNTIF(H$2:H433,H433) -> 8 | C433: 102419142 | D433: 0081520116 | E433: 102419142 / 0081520116 | F433: FIRLY DWI ATHALLAH | G433: L | H433: XI KA 1 | I433: XI KA | J433: KA | K433: =G433&J433 -> LKA | P433: L
A434: =H434&B434 -> XI KA 19 | B434: =COUNTIF(H$2:H434,H434) -> 9 | C434: 102419143 | D434: 0092327546 | E434: 102419143 / 0092327546 | F434: GYNA RIZKI NUR PADILAH | G434: P | H434: XI KA 1 | I434: XI KA | J434: KA | K434: =G434&J434 -> PKA | P434: P
A435: =H435&B435 -> XI KA 110 | B435: =COUNTIF(H$2:H435,H435) -> 10 | C435: 102419144 | D435: 0086624070 | E435: 102419144 / 0086624070 | F435: IRFAN RAMADHANI | G435: L | H435: XI KA 1 | I435: XI KA | J435: KA | K435: =G435&J435 -> LKA | P435: L
A436: =H436&B436 -> XI KA 111 | B436: =COUNTIF(H$2:H436,H436) -> 11 | C436: 102419145 | D436: 0081155652 | E436: 102419145 / 0081155652 | F436: JASMINE QUEENEZ KHARUNNISA | G436: P | H436: XI KA 1 | I436: XI KA | J436: KA | K436: =G436&J436 -> PKA | P436: P
A437: =H437&B437 -> XI KA 112 | B437: =COUNTIF(H$2:H437,H437) -> 12 | C437: 102419146 | D437: 0085551583 | E437: 102419146 / 0085551583 | F437: JIHAN ASSYIFA DEWI | G437: P | H437: XI KA 1 | I437: XI KA | J437: KA | K437: =G437&J437 -> PKA | P437: P
A438: =H438&B438 -> XI KA 113 | B438: =COUNTIF(H$2:H438,H438) -> 13 | C438: 102419148 | D438: 3080576208 | E438: 102419148 / 3080576208 | F438: KEIKO KANAYA RIZQI WAHYUDI PUTRI | G438: P | H438: XI KA 1 | I438: XI KA | J438: KA | K438: =G438&J438 -> PKA | P438: P
...

Sheet Harian
D7: .
A13: PRESENSI SISWA | AL13: 23 | AM13: =VLOOKUP(AL13,AL14:AM52,2) -> XII KA 1 | AN13: =VLOOKUP(AL13,AL14:AO52,3) -> 0
A14: TAHUN PELAJARAN 2023/2024 | AL14: 1 | AM14: X KA 1
A15: ="KELAS "&AM13 -> KELAS XII KA 1 | AL15: 2 | AM15: X KA 2
A16: KELAS KOSEN | AL16: 3 | AM16: X KA 3 | AO16: Sabila Fauzia, S.PD
B17: WALI KELAS : | C17: =AN13 -> 0 | AL17: 4 | AM17: X KA 4
A18: NO | B18: NIS / NISN | C18: NAMA | D18: L/P | E18: PERTEMUAN | AJ18: KET | AL18: 5 | AM18: X KA 5
E19: 1 | F19: 2 | G19: 3 | H19: 4 | I19: 5 | J19: 6 | K19: 7 | L19: 8 | M19: 9 | N19: 10 | O19: 11 | P19: 12 | Q19: 13 | R19: 14 | S19: 15 | T19: 16 | U19: 17 | V19: 18 | W19: 19 | X19: 20 | Y19: 21 | Z19: 22 | AA19: 23 | AB19: 24 | AC19: 25 | AD19: 26 | AE19: 27 | AF19: 28 | AG19: 29 | AH19: 30 | AI19: 31 | AL19: 6 | AM19: X KA 6
AL20: 7 | AM20: X PPLG 1 | AN20: Sabila Fauziyya, S.kom.
A21: 1 | B21: =VLOOKUP($AM$13&$A21,Baru!$A$2:$H$1373,5,0) -> 102318738 / 0076650474 | C21: =VLOOKUP($AM$13&$A21,Baru!$A$2:$H$1373,6,0) -> ADAM ALIF NURAHNAF SYAIFUDIN | D21: =VLOOKUP($AM$13&$A21,Baru!$A$2:$H$1373,7,0) -> L | AL21: 8 | AM21: X PPLG 2 | AN21: Regina Fitrie, S.Pd
A22: 2 | B22: =VLOOKUP($AM$13&$A22,Baru!$A$2:$H$1373,5,0) -> 102318739 / 0086535292 | C22: =VLOOKUP($AM$13&$A22,Baru!$A$2:$H$1373,6,0) -> ALIFA SYAKINA | D22: =VLOOKUP($AM$13&$A22,Baru!$A$2:$H$1373,7,0) -> P | AL22: 9 | AM22: X TJKT 1 | AN22: Eros Roswiyah,S.Pd | AO22: Kania Dewi Waluya, S.Kom
A23: 3 | B23: =VLOOKUP($AM$13&$A23,Baru!$A$2:$H$1373,5,0) -> 102318740 / 0073643663 | C23: =VLOOKUP($AM$13&$A23,Baru!$A$2:$H$1373,6,0) -> ALIYA KHAIRUNNISA | D23: =VLOOKUP($AM$13&$A23,Baru!$A$2:$H$1373,7,0) -> P | AL23: 10 | AM23: X TJKT 2 | AN23: Apriliani Hardiyanti Hariyono,S.Pd
A24: 4 | B24: =VLOOKUP($AM$13&$A24,Baru!$A$2:$H$1373,5,0) -> 102318741 / 0089316539 | C24: =VLOOKUP($AM$13&$A24,Baru!$A$2:$H$1373,6,0) -> ALYA TRI CAHYANI | D24: =VLOOKUP($AM$13&$A24,Baru!$A$2:$H$1373,7,0) -> P | AL24: 11 | AM24: X TJKT 3 | AN24: Sukmawidi,S.Pd
A25: 5 | B25: =VLOOKUP($AM$13&$A25,Baru!$A$2:$H$1373,5,0) -> 102318742 / 0075977264 | C25: =VLOOKUP($AM$13&$A25,Baru!$A$2:$H$1373,6,0) -> AYU SYIFA AL FIYANI | D25: =VLOOKUP($AM$13&$A25,Baru!$A$2:$H$1373,7,0) -> P | AL25: 12 | AM25: XI KA 1
A26: 6 | B26: =VLOOKUP($AM$13&$A26,Baru!$A$2:$H$1373,5,0) -> 102318743 / 0074316539 | C26: =VLOOKUP($AM$13&$A26,Baru!$A$2:$H$1373,6,0) -> DARIN SYAKIRA MARDHIYA | D26: =VLOOKUP($AM$13&$A26,Baru!$A$2:$H$1373,7,0) -> P | AL26: 13 | AM26: XI KA 2
A27: 7 | B27: =VLOOKUP($AM$13&$A27,Baru!$A$2:$H$1373,5,0) -> 102318744 / 0077024892 | C27: =VLOOKUP($AM$13&$A27,Baru!$A$2:$H$1373,6,0) -> DEMAS PRAYUDHA LUTHFIANTO | D27: =VLOOKUP($AM$13&$A27,Baru!$A$2:$H$1373,7,0) -> L | AL27: 14 | AM27: XI KA 3 | AO27: Dini Karomna, S.Pd
A28: 8 | B28: =VLOOKUP($AM$13&$A28,Baru!$A$2:$H$1373,5,0) -> 102318745 / 0075115777 | C28: =VLOOKUP($AM$13&$A28,Baru!$A$2:$H$1373,6,0) -> DEWI SRI RAHAYU | D28: =VLOOKUP($AM$13&$A28,Baru!$A$2:$H$1373,7,0) -> P | AL28: 15 | AM28: XI KA 4 | AO28: Dra. Mimy Ardiany, M.Pd
A29: 9 | B29: =VLOOKUP($AM$13&$A29,Baru!$A$2:$H$1373,5,0) -> 102318746 / 0089847230 | C29: =VLOOKUP($AM$13&$A29,Baru!$A$2:$H$1373,6,0) -> DINA LATHIFAH ATHIRAH AZHAR | D29: =VLOOKUP($AM$13&$A29,Baru!$A$2:$H$1373,7,0) -> P | AL29: 16 | AM29: XI KA 5
A30: 10 | B30: =VLOOKUP($AM$13&$A30,Baru!$A$2:$H$1373,5,0) -> 102318747 / 0087993601 | C30: =VLOOKUP($AM$13&$A30,Baru!$A$2:$H$1373,6,0) -> DINDA DAMAYANTI | D30: =VLOOKUP($AM$13&$A30,Baru!$A$2:$H$1373,7,0) -> P | AL30: 17 | AM30: XI KA 6
A31: 11 | B31: =VLOOKUP($AM$13&$A31,Baru!$A$2:$H$1373,5,0) -> 102318748 / 0083121409 | C31: =VLOOKUP($AM$13&$A31,Baru!$A$2:$H$1373,6,0) -> DZULFIKAR AHMAD | D31: =VLOOKUP($AM$13&$A31,Baru!$A$2:$H$1373,7,0) -> L | AL31: 18 | AM31: XI PPLG 1
A32: 12 | B32: =VLOOKUP($AM$13&$A32,Baru!$A$2:$H$1373,5,0) -> 102318749 / 0076487771 | C32: =VLOOKUP($AM$13&$A32,Baru!$A$2:$H$1373,6,0) -> EVI RAHMAWATI | D32: =VLOOKUP($AM$13&$A32,Baru!$A$2:$H$1373,7,0) -> P | AL32: 19 | AM32: XI PPLG 2
A33: 13 | B33: =VLOOKUP($AM$13&$A33,Baru!$A$2:$H$1373,5,0) -> 102318750 / 0083861812 | C33: =VLOOKUP($AM$13&$A33,Baru!$A$2:$H$1373,6,0) -> FACHRI MUHAMMAD | D33: =VLOOKUP($AM$13&$A33,Baru!$A$2:$H$1373,7,0) -> L | AL33: 20 | AM33: XI TJKT 1
A34: 14 | B34: =VLOOKUP($AM$13&$A34,Baru!$A$2:$H$1373,5,0) -> 102318751 / 0073444383 | C34: =VLOOKUP($AM$13&$A34,Baru!$A$2:$H$1373,6,0) -> FAUZIA LUTHFI ATHAILLAH | D34: =VLOOKUP($AM$13&$A34,Baru!$A$2:$H$1373,7,0) -> P | AL34: 21 | AM34: XI TJKT 2
A35: 15 | B35: =VLOOKUP($AM$13&$A35,Baru!$A$2:$H$1373,5,0) -> 102318752 / 0086597062 | C35: =VLOOKUP($AM$13&$A35,Baru!$A$2:$H$1373,6,0) -> FIANTIKA DWI IRAWAN | D35: =VLOOKUP($AM$13&$A35,Baru!$A$2:$H$1373,7,0) -> P | AL35: 22 | AM35: XI TJKT 3
A36: 16 | B36: =VLOOKUP($AM$13&$A36,Baru!$A$2:$H$1373,5,0) -> 102318753 / 0088168979 | C36: =VLOOKUP($AM$13&$A36,Baru!$A$2:$H$1373,6,0) -> KAYLA ANANDITA PUTRI | D36: =VLOOKUP($AM$13&$A36,Baru!$A$2:$H$1373,7,0) -> P | AL36: 23 | AM36: XII KA 1
A37: 17 | B37: =VLOOKUP($AM$13&$A37,Baru!$A$2:$H$1373,5,0) -> 102318754 / 0075463246 | C37: =VLOOKUP($AM$13&$A37,Baru!$A$2:$H$1373,6,0) -> KAYLA QOLBY LIYYAL KHAIRA | D37: =VLOOKUP($AM$13&$A37,Baru!$A$2:$H$1373,7,0) -> P | AL37: 24 | AM37: XII KA 2 | AO37: Anggita Septiani, S.TP, M.PD
A38: 18 | B38: =VLOOKUP($AM$13&$A38,Baru!$A$2:$H$1373,5,0) -> 102318755 / 0071783553 | C38: =VLOOKUP($AM$13&$A38,Baru!$A$2:$H$1373,6,0) -> KAYLA RAHADHATUL AISY | D38: =VLOOKUP($AM$13&$A38,Baru!$A$2:$H$1373,7,0) -> P | AL38: 25 | AM38: XII KA 3
A39: 19 | B39: =VLOOKUP($AM$13&$A39,Baru!$A$2:$H$1373,5,0) -> 102318756 / 0082007607 | C39: =VLOOKUP($AM$13&$A39,Baru!$A$2:$H$1373,6,0) -> KHAIRANI NAZWA ALIYYA MUTTAQIN SYAH | D39: =VLOOKUP($AM$13&$A39,Baru!$A$2:$H$1373,7,0) -> P | AL39: 26 | AM39: XII KA 4
A40: 20 | B40: =VLOOKUP($AM$13&$A40,Baru!$A$2:$H$1373,5,0) -> 102318757 / 0087008346 | C40: =VLOOKUP($AM$13&$A40,Baru!$A$2:$H$1373,6,0) -> LUTHFI LATIEFAH NUR JAMEELA | D40: =VLOOKUP($AM$13&$A40,Baru!$A$2:$H$1373,7,0) -> P | AL40: 27 | AM40: XII KA 5
A41: 21 | B41: =VLOOKUP($AM$13&$A41,Baru!$A$2:$H$1373,5,0) -> 102318758 / 0082388418 | C41: =VLOOKUP($AM$13&$A41,Baru!$A$2:$H$1373,6,0) -> MAHYRA ZAHRA PURNAMA | D41: =VLOOKUP($AM$13&$A41,Baru!$A$2:$H$1373,7,0) -> P | AL41: 28 | AM41: XII KA 6
A42: 22 | B42: =VLOOKUP($AM$13&$A42,Baru!$A$2:$H$1373,5,0) -> 102318759 / 0088620854 | C42: =VLOOKUP($AM$13&$A42,Baru!$A$2:$H$1373,6,0) -> MEYLINDA PUTRI SANTIKA | D42: =VLOOKUP($AM$13&$A42,Baru!$A$2:$H$1373,7,0) -> P | AL42: 29 | AM42: XII PPLG 1
A43: 23 | B43: =VLOOKUP($AM$13&$A43,Baru!$A$2:$H$1373,5,0) -> 102318760 / 0082811386 | C43: =VLOOKUP($AM$13&$A43,Baru!$A$2:$H$1373,6,0) -> MIRZA ARIEL FEBY KAVALERI | D43: =VLOOKUP($AM$13&$A43,Baru!$A$2:$H$1373,7,0) -> L | AL43: 30 | AM43: XII PPLG 2
A44: 24 | B44: =VLOOKUP($AM$13&$A44,Baru!$A$2:$H$1373,5,0) -> 102318761 / 0072159565 | C44: =VLOOKUP($AM$13&$A44,Baru!$A$2:$H$1373,6,0) -> MUHAMMAD MULKI HAKIM | D44: =VLOOKUP($AM$13&$A44,Baru!$A$2:$H$1373,7,0) -> L | AL44: 31 | AM44: XII TJKT 1
A45: 25 | B45: =VLOOKUP($AM$13&$A45,Baru!$A$2:$H$1373,5,0) -> 102318762 / 0076284245 | C45: =VLOOKUP($AM$13&$A45,Baru!$A$2:$H$1373,6,0) -> NAILAH AGHNIYA TAFIDAH | D45: =VLOOKUP($AM$13&$A45,Baru!$A$2:$H$1373,7,0) -> P | AL45: 32 | AM45: XII TJKT 2
A46: 26 | B46: =VLOOKUP($AM$13&$A46,Baru!$A$2:$H$1373,5,0) -> 102318763 / 0078016724 | C46: =VLOOKUP($AM$13&$A46,Baru!$A$2:$H$1373,6,0) -> PRISHA KHAIRUNISA NA'IEMAH | D46: =VLOOKUP($AM$13&$A46,Baru!$A$2:$H$1373,7,0) -> P | AL46: 33 | AM46: XII TJKT 3
A47: 27 | B47: =VLOOKUP($AM$13&$A47,Baru!$A$2:$H$1373,5,0) -> 102318764 / 0085595699 | C47: =VLOOKUP($AM$13&$A47,Baru!$A$2:$H$1373,6,0) -> PUTRI RISMAYANTI MUHTARI | D47: =VLOOKUP($AM$13&$A47,Baru!$A$2:$H$1373,7,0) -> P | AL47: 34 | AM47: XIII KA 1 | AO47: Syafitri K Arief, S.Pd., M.T
A48: 28 | B48: =VLOOKUP($AM$13&$A48,Baru!$A$2:$H$1373,5,0) -> 102318765 / 0071854052 | C48: =VLOOKUP($AM$13&$A48,Baru!$A$2:$H$1373,6,0) -> RASYA SYAHID ARROYAN | D48: =VLOOKUP($AM$13&$A48,Baru!$A$2:$H$1373,7,0) -> L | AL48: 35 | AM48: XIII KA 2
A49: 29 | B49: =VLOOKUP($AM$13&$A49,Baru!$A$2:$H$1373,5,0) -> 102318766 / 0074233228 | C49: =VLOOKUP($AM$13&$A49,Baru!$A$2:$H$1373,6,0) -> RATU PUTRIDEWI NURRAHMAN | D49: =VLOOKUP($AM$13&$A49,Baru!$A$2:$H$1373,7,0) -> P | AL49: 36 | AM49: XIII KA 3
A50: 30 | B50: =VLOOKUP($AM$13&$A50,Baru!$A$2:$H$1373,5,0) -> 102318767 / 0081133852 | C50: =VLOOKUP($AM$13&$A50,Baru!$A$2:$H$1373,6,0) -> RIF'AT FADILAH | D50: =VLOOKUP($AM$13&$A50,Baru!$A$2:$H$1373,7,0) -> L | AL50: 37 | AM50: XIII KA 4
A51: 31 | B51: =VLOOKUP($AM$13&$A51,Baru!$A$2:$H$1373,5,0) -> 102318768 / 3078294883 | C51: =VLOOKUP($AM$13&$A51,Baru!$A$2:$H$1373,6,0) -> RIRIN WIDYA AJAHRA | D51: =VLOOKUP($AM$13&$A51,Baru!$A$2:$H$1373,7,0) -> P | AL51: 38 | AM51: XIII KA 5
...

Sheet Print
D7: .
A13: PRESENSI SISWA | Y13: 12 | Z13: =VLOOKUP(Y13,Y14:Z52,2) -> XI KA 1 | AA13: =VLOOKUP(Y13,Y14:AB52,3) -> Taufik Hidayat, S.Pd, M.M.Pd
A14: TAHUN PELAJARAN 2025/2026 | Y14: 1 | Z14: X KA 1 | AA14: Nadia Afriliani, S.Pd
A15: ="KELAS "&Z13 -> KELAS XI KA 1 | Y15: 2 | Z15: X KA 2 | AA15: Meli Novita, S.Pd
A16: KELAS KOSEN | Y16: 3 | Z16: X KA 3 | AA16: Sugiyatmi, S.Si
B17: WALI KELAS : | C17: =AA13 -> Taufik Hidayat, S.Pd, M.M.Pd | Y17: 4 | Z17: X KA 4 | AA17: Tita Heriyanti, S.Pd
A18: NO | B18: NIS / NISN | C18: NAMA | D18: L/P | E18: PERTEMUAN | W18: KET | Y18: 5 | Z18: X KA 5 | AA18: Fertika, S.Pd
E19: 1 | F19: 2 | G19: 3 | H19: 4 | I19: 5 | J19: 6 | K19: 7 | L19: 8 | M19: 9 | N19: 10 | O19: 11 | P19: 12 | Q19: 13 | R19: 14 | S19: 15 | T19: 16 | U19: 17 | V19: 18 | Y19: 6 | Z19: X KA 6 | AA19: Ujang Suhara, S.Pd
Y20: 7 | Z20: X PPLG 1 | AA20: Desta Mulyanti, S.Sn
A21: 1 | B21: =VLOOKUP($Z$13&$A21,Baru!$A$2:$H$1373,5,0) -> 102419135 / 0086985872 | C21: =VLOOKUP($Z$13&$A21,Baru!$A$2:$H$1373,6,0) -> AKHTAR ANARGYA WAHYUDI | D21: =VLOOKUP($Z$13&$A21,Baru!$A$2:$H$1373,7,0) -> L | Y21: 8 | Z21: X PPLG 2 | AA21: Samsudin, S.Ag
A22: 2 | B22: =VLOOKUP($Z$13&$A22,Baru!$A$2:$H$1373,5,0) -> 102419136 / 0082738092 | C22: =VLOOKUP($Z$13&$A22,Baru!$A$2:$H$1373,6,0) -> AKMAL NUR HAKIM | D22: =VLOOKUP($Z$13&$A22,Baru!$A$2:$H$1373,7,0) -> L | Y22: 9 | Z22: X TJKT 1 | AA22: Yeni Meilina, S.Pd
A23: 3 | B23: =VLOOKUP($Z$13&$A23,Baru!$A$2:$H$1373,5,0) -> 102419137 / 0085056739 | C23: =VLOOKUP($Z$13&$A23,Baru!$A$2:$H$1373,6,0) -> ANDHIKA DWI PUTRA KUSTYAN | D23: =VLOOKUP($Z$13&$A23,Baru!$A$2:$H$1373,7,0) -> L | Y23: 10 | Z23: X TJKT 2 | AA23: Regina Fitrie, S.Pd
A24: 4 | B24: =VLOOKUP($Z$13&$A24,Baru!$A$2:$H$1373,5,0) -> 102419138 / 0096040843 | C24: =VLOOKUP($Z$13&$A24,Baru!$A$2:$H$1373,6,0) -> ARRUBI NAZMA HIDAYAT | D24: =VLOOKUP($Z$13&$A24,Baru!$A$2:$H$1373,7,0) -> P | Y24: 11 | Z24: X TJKT 3 | AA24: Tubagus Saputra, M.Pd
A25: 5 | B25: =VLOOKUP($Z$13&$A25,Baru!$A$2:$H$1373,5,0) -> 102419139 / 0091552057 | C25: =VLOOKUP($Z$13&$A25,Baru!$A$2:$H$1373,6,0) -> AVISA VALERIE INDRA PUTRI | D25: =VLOOKUP($Z$13&$A25,Baru!$A$2:$H$1373,7,0) -> P | Y25: 12 | Z25: XI KA 1 | AA25: Taufik Hidayat, S.Pd, M.M.Pd
A26: 6 | B26: =VLOOKUP($Z$13&$A26,Baru!$A$2:$H$1373,5,0) -> 102419140 / 0081306089 | C26: =VLOOKUP($Z$13&$A26,Baru!$A$2:$H$1373,6,0) -> CHARISA FITRIYANTI | D26: =VLOOKUP($Z$13&$A26,Baru!$A$2:$H$1373,7,0) -> P | Y26: 13 | Z26: XI KA 2 | AA26: Octavina Sopamena, M.Pd
A27: 7 | B27: =VLOOKUP($Z$13&$A27,Baru!$A$2:$H$1373,5,0) -> 102419141 / 0084014496 | C27: =VLOOKUP($Z$13&$A27,Baru!$A$2:$H$1373,6,0) -> FATMA RIZKYANI FADILAH | D27: =VLOOKUP($Z$13&$A27,Baru!$A$2:$H$1373,7,0) -> P | Y27: 14 | Z27: XI KA 3 | AA27: Ela Nurlaela, S.Pd
A28: 8 | B28: =VLOOKUP($Z$13&$A28,Baru!$A$2:$H$1373,5,0) -> 102419142 / 0081520116 | C28: =VLOOKUP($Z$13&$A28,Baru!$A$2:$H$1373,6,0) -> FIRLY DWI ATHALLAH | D28: =VLOOKUP($Z$13&$A28,Baru!$A$2:$H$1373,7,0) -> L | Y28: 15 | Z28: XI KA 4 | AA28: Iah Robiah, S.Pd
A29: 9 | B29: =VLOOKUP($Z$13&$A29,Baru!$A$2:$H$1373,5,0) -> 102419143 / 0092327546 | C29: =VLOOKUP($Z$13&$A29,Baru!$A$2:$H$1373,6,0) -> GYNA RIZKI NUR PADILAH | D29: =VLOOKUP($Z$13&$A29,Baru!$A$2:$H$1373,7,0) -> P | Y29: 16 | Z29: XI KA 5 | AA29: Ina Marina, S.T
A30: 10 | B30: =VLOOKUP($Z$13&$A30,Baru!$A$2:$H$1373,5,0) -> 102419144 / 0086624070 | C30: =VLOOKUP($Z$13&$A30,Baru!$A$2:$H$1373,6,0) -> IRFAN RAMADHANI | D30: =VLOOKUP($Z$13&$A30,Baru!$A$2:$H$1373,7,0) -> L | Y30: 17 | Z30: XI KA 6 | AA30: Lia Yulianti, M.Pd
A31: 11 | B31: =VLOOKUP($Z$13&$A31,Baru!$A$2:$H$1373,5,0) -> 102419145 / 0081155652 | C31: =VLOOKUP($Z$13&$A31,Baru!$A$2:$H$1373,6,0) -> JASMINE QUEENEZ KHARUNNISA | D31: =VLOOKUP($Z$13&$A31,Baru!$A$2:$H$1373,7,0) -> P | Y31: 18 | Z31: XI RPL 1 | AA31: Pratiwi, S.Si
A32: 12 | B32: =VLOOKUP($Z$13&$A32,Baru!$A$2:$H$1373,5,0) -> 102419146 / 0085551583 | C32: =VLOOKUP($Z$13&$A32,Baru!$A$2:$H$1373,6,0) -> JIHAN ASSYIFA DEWI | D32: =VLOOKUP($Z$13&$A32,Baru!$A$2:$H$1373,7,0) -> P | Y32: 19 | Z32: XI RPL 2 | AA32: Sabila Fauziyya, S.Kom
... A52: 32 | B52: =VLOOKUP($Z$13&$A52,Baru!$A$2:$H$1373,5,0) -> 102419170 / 0096436995 | C52: =VLOOKUP($Z$13&$A52,Baru!$A$2:$H$1373,6,0) -> ZAHRA EKA PUTRI | D52: =VLOOKUP($Z$13&$A52,Baru!$A$2:$H$1373,7,0) -> P | Y52: 39 | Z52: XIII KA 6 | AA52: Syafitri K Arief, S.Pd, M.T
A53: 33 | B53: =VLOOKUP($Z$13&$A53,Baru!$A$2:$H$1373,5,0) -> #N/A | C53: =VLOOKUP($Z$13&$A53,Baru!$A$2:$H$1373,6,0) -> #N/A | D53: =VLOOKUP($Z$13&$A53,Baru!$A$2:$H$1373,7,0) -> #N/A
A54: 34 | B54: =VLOOKUP($Z$13&$A54,Baru!$A$2:$H$1373,5,0) -> #N/A | C54: =VLOOKUP($Z$13&$A54,Baru!$A$2:$H$1373,6,0) -> #N/A | D54: =VLOOKUP($Z$13&$A54,Baru!$A$2:$H$1373,7,0) -> #N/A
A55: 35 | B55: =VLOOKUP($Z$13&$A55,Baru!$A$2:$H$1373,5,0) -> #N/A | C55: =VLOOKUP($Z$13&$A55,Baru!$A$2:$H$1373,6,0) -> #N/A | D55: =VLOOKUP($Z$13&$A55,Baru!$A$2:$H$1373,7,0) -> #N/A
A56: 36 | B56: =VLOOKUP($Z$13&$A56,Baru!$A$2:$H$1373,5,0) -> #N/A | C56: =VLOOKUP($Z$13&$A56,Baru!$A$2:$H$1373,6,0) -> #N/A | D56: =VLOOKUP($Z$13&$A56,Baru!$A$2:$H$1373,7,0) -> #N/A
A57: 37 | B57: =VLOOKUP($Z$13&$A57,Baru!$A$2:$H$1373,5,0) -> #N/A | C57: =VLOOKUP($Z$13&$A57,Baru!$A$2:$H$1373,6,0) -> #N/A | D57: =VLOOKUP($Z$13&$A57,Baru!$A$2:$H$1373,7,0) -> #N/A
A58: 38 | B58: =VLOOKUP($Z$13&$A58,Baru!$A$2:$H$1373,5,0) -> #N/A | C58: =VLOOKUP($Z$13&$A58,Baru!$A$2:$H$1373,6,0) -> #N/A | D58: =VLOOKUP($Z$13&$A58,Baru!$A$2:$H$1373,7,0) -> #N/A
A59: 39 | B59: =VLOOKUP($Z$13&$A59,Baru!$A$2:$H$1373,5,0) -> #N/A | C59: =VLOOKUP($Z$13&$A59,Baru!$A$2:$H$1373,6,0) -> #N/A | D59: =VLOOKUP($Z$13&$A59,Baru!$A$2:$H$1373,7,0) -> #N/A
A60: 40 | B60: =VLOOKUP($Z$13&$A60,Baru!$A$2:$H$1373,5,0) -> #N/A | C60: =VLOOKUP($Z$13&$A60,Baru!$A$2:$H$1373,6,0) -> #N/A | D60: =VLOOKUP($Z$13&$A60,Baru!$A$2:$H$1373,7,0) -> #N/A
B62: JUMLAH | Z62: `
B63: LAKI-LAKI | C63: ="= "&COUNTIF(D21:D60,"L") -> = 6 | Q63: Guru Mata Pelajaran
B64: PEREMPUAN | C64: ="= "&COUNTIF(D21:D60,"P") -> = 26
B65: KETERANGAN
B66: S : Sakit
B67: A : Alpa
B68: I : Izin
I69: =Z13 -> XI KA 1
AN83: P

Sheet Absen Kehadiran
D7: .
A12: PRESENSI RAPAT ORANGTUA SISWA
A13: SOSIALISASI PEMAPARAN PROGRAM SEKOLAH KELAS XII DAN XIII | G13: 40 | H13: =VLOOKUP(G13,G14:H52,2) -> XIII AK 6 | I13: =VLOOKUP(G13,G14:J52,3) -> Ade Hartono, S.Pd
A14: TAHUN PELAJARAN 2023/2024 | G14: 1 | H14: X KA 1 | I14: Windy Novia Anggraeni, S.Si
A15: ="KELAS "&H13 -> KELAS XIII AK 6 | G15: 2 | H15: X KA 2 | I15: Neneng Suhartini, S.Si
A16: KELAS KOSEN | G16: 3 | H16: X KA 3 | I16: Nofa Nirawati, S.Pd,M.T
B17: WALI KELAS : | C17: =I13 -> Ade Hartono, S.Pd | G17: 4 | H17: X KA 4 | I17: Titin Siti Halimah, S.Pd
A18: NO | B18: NIS / NISN | C18: NAMA SISWA | D18: NAMA ORANGTUA | E18: TANDA TANGAN | G18: 5 | H18: X KA 5 | I18: Tini Rosmayani, S.Pd.
G19: 6 | H19: X KA 6 | I19: Kiki Aima Mu’mina, S.Pd (ak6)
G20: 7 | H20: X PPLG 1 | I20: Sabila Fauziyya, S.kom.
A21: 1 | B21: =VLOOKUP($H$13&$A21,Baru!$A$426:$H$1373,5,0) -> #N/A | C21: =VLOOKUP($H$13&$A21,Baru!$A$426:$H$1373,6,0) -> #N/A | E21: 1 | G21: 8 | H21: X PPLG 2 | I21: Regina Fitrie, S.Pd
A22: 2 | B22: =VLOOKUP($H$13&$A22,Baru!$A$426:$H$1373,5,0) -> #N/A | C22: =VLOOKUP($H$13&$A22,Baru!$A$426:$H$1373,6,0) -> #N/A | E22: 2 | G22: 9 | H22: X TJKT 1 | I22: Desta Mulyanti, S. Sn
A23: 3 | B23: =VLOOKUP($H$13&$A23,Baru!$A$426:$H$1373,5,0) -> #N/A | C23: =VLOOKUP($H$13&$A23,Baru!$A$426:$H$1373,6,0) -> #N/A | E23: 3 | G23: 10 | H23: X TJKT 2 | I23: Sudarmi, M.Pd
A24: 4 | B24: =VLOOKUP($H$13&$A24,Baru!$A$426:$H$1373,5,0) -> #N/A | C24: =VLOOKUP($H$13&$A24,Baru!$A$426:$H$1373,6,0) -> #N/A | E24: 4 | G24: 11 | H24: X TJKT 3 | I24: Yeni Meilina, S.Pd.
A25: 5 | B25: =VLOOKUP($H$13&$A25,Baru!$A$426:$H$1373,5,0) -> #N/A | C25: =VLOOKUP($H$13&$A25,Baru!$A$426:$H$1373,6,0) -> #N/A | E25: 5 | G25: 12 | H25: XI KA 1 | I25: Gana Dargana, S. Pd., M.T
A26: 6 | B26: =VLOOKUP($H$13&$A26,Baru!$A$426:$H$1373,5,0) -> #N/A | C26: =VLOOKUP($H$13&$A26,Baru!$A$426:$H$1373,6,0) -> #N/A | E26: 6 | G26: 13 | H26: XI KA 2 | I26: Octavina Sopamena, M.Pd
A27: 7 | B27: =VLOOKUP($H$13&$A27,Baru!$A$426:$H$1373,5,0) -> #N/A | C27: =VLOOKUP($H$13&$A27,Baru!$A$426:$H$1373,6,0) -> #N/A | E27: 7 | G27: 14 | H27: XI KA 3 | I27: Iah Robiah, S.Pd
A28: 8 | B28: =VLOOKUP($H$13&$A28,Baru!$A$426:$H$1373,5,0) -> #N/A | C28: =VLOOKUP($H$13&$A28,Baru!$A$426:$H$1373,6,0) -> #N/A | E28: 8 | G28: 15 | H28: XI KA 4 | I28: Sarinah Br Ginting, M.Pd
A29: 9 | B29: =VLOOKUP($H$13&$A29,Baru!$A$426:$H$1373,5,0) -> #N/A | C29: =VLOOKUP($H$13&$A29,Baru!$A$426:$H$1373,6,0) -> #N/A | E29: 9 | G29: 16 | H29: XI KA 5 | I29: Lia Yulianti, S.Pd
A30: 10 | B30: =VLOOKUP($H$13&$A30,Baru!$A$426:$H$1373,5,0) -> #N/A | C30: =VLOOKUP($H$13&$A30,Baru!$A$426:$H$1373,6,0) -> #N/A | E30: 10 | G30: 17 | H30: XI KA 6 | I30: Ruhya, S.Ag, M.M.Pd
A31: 11 | B31: =VLOOKUP($H$13&$A31,Baru!$A$426:$H$1373,5,0) -> #N/A | C31: =VLOOKUP($H$13&$A31,Baru!$A$426:$H$1373,6,0) -> #N/A | E31: 11 | G31: 18 | H31: XI PPLG 1 | I31: Pratiwi, S.SI, GR
A32: 12 | B32: =VLOOKUP($H$13&$A32,Baru!$A$426:$H$1373,5,0) -> #N/A | C32: =VLOOKUP($H$13&$A32,Baru!$A$426:$H$1373,6,0) -> #N/A | E32: 12 | G32: 19 | H32: XI PPLG 2 | I32: Dena Handriana, M. Pd
... A52: 32 | B52: =VLOOKUP($H$13&$A52,Baru!$A$426:$H$1373,5,0) -> #N/A | C52: =VLOOKUP($H$13&$A52,Baru!$A$426:$H$1373,6,0) -> #N/A | E52: 32 | G52: 39 | H52: XIII AK 6 | I52: Ade Hartono, S.Pd
A53: 33 | B53: =VLOOKUP($H$13&$A53,Baru!$A$426:$H$1373,5,0) -> #N/A | C53: =VLOOKUP($H$13&$A53,Baru!$A$426:$H$1373,6,0) -> #N/A | E53: 33
A54: 34 | B54: =VLOOKUP($H$13&$A54,Baru!$A$426:$H$1373,5,0) -> #N/A | C54: =VLOOKUP($H$13&$A54,Baru!$A$426:$H$1373,6,0) -> #N/A
A55: 35 | B55: =VLOOKUP($H$13&$A55,Baru!$A$426:$H$1373,5,0) -> #N/A | C55: =VLOOKUP($H$13&$A55,Baru!$A$426:$H$1373,6,0) -> #N/A
A56: 36 | B56: =VLOOKUP($H$13&$A56,Baru!$A$426:$H$1373,5,0) -> #N/A | C56: =VLOOKUP($H$13&$A56,Baru!$A$426:$H$1373,6,0) -> #N/A
H58: `
V79: P

Sheet Penerimaan Ijazah
D7: .
A13: BUKTI SERAH TERIMA IJAZAH DAN TRANSKRIP NILAI | I13: 40 | J13: =VLOOKUP(I13,I14:J52,2) -> XIII AK 6 | K13: =VLOOKUP(I13,I14:L52,3) -> Syafitri K. Arief, S.Pd, M.T
A14: SISWA LULUSAN TAHUN PELAJARAN 2024/2025 | I14: 1 | J14: X AK 1 | K14: Oman Somana, M.Pd
A15: ="KELAS "&J13 -> KELAS XIII AK 6 | I15: 2 | J15: X AK 2 | K15: Eros Roswiyah,S.Pd
A16: KELAS KOSEN | I16: 3 | J16: X AK 3 | K16: Rani Rabiussani, M.Pd | L16: Nofa Nirawati, S.Pd,M.T
B17: WALI KELAS : | C17: =K13 -> Syafitri K. Arief, S.Pd, M.T | I17: 4 | J17: X AK 4 | K17: Adiwiguna, S.Pd
A18: NO | B18: NIS / NISN | C18: NAMA | D18: L/P | E18: TANGGAL PENGAMBILAN | F18: DOKUMEN | I18: 5 | J18: X AK 5 | K18: Ujang Suhara, S.Pd
F19: IJAZAH | G19: TRANSKRIP NILAI | I19: 6 | J19: X AK 6 | K19: Tessa Eka Yuniar, S.Pd | L19: Kiki Aima Mu’mina, S.Pd (ak6)
I20: 7 | J20: X RPL 1 | K20: Sukmawidi,S.Pd
A21: 1 | B21: =VLOOKUP($J$13&$A21,Baru!$A$2:$H$1373,5,0) -> #N/A | C21: =VLOOKUP($J$13&$A21,Baru!$A$2:$H$1373,6,0) -> #N/A | D21: =VLOOKUP($J$13&$A21,Baru!$A$2:$H$1373,7,0) -> #N/A | I21: 8 | J21: X RPL 2 | K21: Eti Ariesanti, S.Pd
A22: 2 | B22: =VLOOKUP($J$13&$A22,Baru!$A$2:$H$1373,5,0) -> #N/A | C22: =VLOOKUP($J$13&$A22,Baru!$A$2:$H$1373,6,0) -> #N/A | D22: =VLOOKUP($J$13&$A22,Baru!$A$2:$H$1373,7,0) -> #N/A | I22: 9 | J22: X TKJ 1 | K22: Kania Dewi Waluya, S.kom
A23: 3 | B23: =VLOOKUP($J$13&$A23,Baru!$A$2:$H$1373,5,0) -> #N/A | C23: =VLOOKUP($J$13&$A23,Baru!$A$2:$H$1373,6,0) -> #N/A | D23: =VLOOKUP($J$13&$A23,Baru!$A$2:$H$1373,7,0) -> #N/A | I23: 10 | J23: X TKJ 2 | K23: Apriliani Hardiyanti Hariyono,S.Pd | L23: Sudarmi, M.Pd
A24: 4 | B24: =VLOOKUP($J$13&$A24,Baru!$A$2:$H$1373,5,0) -> #N/A | C24: =VLOOKUP($J$13&$A24,Baru!$A$2:$H$1373,6,0) -> #N/A | D24: =VLOOKUP($J$13&$A24,Baru!$A$2:$H$1373,7,0) -> #N/A | I24: 11 | J24: X TKJ 3 | K24: Ruhya, S.Ag, M.M.Pd | L24: Yeni Meilina, S.Pd.
A25: 5 | B25: =VLOOKUP($J$13&$A25,Baru!$A$2:$H$1373,5,0) -> #N/A | C25: =VLOOKUP($J$13&$A25,Baru!$A$2:$H$1373,6,0) -> #N/A | D25: =VLOOKUP($J$13&$A25,Baru!$A$2:$H$1373,7,0) -> #N/A | I25: 12 | J25: XI AK 1 | K25: Dra. Mimy Ardiany, M.T
A26: 6 | B26: =VLOOKUP($J$13&$A26,Baru!$A$2:$H$1373,5,0) -> #N/A | C26: =VLOOKUP($J$13&$A26,Baru!$A$2:$H$1373,6,0) -> #N/A | D26: =VLOOKUP($J$13&$A26,Baru!$A$2:$H$1373,7,0) -> #N/A | I26: 13 | J26: XI AK 2 | K26: Ade Hartono, S.Pd
A27: 7 | B27: =VLOOKUP($J$13&$A27,Baru!$A$2:$H$1373,5,0) -> #N/A | C27: =VLOOKUP($J$13&$A27,Baru!$A$2:$H$1373,6,0) -> #N/A | D27: =VLOOKUP($J$13&$A27,Baru!$A$2:$H$1373,7,0) -> #N/A | I27: 14 | J27: XI AK 3 | K27: Dra. Rahmi Dalilah Fitrianni
A28: 8 | B28: =VLOOKUP($J$13&$A28,Baru!$A$2:$H$1373,5,0) -> #N/A | C28: =VLOOKUP($J$13&$A28,Baru!$A$2:$H$1373,6,0) -> #N/A | D28: =VLOOKUP($J$13&$A28,Baru!$A$2:$H$1373,7,0) -> #N/A | I28: 15 | J28: XI AK 4 | K28: Ela Nurlaela, S.Pd | L28: Sarinah Br Ginting, M.Pd
A29: 9 | B29: =VLOOKUP($J$13&$A29,Baru!$A$2:$H$1373,5,0) -> #N/A | C29: =VLOOKUP($J$13&$A29,Baru!$A$2:$H$1373,6,0) -> #N/A | D29: =VLOOKUP($J$13&$A29,Baru!$A$2:$H$1373,7,0) -> #N/A | I29: 16 | J29: XI AK 5 | K29: Octavina Sopamena, M.Pd | L29: Lia Yulianti, S.Pd
A30: 10 | B30: =VLOOKUP($J$13&$A30,Baru!$A$2:$H$1373,5,0) -> #N/A | C30: =VLOOKUP($J$13&$A30,Baru!$A$2:$H$1373,6,0) -> #N/A | D30: =VLOOKUP($J$13&$A30,Baru!$A$2:$H$1373,7,0) -> #N/A | I30: 17 | J30: XI AK 6 | K30: Iah Robiah, S.Pd
A31: 11 | B31: =VLOOKUP($J$13&$A31,Baru!$A$2:$H$1373,5,0) -> #N/A | C31: =VLOOKUP($J$13&$A31,Baru!$A$2:$H$1373,6,0) -> #N/A | D31: =VLOOKUP($J$13&$A31,Baru!$A$2:$H$1373,7,0) -> #N/A | I31: 18 | J31: XI RPL 1 | K31: Ariantonius Sagala, S.Kom | L31: Pratiwi, S.SI, GR
A32: 12 | B32: =VLOOKUP($J$13&$A32,Baru!$A$2:$H$1373,5,0) -> #N/A | C32: =VLOOKUP($J$13&$A32,Baru!$A$2:$H$1373,6,0) -> #N/A | D32: =VLOOKUP($J$13&$A32,Baru!$A$2:$H$1373,7,0) -> #N/A | I32: 19 | J32: XI RPL 2 | K32: Rukmana. S.Pd.I
A33: 13 | B33: =VLOOKUP($J$13&$A33,Baru!$A$2:$H$1373,5,0) -> #N/A | C33: =VLOOKUP($J$13&$A33,Baru!$A$2:$H$1373,6,0) -> #N/A | D33: =VLOOKUP($J$13&$A33,Baru!$A$2:$H$1373,7,0) -> #N/A | I33: 20 | J33: XI TKJ 1 | K33: Desta Mulyanti, S. Sn
A34: 14 | B34: =VLOOKUP($J$13&$A34,Baru!$A$2:$H$1373,5,0) -> #N/A | C34: =VLOOKUP($J$13&$A34,Baru!$A$2:$H$1373,6,0) -> #N/A | D34: =VLOOKUP($J$13&$A34,Baru!$A$2:$H$1373,7,0) -> #N/A | I34: 21 | J34: XI TKJ 2 | K34: Dena Handriana, M. Pd | L34: Ermawati, M.Kom
A35: 15 | B35: =VLOOKUP($J$13&$A35,Baru!$A$2:$H$1373,5,0) -> #N/A | C35: =VLOOKUP($J$13&$A35,Baru!$A$2:$H$1373,6,0) -> #N/A | D35: =VLOOKUP($J$13&$A35,Baru!$A$2:$H$1373,7,0) -> #N/A | I35: 22 | J35: XI TKJ 3 | K35: Nogi Muharam, S.Kom | L35: Drs. Erwin Sambas, M.M.Pd
A36: 16 | B36: =VLOOKUP($J$13&$A36,Baru!$A$2:$H$1373,5,0) -> #N/A | C36: =VLOOKUP($J$13&$A36,Baru!$A$2:$H$1373,6,0) -> #N/A | D36: =VLOOKUP($J$13&$A36,Baru!$A$2:$H$1373,7,0) -> #N/A | I36: 23 | J36: XII AK 1 | K36: Windy Novia Anggraeni, S.Si
A37: 17 | B37: =VLOOKUP($J$13&$A37,Baru!$A$2:$H$1373,5,0) -> #N/A | C37: =VLOOKUP($J$13&$A37,Baru!$A$2:$H$1373,6,0) -> #N/A | D37: =VLOOKUP($J$13&$A37,Baru!$A$2:$H$1373,7,0) -> #N/A | I37: 24 | J37: XII AK 2 | K37: Danty, S.Pd
A38: 18 | B38: =VLOOKUP($J$13&$A38,Baru!$A$2:$H$1373,5,0) -> #N/A | C38: =VLOOKUP($J$13&$A38,Baru!$A$2:$H$1373,6,0) -> #N/A | D38: =VLOOKUP($J$13&$A38,Baru!$A$2:$H$1373,7,0) -> #N/A | I38: 25 | J38: XII AK 3 | K38: Neneng Suhartini, S.Si
A39: 19 | B39: =VLOOKUP($J$13&$A39,Baru!$A$2:$H$1373,5,0) -> #N/A | C39: =VLOOKUP($J$13&$A39,Baru!$A$2:$H$1373,6,0) -> #N/A | D39: =VLOOKUP($J$13&$A39,Baru!$A$2:$H$1373,7,0) -> #N/A | I39: 26 | J39: XII AK 4 | K39: Tini Rosmayani, S.Si
A40: 20 | B40: =VLOOKUP($J$13&$A40,Baru!$A$2:$H$1373,5,0) -> #N/A | C40: =VLOOKUP($J$13&$A40,Baru!$A$2:$H$1373,6,0) -> #N/A | D40: =VLOOKUP($J$13&$A40,Baru!$A$2:$H$1373,7,0) -> #N/A | I40: 27 | J40: XII AK 5 | K40: Dadan Rukma Dian Dawan, S.Pd
A41: 21 | B41: =VLOOKUP($J$13&$A41,Baru!$A$2:$H$1373,5,0) -> #N/A | C41: =VLOOKUP($J$13&$A41,Baru!$A$2:$H$1373,6,0) -> #N/A | D41: =VLOOKUP($J$13&$A41,Baru!$A$2:$H$1373,7,0) -> #N/A | I41: 28 | J41: XII AK 6 | K41: Cecep Suryana, S.SI
A42: 22 | B42: =VLOOKUP($J$13&$A42,Baru!$A$2:$H$1373,5,0) -> #N/A | C42: =VLOOKUP($J$13&$A42,Baru!$A$2:$H$1373,6,0) -> #N/A | D42: =VLOOKUP($J$13&$A42,Baru!$A$2:$H$1373,7,0) -> #N/A | I42: 29 | J42: XII RPL 1 | K42: Dra. Weni Asmaraeni
A43: 23 | B43: =VLOOKUP($J$13&$A43,Baru!$A$2:$H$1373,5,0) -> #N/A | C43: =VLOOKUP($J$13&$A43,Baru!$A$2:$H$1373,6,0) -> #N/A | D43: =VLOOKUP($J$13&$A43,Baru!$A$2:$H$1373,7,0) -> #N/A | I43: 30 | J43: XII RPL 2 | K43: Sabila Fauziyya, S.kom.
A44: 24 | B44: =VLOOKUP($J$13&$A44,Baru!$A$2:$H$1373,5,0) -> #N/A | C44: =VLOOKUP($J$13&$A44,Baru!$A$2:$H$1373,6,0) -> #N/A | D44: =VLOOKUP($J$13&$A44,Baru!$A$2:$H$1373,7,0) -> #N/A | I44: 31 | J44: XII TKJ 1 | K44: Indirasari P, M.ED
A45: 25 | B45: =VLOOKUP($J$13&$A45,Baru!$A$2:$H$1373,5,0) -> #N/A | C45: =VLOOKUP($J$13&$A45,Baru!$A$2:$H$1373,6,0) -> #N/A | D45: =VLOOKUP($J$13&$A45,Baru!$A$2:$H$1373,7,0) -> #N/A | I45: 32 | J45: XII TKJ 2 | K45: Muchamad Harry Ismail, S.Tr.Kom., M.M
A46: 26 | B46: =VLOOKUP($J$13&$A46,Baru!$A$2:$H$1373,5,0) -> #N/A | C46: =VLOOKUP($J$13&$A46,Baru!$A$2:$H$1373,6,0) -> #N/A | D46: =VLOOKUP($J$13&$A46,Baru!$A$2:$H$1373,7,0) -> #N/A | I46: 33 | J46: XII TKJ 3 | K46: Rini Dwiwahyuni, S.Pd
